Workbook
Name AssetM: [1]Table!$J$3:$K$13
Name Benjamin: OFFSET('[2]Weight Watch'!$B$9,'[2]Weight Watch'!$I$3-9,2,'[2]Weight Watch'!$I$2,1)
Name Client: [1]X!$C$9
Name DateF: OFFSET('[2]Weight Watch'!$B$9,'[2]Weight Watch'!$I$3-9,0,'[2]Weight Watch'!$I$2,1)
Name DefaultB: [1]X!$F$5
Name Difference: OFFSET([3]Salman!$G$9,0,0,[3]Salman!$B$4,1)
Name Eric: OFFSET('[2]Weight Watch'!$B$9,'[2]Weight Watch'!$I$3-9,4,'[2]Weight Watch'!$I$2,1)
Name FanF: OFFSET('[2]Weight Watch'!$B$9,'[2]Weight Watch'!$I$3-9,3,'[2]Weight Watch'!$I$2,1)
Name Footer: [1]X!$C$10
Name George: OFFSET('[2]Weight Watch'!$B$9,'[2]Weight Watch'!$I$3-9,3,'[2]Weight Watch'!$I$2,1)
Name LiF: OFFSET('[2]Weight Watch'!$B$9,'[2]Weight Watch'!$I$3-9,2,'[2]Weight Watch'!$I$2,1)
Name MeasDate: OFFSET('[2]Weight Watch'!$B$9,'[2]Weight Watch'!$I$3-9,0,'[2]Weight Watch'!$I$2,1)
Name MetMRV: [4]Table!$C$21:$D$31
Name Rate: OFFSET([5]Rate!$C$4,0,0,COUNT([5]Rate!$C:$C))
Name Version: [1]X!$A$2
Name WangF: OFFSET('[2]Weight Watch'!$B$9,'[2]Weight Watch'!$I$3-9,4,'[2]Weight Watch'!$I$2,1)
Name Year: OFFSET([5]Rate!$B$4,0,0,COUNT([5]Rate!$B:$B))
Name Year158: '[6]FAS 158 Input'!$H$4

Sheet Claim Triangles
C2: Total Paid claims by month of payment and incurred month, and membership by month
C3: Paid Claims by Month of Payment and Month of Service ("Paid Claims Triange") (in thousands of dollars)
C5: Incurred Month
B6: Paid Month | C6: Total | D6: =B7 -> 40544 | E6: =EDATE(D6,1) -> 40575 | F6: =EDATE(E6,1) -> 40603 | G6: =EDATE(F6,1) -> 40634 | H6: =EDATE(G6,1) -> 40664 | I6: =EDATE(H6,1) -> 40695 | J6: =EDATE(I6,1) -> 40725 | K6: =EDATE(J6,1) -> 40756 | L6: =EDATE(K6,1) -> 40787 | ... AA6: =EDATE(Z6,1) -> 41244
B7: ='Claim Data'!B4 -> 40544 | C7: =SUM(D7:AA7) -> 1649000 | D7: {=IFERROR(INDEX('Claim Data'!$D$4:$D$282,MATCH($B7&D$6,'Claim Data'!$C$4:$C$282&'Claim Data'!$B$4:$B$282,0)),"")} -> 1649000 | E7: {=IFERROR(INDEX('Claim Data'!$D$4:$D$282,MATCH($B7&E$6,'Claim Data'!$C$4:$C$282&'Claim Data'!$B$4:$B$282,0)),"")} | F7: {=IFERROR(INDEX('Claim Data'!$D$4:$D$282,MATCH($B7&F$6,'Claim Data'!$C$4:$C$282&'Claim Data'!$B$4:$B$282,0)),"")} | G7: {=IFERROR(INDEX('Claim Data'!$D$4:$D$282,MATCH($B7&G$6,'Claim Data'!$C$4:$C$282&'Claim Data'!$B$4:$B$282,0)),"")} | H7: {=IFERROR(INDEX('Claim Data'!$D$4:$D$282,MATCH($B7&H$6,'Claim Data'!$C$4:$C$282&'Claim Data'!$B$4:$B$282,0)),"")} | I7: {=IFERROR(INDEX('Claim Data'!$D$4:$D$282,MATCH($B7&I$6,'Claim Data'!$C$4:$C$282&'Claim Data'!$B$4:$B$282,0)),"")} | J7: {=IFERROR(INDEX('Claim Data'!$D$4:$D$282,MATCH($B7&J$6,'Claim Data'!$C$4:$C$282&'Claim Data'!$B$4:$B$282,0)),"")} | K7: {=IFERROR(INDEX('Claim Data'!$D$4:$D$282,MATCH($B7&K$6,'Claim Data'!$C$4:$C$282&'Claim Data'!$B$4:$B$282,0)),"")} | ... AA7: {=IFERROR(INDEX('Claim Data'!$D$4:$D$282,MATCH($B7&AA$6,'Claim Data'!$C$4:$C$282&'Claim Data'!$B$4:$B$282,0)),"")}
B8: =EDATE(B7,1) -> 40575 | C8: =SUM(D8:AA8) -> 5753000 | D8: {=IFERROR(INDEX('Claim Data'!$D$4:$D$282,MATCH($B8&D$6,'Claim Data'!$C$4:$C$282&'Claim Data'!$B$4:$B$282,0)),"")} -> 4580000 | E8: {=IFERROR(INDEX('Claim Data'!$D$4:$D$282,MATCH($B8&E$6,'Claim Data'!$C$4:$C$282&'Claim Data'!$B$4:$B$282,0)),"")} -> 1173000 | F8: {=IFERROR(INDEX('Claim Data'!$D$4:$D$282,MATCH($B8&F$6,'Claim Data'!$C$4:$C$282&'Claim Data'!$B$4:$B$282,0)),"")} | G8: {=IFERROR(INDEX('Claim Data'!$D$4:$D$282,MATCH($B8&G$6,'Claim Data'!$C$4:$C$282&'Claim Data'!$B$4:$B$282,0)),"")} | H8: {=IFERROR(INDEX('Claim Data'!$D$4:$D$282,MATCH($B8&H$6,'Claim Data'!$C$4:$C$282&'Claim Data'!$B$4:$B$282,0)),"")} | I8: {=IFERROR(INDEX('Claim Data'!$D$4:$D$282,MATCH($B8&I$6,'Claim Data'!$C$4:$C$282&'Claim Data'!$B$4:$B$282,0)),"")} | J8: {=IFERROR(INDEX('Claim Data'!$D$4:$D$282,MATCH($B8&J$6,'Claim Data'!$C$4:$C$282&'Claim Data'!$B$4:$B$282,0)),"")} | K8: {=IFERROR(INDEX('Claim Data'!$D$4:$D$282,MATCH($B8&K$6,'Claim Data'!$C$4:$C$282&'Claim Data'!$B$4:$B$282,0)),"")} | ... AA8: {=IFERROR(INDEX('Claim Data'!$D$4:$D$282,MATCH($B8&AA$6,'Claim Data'!$C$4:$C$282&'Claim Data'!$B$4:$B$282,0)),"")}
B9: =EDATE(B8,1) -> 40603 | C9: =SUM(D9:AA9) -> 7843000 | D9: {=IFERROR(INDEX('Claim Data'!$D$4:$D$282,MATCH($B9&D$6,'Claim Data'!$C$4:$C$282&'Claim Data'!$B$4:$B$282,0)),"")} -> 1934000 | E9: {=IFERROR(INDEX('Claim Data'!$D$4:$D$282,MATCH($B9&E$6,'Claim Data'!$C$4:$C$282&'Claim Data'!$B$4:$B$282,0)),"")} -> 4406000 | F9: {=IFERROR(INDEX('Claim Data'!$D$4:$D$282,MATCH($B9&F$6,'Claim Data'!$C$4:$C$282&'Claim Data'!$B$4:$B$282,0)),"")} -> 1503000 | G9: {=IFERROR(INDEX('Claim Data'!$D$4:$D$282,MATCH($B9&G$6,'Claim Data'!$C$4:$C$282&'Claim Data'!$B$4:$B$282,0)),"")} | H9: {=IFERROR(INDEX('Claim Data'!$D$4:$D$282,MATCH($B9&H$6,'Claim Data'!$C$4:$C$282&'Claim Data'!$B$4:$B$282,0)),"")} | I9: {=IFERROR(INDEX('Claim Data'!$D$4:$D$282,MATCH($B9&I$6,'Claim Data'!$C$4:$C$282&'Claim Data'!$B$4:$B$282,0)),"")} | J9: {=IFERROR(INDEX('Claim Data'!$D$4:$D$282,MATCH($B9&J$6,'Claim Data'!$C$4:$C$282&'Claim Data'!$B$4:$B$282,0)),"")} | K9: {=IFERROR(INDEX('Claim Data'!$D$4:$D$282,MATCH($B9&K$6,'Claim Data'!$C$4:$C$282&'Claim Data'!$B$4:$B$282,0)),"")} | ... AA9: {=IFERROR(INDEX('Claim Data'!$D$4:$D$282,MATCH($B9&AA$6,'Claim Data'!$C$4:$C$282&'Claim Data'!$B$4:$B$282,0)),"")}
B10: =EDATE(B9,1) -> 40634 | C10: =SUM(D10:AA10) -> 11370000 | D10: {=IFERROR(INDEX('Claim Data'!$D$4:$D$282,MATCH($B10&D$6,'Claim Data'!$C$4:$C$282&'Claim Data'!$B$4:$B$282,0)),"")} -> 1152000 | E10: {=IFERROR(INDEX('Claim Data'!$D$4:$D$282,MATCH($B10&E$6,'Claim Data'!$C$4:$C$282&'Claim Data'!$B$4:$B$282,0)),"")} -> 1671000 | F10: {=IFERROR(INDEX('Claim Data'!$D$4:$D$282,MATCH($B10&F$6,'Claim Data'!$C$4:$C$282&'Claim Data'!$B$4:$B$282,0)),"")} -> 6462000 | G10: {=IFERROR(INDEX('Claim Data'!$D$4:$D$282,MATCH($B10&G$6,'Claim Data'!$C$4:$C$282&'Claim Data'!$B$4:$B$282,0)),"")} -> 2085000 | H10: {=IFERROR(INDEX('Claim Data'!$D$4:$D$282,MATCH($B10&H$6,'Claim Data'!$C$4:$C$282&'Claim Data'!$B$4:$B$282,0)),"")} | I10: {=IFERROR(INDEX('Claim Data'!$D$4:$D$282,MATCH($B10&I$6,'Claim Data'!$C$4:$C$282&'Claim Data'!$B$4:$B$282,0)),"")} | J10: {=IFERROR(INDEX('Claim Data'!$D$4:$D$282,MATCH($B10&J$6,'Claim Data'!$C$4:$C$282&'Claim Data'!$B$4:$B$282,0)),"")} | K10: {=IFERROR(INDEX('Claim Data'!$D$4:$D$282,MATCH($B10&K$6,'Claim Data'!$C$4:$C$282&'Claim Data'!$B$4:$B$282,0)),"")} | ... AA10: {=IFERROR(INDEX('Claim Data'!$D$4:$D$282,MATCH($B10&AA$6,'Claim Data'!$C$4:$C$282&'Claim Data'!$B$4:$B$282,0)),"")}
B11: =EDATE(B10,1) -> 40664 | C11: =SUM(D11:AA11) -> 9134000 | D11: {=IFERROR(INDEX('Claim Data'!$D$4:$D$282,MATCH($B11&D$6,'Claim Data'!$C$4:$C$282&'Claim Data'!$B$4:$B$282,0)),"")} -> 221000 | E11: {=IFERROR(INDEX('Claim Data'!$D$4:$D$282,MATCH($B11&E$6,'Claim Data'!$C$4:$C$282&'Claim Data'!$B$4:$B$282,0)),"")} -> 571000 | F11: {=IFERROR(INDEX('Claim Data'!$D$4:$D$282,MATCH($B11&F$6,'Claim Data'!$C$4:$C$282&'Claim Data'!$B$4:$B$282,0)),"")} -> 1417000 | G11: {=IFERROR(INDEX('Claim Data'!$D$4:$D$282,MATCH($B11&G$6,'Claim Data'!$C$4:$C$282&'Claim Data'!$B$4:$B$282,0)),"")} -> 5009000 | H11: {=IFERROR(INDEX('Claim Data'!$D$4:$D$282,MATCH($B11&H$6,'Claim Data'!$C$4:$C$282&'Claim Data'!$B$4:$B$282,0)),"")} -> 1916000 | I11: {=IFERROR(INDEX('Claim Data'!$D$4:$D$282,MATCH($B11&I$6,'Claim Data'!$C$4:$C$282&'Claim Data'!$B$4:$B$282,0)),"")} | J11: {=IFERROR(INDEX('Claim Data'!$D$4:$D$282,MATCH($B11&J$6,'Claim Data'!$C$4:$C$282&'Claim Data'!$B$4:$B$282,0)),"")} | K11: {=IFERROR(INDEX('Claim Data'!$D$4:$D$282,MATCH($B11&K$6,'Claim Data'!$C$4:$C$282&'Claim Data'!$B$4:$B$282,0)),"")} | ... AA11: {=IFERROR(INDEX('Claim Data'!$D$4:$D$282,MATCH($B11&AA$6,'Claim Data'!$C$4:$C$282&'Claim Data'!$B$4:$B$282,0)),"")}
B12: =EDATE(B11,1) -> 40695 | C12: =SUM(D12:AA12) -> 8995000 | D12: {=IFERROR(INDEX('Claim Data'!$D$4:$D$282,MATCH($B12&D$6,'Claim Data'!$C$4:$C$282&'Claim Data'!$B$4:$B$282,0)),"")} -> 173000 | E12: {=IFERROR(INDEX('Claim Data'!$D$4:$D$282,MATCH($B12&E$6,'Claim Data'!$C$4:$C$282&'Claim Data'!$B$4:$B$282,0)),"")} -> 93000 | F12: {=IFERROR(INDEX('Claim Data'!$D$4:$D$282,MATCH($B12&F$6,'Claim Data'!$C$4:$C$282&'Claim Data'!$B$4:$B$282,0)),"")} -> 861000 | G12: {=IFERROR(INDEX('Claim Data'!$D$4:$D$282,MATCH($B12&G$6,'Claim Data'!$C$4:$C$282&'Claim Data'!$B$4:$B$282,0)),"")} -> 1164000 | H12: {=IFERROR(INDEX('Claim Data'!$D$4:$D$282,MATCH($B12&H$6,'Claim Data'!$C$4:$C$282&'Claim Data'!$B$4:$B$282,0)),"")} -> 4930000 | I12: {=IFERROR(INDEX('Claim Data'!$D$4:$D$282,MATCH($B12&I$6,'Claim Data'!$C$4:$C$282&'Claim Data'!$B$4:$B$282,0)),"")} -> 1774000 | J12: {=IFERROR(INDEX('Claim Data'!$D$4:$D$282,MATCH($B12&J$6,'Claim Data'!$C$4:$C$282&'Claim Data'!$B$4:$B$282,0)),"")} | K12: {=IFERROR(INDEX('Claim Data'!$D$4:$D$282,MATCH($B12&K$6,'Claim Data'!$C$4:$C$282&'Claim Data'!$B$4:$B$282,0)),"")} | ... AA12: {=IFERROR(INDEX('Claim Data'!$D$4:$D$282,MATCH($B12&AA$6,'Claim Data'!$C$4:$C$282&'Claim Data'!$B$4:$B$282,0)),"")}
B13: =EDATE(B12,1) -> 40725 | C13: =SUM(D13:AA13) -> 9945000 | D13: {=IFERROR(INDEX('Claim Data'!$D$4:$D$282,MATCH($B13&D$6,'Claim Data'!$C$4:$C$282&'Claim Data'!$B$4:$B$282,0)),"")} -> 60000 | E13: {=IFERROR(INDEX('Claim Data'!$D$4:$D$282,MATCH($B13&E$6,'Claim Data'!$C$4:$C$282&'Claim Data'!$B$4:$B$282,0)),"")} -> 129000 | F13: {=IFERROR(INDEX('Claim Data'!$D$4:$D$282,MATCH($B13&F$6,'Claim Data'!$C$4:$C$282&'Claim Data'!$B$4:$B$282,0)),"")} -> 243000 | G13: {=IFERROR(INDEX('Claim Data'!$D$4:$D$282,MATCH($B13&G$6,'Claim Data'!$C$4:$C$282&'Claim Data'!$B$4:$B$282,0)),"")} -> 388000 | H13: {=IFERROR(INDEX('Claim Data'!$D$4:$D$282,MATCH($B13&H$6,'Claim Data'!$C$4:$C$282&'Claim Data'!$B$4:$B$282,0)),"")} -> 1473000 | I13: {=IFERROR(INDEX('Claim Data'!$D$4:$D$282,MATCH($B13&I$6,'Claim Data'!$C$4:$C$282&'Claim Data'!$B$4:$B$282,0)),"")} -> 5681000 | J13: {=IFERROR(INDEX('Claim Data'!$D$4:$D$282,MATCH($B13&J$6,'Claim Data'!$C$4:$C$282&'Claim Data'!$B$4:$B$282,0)),"")} -> 1971000 | K13: {=IFERROR(INDEX('Claim Data'!$D$4:$D$282,MATCH($B13&K$6,'Claim Data'!$C$4:$C$282&'Claim Data'!$B$4:$B$282,0)),"")} | ... AA13: {=IFERROR(INDEX('Claim Data'!$D$4:$D$282,MATCH($B13&AA$6,'Claim Data'!$C$4:$C$282&'Claim Data'!$B$4:$B$282,0)),"")}
B14: =EDATE(B13,1) -> 40756 | C14: =SUM(D14:AA14) -> 8831000 | D14: {=IFERROR(INDEX('Claim Data'!$D$4:$D$282,MATCH($B14&D$6,'Claim Data'!$C$4:$C$282&'Claim Data'!$B$4:$B$282,0)),"")} -> 16000 | E14: {=IFERROR(INDEX('Claim Data'!$D$4:$D$282,MATCH($B14&E$6,'Claim Data'!$C$4:$C$282&'Claim Data'!$B$4:$B$282,0)),"")} -> 102000 | F14: {=IFERROR(INDEX('Claim Data'!$D$4:$D$282,MATCH($B14&F$6,'Claim Data'!$C$4:$C$282&'Claim Data'!$B$4:$B$282,0)),"")} -> 93000 | G14: {=IFERROR(INDEX('Claim Data'!$D$4:$D$282,MATCH($B14&G$6,'Claim Data'!$C$4:$C$282&'Claim Data'!$B$4:$B$282,0)),"")} -> 283000 | H14: {=IFERROR(INDEX('Claim Data'!$D$4:$D$282,MATCH($B14&H$6,'Claim Data'!$C$4:$C$282&'Claim Data'!$B$4:$B$282,0)),"")} -> 442000 | I14: {=IFERROR(INDEX('Claim Data'!$D$4:$D$282,MATCH($B14&I$6,'Claim Data'!$C$4:$C$282&'Claim Data'!$B$4:$B$282,0)),"")} -> 1560000 | J14: {=IFERROR(INDEX('Claim Data'!$D$4:$D$282,MATCH($B14&J$6,'Claim Data'!$C$4:$C$282&'Claim Data'!$B$4:$B$282,0)),"")} -> 4605000 | K14: {=IFERROR(INDEX('Claim Data'!$D$4:$D$282,MATCH($B14&K$6,'Claim Data'!$C$4:$C$282&'Claim Data'!$B$4:$B$282,0)),"")} -> 1730000 | ... AA14: {=IFERROR(INDEX('Claim Data'!$D$4:$D$282,MATCH($B14&AA$6,'Claim Data'!$C$4:$C$282&'Claim Data'!$B$4:$B$282,0)),"")}
B15: =EDATE(B14,1) -> 40787 | C15: =SUM(D15:AA15) -> 9873000 | D15: {=IFERROR(INDEX('Claim Data'!$D$4:$D$282,MATCH($B15&D$6,'Claim Data'!$C$4:$C$282&'Claim Data'!$B$4:$B$282,0)),"")} -> 6000 | E15: {=IFERROR(INDEX('Claim Data'!$D$4:$D$282,MATCH($B15&E$6,'Claim Data'!$C$4:$C$282&'Claim Data'!$B$4:$B$282,0)),"")} -> 23000 | F15: {=IFERROR(INDEX('Claim Data'!$D$4:$D$282,MATCH($B15&F$6,'Claim Data'!$C$4:$C$282&'Claim Data'!$B$4:$B$282,0)),"")} -> 65000 | G15: {=IFERROR(INDEX('Claim Data'!$D$4:$D$282,MATCH($B15&G$6,'Claim Data'!$C$4:$C$282&'Claim Data'!$B$4:$B$282,0)),"")} -> 261000 | H15: {=IFERROR(INDEX('Claim Data'!$D$4:$D$282,MATCH($B15&H$6,'Claim Data'!$C$4:$C$282&'Claim Data'!$B$4:$B$282,0)),"")} -> 244000 | I15: {=IFERROR(INDEX('Claim Data'!$D$4:$D$282,MATCH($B15&I$6,'Claim Data'!$C$4:$C$282&'Claim Data'!$B$4:$B$282,0)),"")} -> 565000 | J15: {=IFERROR(INDEX('Claim Data'!$D$4:$D$282,MATCH($B15&J$6,'Claim Data'!$C$4:$C$282&'Claim Data'!$B$4:$B$282,0)),"")} -> 1706000 | K15: {=IFERROR(INDEX('Claim Data'!$D$4:$D$282,MATCH($B15&K$6,'Claim Data'!$C$4:$C$282&'Claim Data'!$B$4:$B$282,0)),"")} -> 5000000 | ... AA15: {=IFERROR(INDEX('Claim Data'!$D$4:$D$282,MATCH($B15&AA$6,'Claim Data'!$C$4:$C$282&'Claim Data'!$B$4:$B$282,0)),"")}
B16: =EDATE(B15,1) -> 40817 | C16: =SUM(D16:AA16) -> 8448000 | D16: {=IFERROR(INDEX('Claim Data'!$D$4:$D$282,MATCH($B16&D$6,'Claim Data'!$C$4:$C$282&'Claim Data'!$B$4:$B$282,0)),"")} -> 52000 | E16: {=IFERROR(INDEX('Claim Data'!$D$4:$D$282,MATCH($B16&E$6,'Claim Data'!$C$4:$C$282&'Claim Data'!$B$4:$B$282,0)),"")} -> 11000 | F16: {=IFERROR(INDEX('Claim Data'!$D$4:$D$282,MATCH($B16&F$6,'Claim Data'!$C$4:$C$282&'Claim Data'!$B$4:$B$282,0)),"")} -> 17000 | G16: {=IFERROR(INDEX('Claim Data'!$D$4:$D$282,MATCH($B16&G$6,'Claim Data'!$C$4:$C$282&'Claim Data'!$B$4:$B$282,0)),"")} -> 35000 | H16: {=IFERROR(INDEX('Claim Data'!$D$4:$D$282,MATCH($B16&H$6,'Claim Data'!$C$4:$C$282&'Claim Data'!$B$4:$B$282,0)),"")} -> 96000 | I16: {=IFERROR(INDEX('Claim Data'!$D$4:$D$282,MATCH($B16&I$6,'Claim Data'!$C$4:$C$282&'Claim Data'!$B$4:$B$282,0)),"")} -> 149000 | J16: {=IFERROR(INDEX('Claim Data'!$D$4:$D$282,MATCH($B16&J$6,'Claim Data'!$C$4:$C$282&'Claim Data'!$B$4:$B$282,0)),"")} -> 480000 | K16: {=IFERROR(INDEX('Claim Data'!$D$4:$D$282,MATCH($B16&K$6,'Claim Data'!$C$4:$C$282&'Claim Data'!$B$4:$B$282,0)),"")} -> 1243000 | ... AA16: {=IFERROR(INDEX('Claim Data'!$D$4:$D$282,MATCH($B16&AA$6,'Claim Data'!$C$4:$C$282&'Claim Data'!$B$4:$B$282,0)),"")}
B17: =EDATE(B16,1) -> 40848 | C17: =SUM(D17:AA17) -> 9493000 | D17: {=IFERROR(INDEX('Claim Data'!$D$4:$D$282,MATCH($B17&D$6,'Claim Data'!$C$4:$C$282&'Claim Data'!$B$4:$B$282,0)),"")} -> 21000 | E17: {=IFERROR(INDEX('Claim Data'!$D$4:$D$282,MATCH($B17&E$6,'Claim Data'!$C$4:$C$282&'Claim Data'!$B$4:$B$282,0)),"")} -> 24000 | F17: {=IFERROR(INDEX('Claim Data'!$D$4:$D$282,MATCH($B17&F$6,'Claim Data'!$C$4:$C$282&'Claim Data'!$B$4:$B$282,0)),"")} -> 16000 | G17: {=IFERROR(INDEX('Claim Data'!$D$4:$D$282,MATCH($B17&G$6,'Claim Data'!$C$4:$C$282&'Claim Data'!$B$4:$B$282,0)),"")} -> 26000 | H17: {=IFERROR(INDEX('Claim Data'!$D$4:$D$282,MATCH($B17&H$6,'Claim Data'!$C$4:$C$282&'Claim Data'!$B$4:$B$282,0)),"")} -> 24000 | I17: {=IFERROR(INDEX('Claim Data'!$D$4:$D$282,MATCH($B17&I$6,'Claim Data'!$C$4:$C$282&'Claim Data'!$B$4:$B$282,0)),"")} -> 129000 | J17: {=IFERROR(INDEX('Claim Data'!$D$4:$D$282,MATCH($B17&J$6,'Claim Data'!$C$4:$C$282&'Claim Data'!$B$4:$B$282,0)),"")} -> 126000 | K17: {=IFERROR(INDEX('Claim Data'!$D$4:$D$282,MATCH($B17&K$6,'Claim Data'!$C$4:$C$282&'Claim Data'!$B$4:$B$282,0)),"")} -> 873000 | ... AA17: {=IFERROR(INDEX('Claim Data'!$D$4:$D$282,MATCH($B17&AA$6,'Claim Data'!$C$4:$C$282&'Claim Data'!$B$4:$B$282,0)),"")}
B18: =EDATE(B17,1) -> 40878 | C18: =SUM(D18:AA18) -> 9935000 | D18: {=IFERROR(INDEX('Claim Data'!$D$4:$D$282,MATCH($B18&D$6,'Claim Data'!$C$4:$C$282&'Claim Data'!$B$4:$B$282,0)),"")} -> 85000 | E18: {=IFERROR(INDEX('Claim Data'!$D$4:$D$282,MATCH($B18&E$6,'Claim Data'!$C$4:$C$282&'Claim Data'!$B$4:$B$282,0)),"")} -> 29000 | F18: {=IFERROR(INDEX('Claim Data'!$D$4:$D$282,MATCH($B18&F$6,'Claim Data'!$C$4:$C$282&'Claim Data'!$B$4:$B$282,0)),"")} -> 29000 | G18: {=IFERROR(INDEX('Claim Data'!$D$4:$D$282,MATCH($B18&G$6,'Claim Data'!$C$4:$C$282&'Claim Data'!$B$4:$B$282,0)),"")} -> 17000 | H18: {=IFERROR(INDEX('Claim Data'!$D$4:$D$282,MATCH($B18&H$6,'Claim Data'!$C$4:$C$282&'Claim Data'!$B$4:$B$282,0)),"")} -> 18000 | I18: {=IFERROR(INDEX('Claim Data'!$D$4:$D$282,MATCH($B18&I$6,'Claim Data'!$C$4:$C$282&'Claim Data'!$B$4:$B$282,0)),"")} -> 128000 | J18: {=IFERROR(INDEX('Claim Data'!$D$4:$D$282,MATCH($B18&J$6,'Claim Data'!$C$4:$C$282&'Claim Data'!$B$4:$B$282,0)),"")} -> 91000 | K18: {=IFERROR(INDEX('Claim Data'!$D$4:$D$282,MATCH($B18&K$6,'Claim Data'!$C$4:$C$282&'Claim Data'!$B$4:$B$282,0)),"")} -> 291000 | ... AA18: {=IFERROR(INDEX('Claim Data'!$D$4:$D$282,MATCH($B18&AA$6,'Claim Data'!$C$4:$C$282&'Claim Data'!$B$4:$B$282,0)),"")}
B19: =EDATE(B18,1) -> 40909 | C19: =SUM(D19:AA19) -> 7149000 | D19: {=IFERROR(INDEX('Claim Data'!$D$4:$D$282,MATCH($B19&D$6,'Claim Data'!$C$4:$C$282&'Claim Data'!$B$4:$B$282,0)),"")} -> 2000 | E19: {=IFERROR(INDEX('Claim Data'!$D$4:$D$282,MATCH($B19&E$6,'Claim Data'!$C$4:$C$282&'Claim Data'!$B$4:$B$282,0)),"")} -> 10000 | F19: {=IFERROR(INDEX('Claim Data'!$D$4:$D$282,MATCH($B19&F$6,'Claim Data'!$C$4:$C$282&'Claim Data'!$B$4:$B$282,0)),"")} -> 21000 | G19: {=IFERROR(INDEX('Claim Data'!$D$4:$D$282,MATCH($B19&G$6,'Claim Data'!$C$4:$C$282&'Claim Data'!$B$4:$B$282,0)),"")} -> 10000 | H19: {=IFERROR(INDEX('Claim Data'!$D$4:$D$282,MATCH($B19&H$6,'Claim Data'!$C$4:$C$282&'Claim Data'!$B$4:$B$282,0)),"")} -> -5000 | I19: {=IFERROR(INDEX('Claim Data'!$D$4:$D$282,MATCH($B19&I$6,'Claim Data'!$C$4:$C$282&'Claim Data'!$B$4:$B$282,0)),"")} -> 37000 | J19: {=IFERROR(INDEX('Claim Data'!$D$4:$D$282,MATCH($B19&J$6,'Claim Data'!$C$4:$C$282&'Claim Data'!$B$4:$B$282,0)),"")} -> 78000 | K19: {=IFERROR(INDEX('Claim Data'!$D$4:$D$282,MATCH($B19&K$6,'Claim Data'!$C$4:$C$282&'Claim Data'!$B$4:$B$282,0)),"")} -> 101000 | ... AA19: {=IFERROR(INDEX('Claim Data'!$D$4:$D$282,MATCH($B19&AA$6,'Claim Data'!$C$4:$C$282&'Claim Data'!$B$4:$B$282,0)),"")}
... B30: =EDATE(B29,1) -> 41244 | C30: =SUM(D30:AA30) -> 8973000 | D30: {=IFERROR(INDEX('Claim Data'!$D$4:$D$282,MATCH($B30&D$6,'Claim Data'!$C$4:$C$282&'Claim Data'!$B$4:$B$282,0)),"")} | E30: {=IFERROR(INDEX('Claim Data'!$D$4:$D$282,MATCH($B30&E$6,'Claim Data'!$C$4:$C$282&'Claim Data'!$B$4:$B$282,0)),"")} | F30: {=IFERROR(INDEX('Claim Data'!$D$4:$D$282,MATCH($B30&F$6,'Claim Data'!$C$4:$C$282&'Claim Data'!$B$4:$B$282,0)),"")} | G30: {=IFERROR(INDEX('Claim Data'!$D$4:$D$282,MATCH($B30&G$6,'Claim Data'!$C$4:$C$282&'Claim Data'!$B$4:$B$282,0)),"")} | H30: {=IFERROR(INDEX('Claim Data'!$D$4:$D$282,MATCH($B30&H$6,'Claim Data'!$C$4:$C$282&'Claim Data'!$B$4:$B$282,0)),"")} | I30: {=IFERROR(INDEX('Claim Data'!$D$4:$D$282,MATCH($B30&I$6,'Claim Data'!$C$4:$C$282&'Claim Data'!$B$4:$B$282,0)),"")} | J30: {=IFERROR(INDEX('Claim Data'!$D$4:$D$282,MATCH($B30&J$6,'Claim Data'!$C$4:$C$282&'Claim Data'!$B$4:$B$282,0)),"")} -> 2000 | K30: {=IFERROR(INDEX('Claim Data'!$D$4:$D$282,MATCH($B30&K$6,'Claim Data'!$C$4:$C$282&'Claim Data'!$B$4:$B$282,0)),"")} -> 12000 | ... AA30: {=IFERROR(INDEX('Claim Data'!$D$4:$D$282,MATCH($B30&AA$6,'Claim Data'!$C$4:$C$282&'Claim Data'!$B$4:$B$282,0)),"")} -> 1938000
B31: Total | C31: =SUM(D31:AA31) -> 205299500 | D31: =SUM(D7:D30) -> 9971000 | E31: =SUM(E7:E30) -> 8351000 | F31: =SUM(F7:F30) -> 10797000 | G31: =SUM(G7:G30) -> 9382000 | H31: =SUM(H7:H30) -> 9536000 | I31: =SUM(I7:I30) -> 10355000 | J31: =SUM(J7:J30) -> 9137000 | K31: =SUM(K7:K30) -> 9459500 | ... AA31: =SUM(AA7:AA30) -> 1938000
B33: Membership: | C33: (thousands) | D33: =(LOOKUP(D$6,'Claim Data'!$G$4:$G$27,'Claim Data'!$H$4:$H$27))/1000 -> 47.76 | E33: =(LOOKUP(E$6,'Claim Data'!$G$4:$G$27,'Claim Data'!$H$4:$H$27))/1000 -> 46.98 | F33: =(LOOKUP(F$6,'Claim Data'!$G$4:$G$27,'Claim Data'!$H$4:$H$27))/1000 -> 46.3 | G33: =(LOOKUP(G$6,'Claim Data'!$G$4:$G$27,'Claim Data'!$H$4:$H$27))/1000 -> 45.52 | H33: =(LOOKUP(H$6,'Claim Data'!$G$4:$G$27,'Claim Data'!$H$4:$H$27))/1000 -> 45.38 | I33: =(LOOKUP(I$6,'Claim Data'!$G$4:$G$27,'Claim Data'!$H$4:$H$27))/1000 -> 44.72 | J33: =(LOOKUP(J$6,'Claim Data'!$G$4:$G$27,'Claim Data'!$H$4:$H$27))/1000 -> 43.52 | K33: =(LOOKUP(K$6,'Claim Data'!$G$4:$G$27,'Claim Data'!$H$4:$H$27))/1000 -> 42.5 | ... AA33: =(LOOKUP(AA$6,'Claim Data'!$G$4:$G$27,'Claim Data'!$H$4:$H$27))/1000 -> 40.11
C36: Inventory levels by reporting month and incurred month
C37: Inventory by Reporting Month and Incurred Month ("Paid Claims Triange") (in thousands of dollars)
C39: Incurred Month
B40: Reporting Month | C40: Total | D40: =B7 -> 40544 | E40: =EDATE(D40,1) -> 40575 | F40: =EDATE(E40,1) -> 40603 | G40: =EDATE(F40,1) -> 40634 | H40: =EDATE(G40,1) -> 40664 | I40: =EDATE(H40,1) -> 40695 | J40: =EDATE(I40,1) -> 40725 | K40: =EDATE(J40,1) -> 40756 | L40: =EDATE(K40,1) -> 40787 | ... AA40: =EDATE(Z40,1) -> 41244
B41: ='Claim Data'!B4 -> 40544 | C41: =SUM(D41:AA41) -> 329000 | D41: {=IFERROR(INDEX('Claim Data'!$E$4:$E$282,MATCH($B7&D$6,'Claim Data'!$C$4:$C$282&'Claim Data'!$B$4:$B$282,0)),"")} -> 329000 | E41: {=IFERROR(INDEX('Claim Data'!$E$4:$E$282,MATCH($B7&E$6,'Claim Data'!$C$4:$C$282&'Claim Data'!$B$4:$B$282,0)),"")} | F41: {=IFERROR(INDEX('Claim Data'!$E$4:$E$282,MATCH($B7&F$6,'Claim Data'!$C$4:$C$282&'Claim Data'!$B$4:$B$282,0)),"")} | G41: {=IFERROR(INDEX('Claim Data'!$E$4:$E$282,MATCH($B7&G$6,'Claim Data'!$C$4:$C$282&'Claim Data'!$B$4:$B$282,0)),"")} | H41: {=IFERROR(INDEX('Claim Data'!$E$4:$E$282,MATCH($B7&H$6,'Claim Data'!$C$4:$C$282&'Claim Data'!$B$4:$B$282,0)),"")} | I41: {=IFERROR(INDEX('Claim Data'!$E$4:$E$282,MATCH($B7&I$6,'Claim Data'!$C$4:$C$282&'Claim Data'!$B$4:$B$282,0)),"")} | J41: {=IFERROR(INDEX('Claim Data'!$E$4:$E$282,MATCH($B7&J$6,'Claim Data'!$C$4:$C$282&'Claim Data'!$B$4:$B$282,0)),"")} | K41: {=IFERROR(INDEX('Claim Data'!$E$4:$E$282,MATCH($B7&K$6,'Claim Data'!$C$4:$C$282&'Claim Data'!$B$4:$B$282,0)),"")} | ... AA41: {=IFERROR(INDEX('Claim Data'!$E$4:$E$282,MATCH($B7&AA$6,'Claim Data'!$C$4:$C$282&'Claim Data'!$B$4:$B$282,0)),"")}
B42: =EDATE(B41,1) -> 40575 | C42: =SUM(D42:AA42) -> 683000 | D42: {=IFERROR(INDEX('Claim Data'!$E$4:$E$282,MATCH($B8&D$6,'Claim Data'!$C$4:$C$282&'Claim Data'!$B$4:$B$282,0)),"")} -> 8000 | E42: {=IFERROR(INDEX('Claim Data'!$E$4:$E$282,MATCH($B8&E$6,'Claim Data'!$C$4:$C$282&'Claim Data'!$B$4:$B$282,0)),"")} -> 675000 | F42: {=IFERROR(INDEX('Claim Data'!$E$4:$E$282,MATCH($B8&F$6,'Claim Data'!$C$4:$C$282&'Claim Data'!$B$4:$B$282,0)),"")} | G42: {=IFERROR(INDEX('Claim Data'!$E$4:$E$282,MATCH($B8&G$6,'Claim Data'!$C$4:$C$282&'Claim Data'!$B$4:$B$282,0)),"")} | H42: {=IFERROR(INDEX('Claim Data'!$E$4:$E$282,MATCH($B8&H$6,'Claim Data'!$C$4:$C$282&'Claim Data'!$B$4:$B$282,0)),"")} | I42: {=IFERROR(INDEX('Claim Data'!$E$4:$E$282,MATCH($B8&I$6,'Claim Data'!$C$4:$C$282&'Claim Data'!$B$4:$B$282,0)),"")} | J42: {=IFERROR(INDEX('Claim Data'!$E$4:$E$282,MATCH($B8&J$6,'Claim Data'!$C$4:$C$282&'Claim Data'!$B$4:$B$282,0)),"")} | K42: {=IFERROR(INDEX('Claim Data'!$E$4:$E$282,MATCH($B8&K$6,'Claim Data'!$C$4:$C$282&'Claim Data'!$B$4:$B$282,0)),"")} | ... AA42: {=IFERROR(INDEX('Claim Data'!$E$4:$E$282,MATCH($B8&AA$6,'Claim Data'!$C$4:$C$282&'Claim Data'!$B$4:$B$282,0)),"")}
B43: =EDATE(B42,1) -> 40603 | C43: =SUM(D43:AA43) -> 648000 | D43: {=IFERROR(INDEX('Claim Data'!$E$4:$E$282,MATCH($B9&D$6,'Claim Data'!$C$4:$C$282&'Claim Data'!$B$4:$B$282,0)),"")} -> 17000 | E43: {=IFERROR(INDEX('Claim Data'!$E$4:$E$282,MATCH($B9&E$6,'Claim Data'!$C$4:$C$282&'Claim Data'!$B$4:$B$282,0)),"")} -> 13000 | F43: {=IFERROR(INDEX('Claim Data'!$E$4:$E$282,MATCH($B9&F$6,'Claim Data'!$C$4:$C$282&'Claim Data'!$B$4:$B$282,0)),"")} -> 618000 | G43: {=IFERROR(INDEX('Claim Data'!$E$4:$E$282,MATCH($B9&G$6,'Claim Data'!$C$4:$C$282&'Claim Data'!$B$4:$B$282,0)),"")} | H43: {=IFERROR(INDEX('Claim Data'!$E$4:$E$282,MATCH($B9&H$6,'Claim Data'!$C$4:$C$282&'Claim Data'!$B$4:$B$282,0)),"")} | I43: {=IFERROR(INDEX('Claim Data'!$E$4:$E$282,MATCH($B9&I$6,'Claim Data'!$C$4:$C$282&'Claim Data'!$B$4:$B$282,0)),"")} | J43: {=IFERROR(INDEX('Claim Data'!$E$4:$E$282,MATCH($B9&J$6,'Claim Data'!$C$4:$C$282&'Claim Data'!$B$4:$B$282,0)),"")} | K43: {=IFERROR(INDEX('Claim Data'!$E$4:$E$282,MATCH($B9&K$6,'Claim Data'!$C$4:$C$282&'Claim Data'!$B$4:$B$282,0)),"")} | ... AA43: {=IFERROR(INDEX('Claim Data'!$E$4:$E$282,MATCH($B9&AA$6,'Claim Data'!$C$4:$C$282&'Claim Data'!$B$4:$B$282,0)),"")}
B44: =EDATE(B43,1) -> 40634 | C44: =SUM(D44:AA44) -> 219000 | D44: {=IFERROR(INDEX('Claim Data'!$E$4:$E$282,MATCH($B10&D$6,'Claim Data'!$C$4:$C$282&'Claim Data'!$B$4:$B$282,0)),"")} -> 10000 | E44: {=IFERROR(INDEX('Claim Data'!$E$4:$E$282,MATCH($B10&E$6,'Claim Data'!$C$4:$C$282&'Claim Data'!$B$4:$B$282,0)),"")} -> 8000 | F44: {=IFERROR(INDEX('Claim Data'!$E$4:$E$282,MATCH($B10&F$6,'Claim Data'!$C$4:$C$282&'Claim Data'!$B$4:$B$282,0)),"")} -> 88000 | G44: {=IFERROR(INDEX('Claim Data'!$E$4:$E$282,MATCH($B10&G$6,'Claim Data'!$C$4:$C$282&'Claim Data'!$B$4:$B$282,0)),"")} -> 113000 | H44: {=IFERROR(INDEX('Claim Data'!$E$4:$E$282,MATCH($B10&H$6,'Claim Data'!$C$4:$C$282&'Claim Data'!$B$4:$B$282,0)),"")} | I44: {=IFERROR(INDEX('Claim Data'!$E$4:$E$282,MATCH($B10&I$6,'Claim Data'!$C$4:$C$282&'Claim Data'!$B$4:$B$282,0)),"")} | J44: {=IFERROR(INDEX('Claim Data'!$E$4:$E$282,MATCH($B10&J$6,'Claim Data'!$C$4:$C$282&'Claim Data'!$B$4:$B$282,0)),"")} | K44: {=IFERROR(INDEX('Claim Data'!$E$4:$E$282,MATCH($B10&K$6,'Claim Data'!$C$4:$C$282&'Claim Data'!$B$4:$B$282,0)),"")} | ... AA44: {=IFERROR(INDEX('Claim Data'!$E$4:$E$282,MATCH($B10&AA$6,'Claim Data'!$C$4:$C$282&'Claim Data'!$B$4:$B$282,0)),"")}
B45: =EDATE(B44,1) -> 40664 | C45: =SUM(D45:AA45) -> 462000 | D45: {=IFERROR(INDEX('Claim Data'!$E$4:$E$282,MATCH($B11&D$6,'Claim Data'!$C$4:$C$282&'Claim Data'!$B$4:$B$282,0)),"")} -> 4000 | E45: {=IFERROR(INDEX('Claim Data'!$E$4:$E$282,MATCH($B11&E$6,'Claim Data'!$C$4:$C$282&'Claim Data'!$B$4:$B$282,0)),"")} -> 11000 | F45: {=IFERROR(INDEX('Claim Data'!$E$4:$E$282,MATCH($B11&F$6,'Claim Data'!$C$4:$C$282&'Claim Data'!$B$4:$B$282,0)),"")} -> 20000 | G45: {=IFERROR(INDEX('Claim Data'!$E$4:$E$282,MATCH($B11&G$6,'Claim Data'!$C$4:$C$282&'Claim Data'!$B$4:$B$282,0)),"")} -> 16000 | H45: {=IFERROR(INDEX('Claim Data'!$E$4:$E$282,MATCH($B11&H$6,'Claim Data'!$C$4:$C$282&'Claim Data'!$B$4:$B$282,0)),"")} -> 411000 | I45: {=IFERROR(INDEX('Claim Data'!$E$4:$E$282,MATCH($B11&I$6,'Claim Data'!$C$4:$C$282&'Claim Data'!$B$4:$B$282,0)),"")} | J45: {=IFERROR(INDEX('Claim Data'!$E$4:$E$282,MATCH($B11&J$6,'Claim Data'!$C$4:$C$282&'Claim Data'!$B$4:$B$282,0)),"")} | K45: {=IFERROR(INDEX('Claim Data'!$E$4:$E$282,MATCH($B11&K$6,'Claim Data'!$C$4:$C$282&'Claim Data'!$B$4:$B$282,0)),"")} | ... AA45: {=IFERROR(INDEX('Claim Data'!$E$4:$E$282,MATCH($B11&AA$6,'Claim Data'!$C$4:$C$282&'Claim Data'!$B$4:$B$282,0)),"")}
B46: =EDATE(B45,1) -> 40695 | C46: =SUM(D46:AA46) -> 507000 | D46: {=IFERROR(INDEX('Claim Data'!$E$4:$E$282,MATCH($B12&D$6,'Claim Data'!$C$4:$C$282&'Claim Data'!$B$4:$B$282,0)),"")} -> 3000 | E46: {=IFERROR(INDEX('Claim Data'!$E$4:$E$282,MATCH($B12&E$6,'Claim Data'!$C$4:$C$282&'Claim Data'!$B$4:$B$282,0)),"")} -> 9000 | F46: {=IFERROR(INDEX('Claim Data'!$E$4:$E$282,MATCH($B12&F$6,'Claim Data'!$C$4:$C$282&'Claim Data'!$B$4:$B$282,0)),"")} -> 23000 | G46: {=IFERROR(INDEX('Claim Data'!$E$4:$E$282,MATCH($B12&G$6,'Claim Data'!$C$4:$C$282&'Claim Data'!$B$4:$B$282,0)),"")} -> 15000 | H46: {=IFERROR(INDEX('Claim Data'!$E$4:$E$282,MATCH($B12&H$6,'Claim Data'!$C$4:$C$282&'Claim Data'!$B$4:$B$282,0)),"")} -> 50000 | I46: {=IFERROR(INDEX('Claim Data'!$E$4:$E$282,MATCH($B12&I$6,'Claim Data'!$C$4:$C$282&'Claim Data'!$B$4:$B$282,0)),"")} -> 407000 | J46: {=IFERROR(INDEX('Claim Data'!$E$4:$E$282,MATCH($B12&J$6,'Claim Data'!$C$4:$C$282&'Claim Data'!$B$4:$B$282,0)),"")} | K46: {=IFERROR(INDEX('Claim Data'!$E$4:$E$282,MATCH($B12&K$6,'Claim Data'!$C$4:$C$282&'Claim Data'!$B$4:$B$282,0)),"")} | ... AA46: {=IFERROR(INDEX('Claim Data'!$E$4:$E$282,MATCH($B12&AA$6,'Claim Data'!$C$4:$C$282&'Claim Data'!$B$4:$B$282,0)),"")}
B47: =EDATE(B46,1) -> 40725 | C47: =SUM(D47:AA47) -> 724000 | D47: {=IFERROR(INDEX('Claim Data'!$E$4:$E$282,MATCH($B13&D$6,'Claim Data'!$C$4:$C$282&'Claim Data'!$B$4:$B$282,0)),"")} -> 2000 | E47: {=IFERROR(INDEX('Claim Data'!$E$4:$E$282,MATCH($B13&E$6,'Claim Data'!$C$4:$C$282&'Claim Data'!$B$4:$B$282,0)),"")} -> 13000 | F47: {=IFERROR(INDEX('Claim Data'!$E$4:$E$282,MATCH($B13&F$6,'Claim Data'!$C$4:$C$282&'Claim Data'!$B$4:$B$282,0)),"")} -> 20000 | G47: {=IFERROR(INDEX('Claim Data'!$E$4:$E$282,MATCH($B13&G$6,'Claim Data'!$C$4:$C$282&'Claim Data'!$B$4:$B$282,0)),"")} -> 8000 | H47: {=IFERROR(INDEX('Claim Data'!$E$4:$E$282,MATCH($B13&H$6,'Claim Data'!$C$4:$C$282&'Claim Data'!$B$4:$B$282,0)),"")} -> 28000 | I47: {=IFERROR(INDEX('Claim Data'!$E$4:$E$282,MATCH($B13&I$6,'Claim Data'!$C$4:$C$282&'Claim Data'!$B$4:$B$282,0)),"")} -> 127000 | J47: {=IFERROR(INDEX('Claim Data'!$E$4:$E$282,MATCH($B13&J$6,'Claim Data'!$C$4:$C$282&'Claim Data'!$B$4:$B$282,0)),"")} -> 526000 | K47: {=IFERROR(INDEX('Claim Data'!$E$4:$E$282,MATCH($B13&K$6,'Claim Data'!$C$4:$C$282&'Claim Data'!$B$4:$B$282,0)),"")} | ... AA47: {=IFERROR(INDEX('Claim Data'!$E$4:$E$282,MATCH($B13&AA$6,'Claim Data'!$C$4:$C$282&'Claim Data'!$B$4:$B$282,0)),"")}
B48: =EDATE(B47,1) -> 40756 | C48: =SUM(D48:AA48) -> 894000 | D48: {=IFERROR(INDEX('Claim Data'!$E$4:$E$282,MATCH($B14&D$6,'Claim Data'!$C$4:$C$282&'Claim Data'!$B$4:$B$282,0)),"")} -> 3000 | E48: {=IFERROR(INDEX('Claim Data'!$E$4:$E$282,MATCH($B14&E$6,'Claim Data'!$C$4:$C$282&'Claim Data'!$B$4:$B$282,0)),"")} -> 5000 | F48: {=IFERROR(INDEX('Claim Data'!$E$4:$E$282,MATCH($B14&F$6,'Claim Data'!$C$4:$C$282&'Claim Data'!$B$4:$B$282,0)),"")} -> 25000 | G48: {=IFERROR(INDEX('Claim Data'!$E$4:$E$282,MATCH($B14&G$6,'Claim Data'!$C$4:$C$282&'Claim Data'!$B$4:$B$282,0)),"")} -> 9000 | H48: {=IFERROR(INDEX('Claim Data'!$E$4:$E$282,MATCH($B14&H$6,'Claim Data'!$C$4:$C$282&'Claim Data'!$B$4:$B$282,0)),"")} -> 13000 | I48: {=IFERROR(INDEX('Claim Data'!$E$4:$E$282,MATCH($B14&I$6,'Claim Data'!$C$4:$C$282&'Claim Data'!$B$4:$B$282,0)),"")} -> 143000 | J48: {=IFERROR(INDEX('Claim Data'!$E$4:$E$282,MATCH($B14&J$6,'Claim Data'!$C$4:$C$282&'Claim Data'!$B$4:$B$282,0)),"")} -> 239000 | K48: {=IFERROR(INDEX('Claim Data'!$E$4:$E$282,MATCH($B14&K$6,'Claim Data'!$C$4:$C$282&'Claim Data'!$B$4:$B$282,0)),"")} -> 457000 | ... AA48: {=IFERROR(INDEX('Claim Data'!$E$4:$E$282,MATCH($B14&AA$6,'Claim Data'!$C$4:$C$282&'Claim Data'!$B$4:$B$282,0)),"")}
B49: =EDATE(B48,1) -> 40787 | C49: =SUM(D49:AA49) -> 1399000 | D49: {=IFERROR(INDEX('Claim Data'!$E$4:$E$282,MATCH($B15&D$6,'Claim Data'!$C$4:$C$282&'Claim Data'!$B$4:$B$282,0)),"")} -> 1000 | E49: {=IFERROR(INDEX('Claim Data'!$E$4:$E$282,MATCH($B15&E$6,'Claim Data'!$C$4:$C$282&'Claim Data'!$B$4:$B$282,0)),"")} -> 4000 | F49: {=IFERROR(INDEX('Claim Data'!$E$4:$E$282,MATCH($B15&F$6,'Claim Data'!$C$4:$C$282&'Claim Data'!$B$4:$B$282,0)),"")} -> 8000 | G49: {=IFERROR(INDEX('Claim Data'!$E$4:$E$282,MATCH($B15&G$6,'Claim Data'!$C$4:$C$282&'Claim Data'!$B$4:$B$282,0)),"")} -> 4000 | H49: {=IFERROR(INDEX('Claim Data'!$E$4:$E$282,MATCH($B15&H$6,'Claim Data'!$C$4:$C$282&'Claim Data'!$B$4:$B$282,0)),"")} -> 4000 | I49: {=IFERROR(INDEX('Claim Data'!$E$4:$E$282,MATCH($B15&I$6,'Claim Data'!$C$4:$C$282&'Claim Data'!$B$4:$B$282,0)),"")} -> 24000 | J49: {=IFERROR(INDEX('Claim Data'!$E$4:$E$282,MATCH($B15&J$6,'Claim Data'!$C$4:$C$282&'Claim Data'!$B$4:$B$282,0)),"")} -> 162000 | K49: {=IFERROR(INDEX('Claim Data'!$E$4:$E$282,MATCH($B15&K$6,'Claim Data'!$C$4:$C$282&'Claim Data'!$B$4:$B$282,0)),"")} -> 705000 | ... AA49: {=IFERROR(INDEX('Claim Data'!$E$4:$E$282,MATCH($B15&AA$6,'Claim Data'!$C$4:$C$282&'Claim Data'!$B$4:$B$282,0)),"")}
B50: =EDATE(B49,1) -> 40817 | C50: =SUM(D50:AA50) -> 1162000 | D50: {=IFERROR(INDEX('Claim Data'!$E$4:$E$282,MATCH($B16&D$6,'Claim Data'!$C$4:$C$282&'Claim Data'!$B$4:$B$282,0)),"")} -> 9000 | E50: {=IFERROR(INDEX('Claim Data'!$E$4:$E$282,MATCH($B16&E$6,'Claim Data'!$C$4:$C$282&'Claim Data'!$B$4:$B$282,0)),"")} -> 6000 | F50: {=IFERROR(INDEX('Claim Data'!$E$4:$E$282,MATCH($B16&F$6,'Claim Data'!$C$4:$C$282&'Claim Data'!$B$4:$B$282,0)),"")} -> 5000 | G50: {=IFERROR(INDEX('Claim Data'!$E$4:$E$282,MATCH($B16&G$6,'Claim Data'!$C$4:$C$282&'Claim Data'!$B$4:$B$282,0)),"")} -> 21000 | H50: {=IFERROR(INDEX('Claim Data'!$E$4:$E$282,MATCH($B16&H$6,'Claim Data'!$C$4:$C$282&'Claim Data'!$B$4:$B$282,0)),"")} -> 6000 | I50: {=IFERROR(INDEX('Claim Data'!$E$4:$E$282,MATCH($B16&I$6,'Claim Data'!$C$4:$C$282&'Claim Data'!$B$4:$B$282,0)),"")} -> 21000 | J50: {=IFERROR(INDEX('Claim Data'!$E$4:$E$282,MATCH($B16&J$6,'Claim Data'!$C$4:$C$282&'Claim Data'!$B$4:$B$282,0)),"")} -> 10000 | K50: {=IFERROR(INDEX('Claim Data'!$E$4:$E$282,MATCH($B16&K$6,'Claim Data'!$C$4:$C$282&'Claim Data'!$B$4:$B$282,0)),"")} -> 99000 | ... AA50: {=IFERROR(INDEX('Claim Data'!$E$4:$E$282,MATCH($B16&AA$6,'Claim Data'!$C$4:$C$282&'Claim Data'!$B$4:$B$282,0)),"")}
B51: =EDATE(B50,1) -> 40848 | C51: =SUM(D51:AA51) -> 1034000 | D51: {=IFERROR(INDEX('Claim Data'!$E$4:$E$282,MATCH($B17&D$6,'Claim Data'!$C$4:$C$282&'Claim Data'!$B$4:$B$282,0)),"")} -> 1000 | E51: {=IFERROR(INDEX('Claim Data'!$E$4:$E$282,MATCH($B17&E$6,'Claim Data'!$C$4:$C$282&'Claim Data'!$B$4:$B$282,0)),"")} -> 0 | F51: {=IFERROR(INDEX('Claim Data'!$E$4:$E$282,MATCH($B17&F$6,'Claim Data'!$C$4:$C$282&'Claim Data'!$B$4:$B$282,0)),"")} -> 3000 | G51: {=IFERROR(INDEX('Claim Data'!$E$4:$E$282,MATCH($B17&G$6,'Claim Data'!$C$4:$C$282&'Claim Data'!$B$4:$B$282,0)),"")} -> 1000 | H51: {=IFERROR(INDEX('Claim Data'!$E$4:$E$282,MATCH($B17&H$6,'Claim Data'!$C$4:$C$282&'Claim Data'!$B$4:$B$282,0)),"")} -> 10000 | I51: {=IFERROR(INDEX('Claim Data'!$E$4:$E$282,MATCH($B17&I$6,'Claim Data'!$C$4:$C$282&'Claim Data'!$B$4:$B$282,0)),"")} -> 7000 | J51: {=IFERROR(INDEX('Claim Data'!$E$4:$E$282,MATCH($B17&J$6,'Claim Data'!$C$4:$C$282&'Claim Data'!$B$4:$B$282,0)),"")} -> 4000 | K51: {=IFERROR(INDEX('Claim Data'!$E$4:$E$282,MATCH($B17&K$6,'Claim Data'!$C$4:$C$282&'Claim Data'!$B$4:$B$282,0)),"")} -> 69000 | ... AA51: {=IFERROR(INDEX('Claim Data'!$E$4:$E$282,MATCH($B17&AA$6,'Claim Data'!$C$4:$C$282&'Claim Data'!$B$4:$B$282,0)),"")}
B52: =EDATE(B51,1) -> 40878 | C52: =SUM(D52:AA52) -> 634000 | D52: {=IFERROR(INDEX('Claim Data'!$E$4:$E$282,MATCH($B18&D$6,'Claim Data'!$C$4:$C$282&'Claim Data'!$B$4:$B$282,0)),"")} -> 3000 | E52: {=IFERROR(INDEX('Claim Data'!$E$4:$E$282,MATCH($B18&E$6,'Claim Data'!$C$4:$C$282&'Claim Data'!$B$4:$B$282,0)),"")} -> 1000 | F52: {=IFERROR(INDEX('Claim Data'!$E$4:$E$282,MATCH($B18&F$6,'Claim Data'!$C$4:$C$282&'Claim Data'!$B$4:$B$282,0)),"")} -> 1000 | G52: {=IFERROR(INDEX('Claim Data'!$E$4:$E$282,MATCH($B18&G$6,'Claim Data'!$C$4:$C$282&'Claim Data'!$B$4:$B$282,0)),"")} -> 4000 | H52: {=IFERROR(INDEX('Claim Data'!$E$4:$E$282,MATCH($B18&H$6,'Claim Data'!$C$4:$C$282&'Claim Data'!$B$4:$B$282,0)),"")} -> 3000 | I52: {=IFERROR(INDEX('Claim Data'!$E$4:$E$282,MATCH($B18&I$6,'Claim Data'!$C$4:$C$282&'Claim Data'!$B$4:$B$282,0)),"")} -> 5000 | J52: {=IFERROR(INDEX('Claim Data'!$E$4:$E$282,MATCH($B18&J$6,'Claim Data'!$C$4:$C$282&'Claim Data'!$B$4:$B$282,0)),"")} -> 15000 | K52: {=IFERROR(INDEX('Claim Data'!$E$4:$E$282,MATCH($B18&K$6,'Claim Data'!$C$4:$C$282&'Claim Data'!$B$4:$B$282,0)),"")} -> 69000 | ... AA52: {=IFERROR(INDEX('Claim Data'!$E$4:$E$282,MATCH($B18&AA$6,'Claim Data'!$C$4:$C$282&'Claim Data'!$B$4:$B$282,0)),"")}
B53: =EDATE(B52,1) -> 40909 | C53: =SUM(D53:AA53) -> 744000 | D53: {=IFERROR(INDEX('Claim Data'!$E$4:$E$282,MATCH($B19&D$6,'Claim Data'!$C$4:$C$282&'Claim Data'!$B$4:$B$282,0)),"")} -> 0 | E53: {=IFERROR(INDEX('Claim Data'!$E$4:$E$282,MATCH($B19&E$6,'Claim Data'!$C$4:$C$282&'Claim Data'!$B$4:$B$282,0)),"")} -> 0 | F53: {=IFERROR(INDEX('Claim Data'!$E$4:$E$282,MATCH($B19&F$6,'Claim Data'!$C$4:$C$282&'Claim Data'!$B$4:$B$282,0)),"")} -> 0 | G53: {=IFERROR(INDEX('Claim Data'!$E$4:$E$282,MATCH($B19&G$6,'Claim Data'!$C$4:$C$282&'Claim Data'!$B$4:$B$282,0)),"")} -> 1000 | H53: {=IFERROR(INDEX('Claim Data'!$E$4:$E$282,MATCH($B19&H$6,'Claim Data'!$C$4:$C$282&'Claim Data'!$B$4:$B$282,0)),"")} -> 75000 | I53: {=IFERROR(INDEX('Claim Data'!$E$4:$E$282,MATCH($B19&I$6,'Claim Data'!$C$4:$C$282&'Claim Data'!$B$4:$B$282,0)),"")} -> 2000 | J53: {=IFERROR(INDEX('Claim Data'!$E$4:$E$282,MATCH($B19&J$6,'Claim Data'!$C$4:$C$282&'Claim Data'!$B$4:$B$282,0)),"")} -> 97000 | K53: {=IFERROR(INDEX('Claim Data'!$E$4:$E$282,MATCH($B19&K$6,'Claim Data'!$C$4:$C$282&'Claim Data'!$B$4:$B$282,0)),"")} -> 15000 | ... AA53: {=IFERROR(INDEX('Claim Data'!$E$4:$E$282,MATCH($B19&AA$6,'Claim Data'!$C$4:$C$282&'Claim Data'!$B$4:$B$282,0)),"")}
... B64: =EDATE(B63,1) -> 41244 | C64: =SUM(D64:AA64) -> 2643877 | D64: {=IFERROR(INDEX('Claim Data'!$E$4:$E$282,MATCH($B30&D$6,'Claim Data'!$C$4:$C$282&'Claim Data'!$B$4:$B$282,0)),"")} | E64: {=IFERROR(INDEX('Claim Data'!$E$4:$E$282,MATCH($B30&E$6,'Claim Data'!$C$4:$C$282&'Claim Data'!$B$4:$B$282,0)),"")} | F64: {=IFERROR(INDEX('Claim Data'!$E$4:$E$282,MATCH($B30&F$6,'Claim Data'!$C$4:$C$282&'Claim Data'!$B$4:$B$282,0)),"")} | G64: {=IFERROR(INDEX('Claim Data'!$E$4:$E$282,MATCH($B30&G$6,'Claim Data'!$C$4:$C$282&'Claim Data'!$B$4:$B$282,0)),"")} | H64: {=IFERROR(INDEX('Claim Data'!$E$4:$E$282,MATCH($B30&H$6,'Claim Data'!$C$4:$C$282&'Claim Data'!$B$4:$B$282,0)),"")} | I64: {=IFERROR(INDEX('Claim Data'!$E$4:$E$282,MATCH($B30&I$6,'Claim Data'!$C$4:$C$282&'Claim Data'!$B$4:$B$282,0)),"")} | J64: {=IFERROR(INDEX('Claim Data'!$E$4:$E$282,MATCH($B30&J$6,'Claim Data'!$C$4:$C$282&'Claim Data'!$B$4:$B$282,0)),"")} -> 13000 | K64: {=IFERROR(INDEX('Claim Data'!$E$4:$E$282,MATCH($B30&K$6,'Claim Data'!$C$4:$C$282&'Claim Data'!$B$4:$B$282,0)),"")} -> 0 | ... AA64: {=IFERROR(INDEX('Claim Data'!$E$4:$E$282,MATCH($B30&AA$6,'Claim Data'!$C$4:$C$282&'Claim Data'!$B$4:$B$282,0)),"")} -> 1420125
B65: Total | C65: =SUM(D65:AA65) -> 21199275 | D65: =SUM(D41:D64) -> 390000 | E65: =SUM(E41:E64) -> 746000 | F65: =SUM(F41:F64) -> 817000 | G65: =SUM(G41:G64) -> 192000 | H65: =SUM(H41:H64) -> 609000 | I65: =SUM(I41:I64) -> 743000 | J65: =SUM(J41:J64) -> 1089500 | K65: =SUM(K41:K64) -> 1467500 | ... AA65: =SUM(AA41:AA64) -> 1420125
B75: =VALUE('Claim Data'!B4)&VALUE('Claim Data'!C4) -> 4054440544
...

Sheet Claim Data
B2: CLAIM DATA in '000 | G2: MEMBERSHIP DATA | K2: Data as of date | L2: 41275 | AB2: Date Calculation for various titles
B3: INCURRED MONTH | C3: PAID MONTH | D3: PAID CLAIM AMOUNT | E3: INVENTORY | G3: INCURRED MONTH | H3: MEMBERSHIP | AB3: Earliest | AC3: =MIN(B4:C282) -> 40544 | AD3: =TEXT(DATE(YEAR(AC4),MONTH(AC4),VLOOKUP(MONTH(AC4),$AD$4:$AE$15,2)),"mm/dd/yy") -> 12/31/12 | AE3: =TEXT(DATE(YEAR(AC4+32),MONTH(AC4+32),1),"mm/yy") -> 01/13 | AF3: =TEXT(DATE(YEAR(AC4+31*6),MONTH(AC4+31*6),1),"mm/yy") -> 06/13 | AG3: =TEXT(DATE(YEAR(AC4+6*31),MONTH(AC4+6*31),VLOOKUP(MONTH(AC4+6*31),AD4:AE15,2)),"mm/dd/yy") -> 06/30/13
A4: 24 | B4: =EDATE($L$2,-A4) -> 40544 | C4: =IF(B4<>B3,B4,EDATE(C3,1)) -> 40544 | D4: 1649000 | E4: 329000 | G4: =B4 -> 40544 | H4: 47760 | AB4: Latest | AC4: =MAX(B4:C282) -> 41244 | AD4: 1 | AE4: 31
A5: 24 | B5: =EDATE($L$2,-A5) -> 40544 | C5: =IF(B5<>B4,B5,EDATE(C4,1)) -> 40575 | D5: 4580000 | E5: 8000 | G5: =EDATE(G4,1) -> 40575 | H5: 46980 | AB5: 12 Mo | AC5: =DATE(YEAR(AC4)-1,MONTH(AC4),DAY(AC4)) -> 40878 | AD5: 2 | AE5: 28
A6: 24 | B6: =EDATE($L$2,-A6) -> 40544 | C6: =IF(B6<>B5,B6,EDATE(C5,1)) -> 40603 | D6: 1934000 | E6: 17000 | G6: =EDATE(G5,1) -> 40603 | H6: 46300 | AD6: 3 | AE6: 31
A7: 24 | B7: =EDATE($L$2,-A7) -> 40544 | C7: =IF(B7<>B6,B7,EDATE(C6,1)) -> 40634 | D7: 1152000 | E7: 10000 | G7: =EDATE(G6,1) -> 40634 | H7: 45520 | AD7: 4 | AE7: 30
A8: 24 | B8: =EDATE($L$2,-A8) -> 40544 | C8: =IF(B8<>B7,B8,EDATE(C7,1)) -> 40664 | D8: 221000 | E8: 4000 | G8: =EDATE(G7,1) -> 40664 | H8: 45380 | AD8: 5 | AE8: 31
A9: 24 | B9: =EDATE($L$2,-A9) -> 40544 | C9: =IF(B9<>B8,B9,EDATE(C8,1)) -> 40695 | D9: 173000 | E9: 3000 | G9: =EDATE(G8,1) -> 40695 | H9: 44720 | AD9: 6 | AE9: 30
A10: 24 | B10: =EDATE($L$2,-A10) -> 40544 | C10: =IF(B10<>B9,B10,EDATE(C9,1)) -> 40725 | D10: 60000 | E10: 2000 | G10: =EDATE(G9,1) -> 40725 | H10: 43520 | AD10: 7 | AE10: 31
A11: 24 | B11: =EDATE($L$2,-A11) -> 40544 | C11: =IF(B11<>B10,B11,EDATE(C10,1)) -> 40756 | D11: 16000 | E11: 3000 | G11: =EDATE(G10,1) -> 40756 | H11: 42500 | AD11: 8 | AE11: 31
A12: 24 | B12: =EDATE($L$2,-A12) -> 40544 | C12: =IF(B12<>B11,B12,EDATE(C11,1)) -> 40787 | D12: 6000 | E12: 1000 | G12: =EDATE(G11,1) -> 40787 | H12: 42360 | AD12: 9 | AE12: 30
A13: 24 | B13: =EDATE($L$2,-A13) -> 40544 | C13: =IF(B13<>B12,B13,EDATE(C12,1)) -> 40817 | D13: 52000 | E13: 9000 | G13: =EDATE(G12,1) -> 40817 | H13: 42020 | AD13: 10 | AE13: 31
A14: 24 | B14: =EDATE($L$2,-A14) -> 40544 | C14: =IF(B14<>B13,B14,EDATE(C13,1)) -> 40848 | D14: 21000 | E14: 1000 | G14: =EDATE(G13,1) -> 40848 | H14: 41850 | AD14: 11 | AE14: 30
A15: 24 | B15: =EDATE($L$2,-A15) -> 40544 | C15: =IF(B15<>B14,B15,EDATE(C14,1)) -> 40878 | D15: 85000 | E15: 3000 | G15: =EDATE(G14,1) -> 40878 | H15: 42250 | AD15: 12 | AE15: 31
A16: 24 | B16: =EDATE($L$2,-A16) -> 40544 | C16: =IF(B16<>B15,B16,EDATE(C15,1)) -> 40909 | D16: 2000 | E16: 0 | G16: =EDATE(G15,1) -> 40909 | H16: 37430
A17: 24 | B17: =EDATE($L$2,-A17) -> 40544 | C17: =IF(B17<>B16,B17,EDATE(C16,1)) -> 40940 | D17: 9000 | E17: 0 | G17: =EDATE(G16,1) -> 40940 | H17: 39350
A18: 24 | B18: =EDATE($L$2,-A18) -> 40544 | C18: =IF(B18<>B17,B18,EDATE(C17,1)) -> 40969 | D18: 5000 | E18: 0 | G18: =EDATE(G17,1) -> 40969 | H18: 40060
A19: 24 | B19: =EDATE($L$2,-A19) -> 40544 | C19: =IF(B19<>B18,B19,EDATE(C18,1)) -> 41000 | D19: 2000 | E19: 0 | G19: =EDATE(G18,1) -> 41000 | H19: 40170
A20: 24 | B20: =EDATE($L$2,-A20) -> 40544 | C20: =IF(B20<>B19,B20,EDATE(C19,1)) -> 41030 | D20: 2000 | E20: 0 | G20: =EDATE(G19,1) -> 41030 | H20: 40220
A21: 24 | B21: =EDATE($L$2,-A21) -> 40544 | C21: =IF(B21<>B20,B21,EDATE(C20,1)) -> 41061 | D21: 2000 | E21: 0 | G21: =EDATE(G20,1) -> 41061 | H21: 40420
A22: 23 | B22: =EDATE($L$2,-A22) -> 40575 | C22: =IF(B22<>B21,B22,EDATE(C21,1)) -> 40575 | D22: 1173000 | E22: 675000 | G22: =EDATE(G21,1) -> 41091 | H22: 40800
A23: 23 | B23: =EDATE($L$2,-A23) -> 40575 | C23: =IF(B23<>B22,B23,EDATE(C22,1)) -> 40603 | D23: 4406000 | E23: 13000 | G23: =EDATE(G22,1) -> 41122 | H23: 40690
A24: 23 | B24: =EDATE($L$2,-A24) -> 40575 | C24: =IF(B24<>B23,B24,EDATE(C23,1)) -> 40634 | D24: 1671000 | E24: 8000 | G24: =EDATE(G23,1) -> 41153 | H24: 40490
A25: 23 | B25: =EDATE($L$2,-A25) -> 40575 | C25: =IF(B25<>B24,B25,EDATE(C24,1)) -> 40664 | D25: 571000 | E25: 11000 | G25: =EDATE(G24,1) -> 41183 | H25: 40480
A26: 23 | B26: =EDATE($L$2,-A26) -> 40575 | C26: =IF(B26<>B25,B26,EDATE(C25,1)) -> 40695 | D26: 93000 | E26: 9000 | G26: =EDATE(G25,1) -> 41214 | H26: 40400
A27: 23 | B27: =EDATE($L$2,-A27) -> 40575 | C27: =IF(B27<>B26,B27,EDATE(C26,1)) -> 40725 | D27: 129000 | E27: 13000 | G27: =EDATE(G26,1) -> 41244 | H27: 40110
A28: 23 | B28: =EDATE($L$2,-A28) -> 40575 | C28: =IF(B28<>B27,B28,EDATE(C27,1)) -> 40756 | D28: 102000 | E28: 5000
A29: 23 | B29: =EDATE($L$2,-A29) -> 40575 | C29: =IF(B29<>B28,B29,EDATE(C28,1)) -> 40787 | D29: 23000 | E29: 4000
A30: 23 | B30: =EDATE($L$2,-A30) -> 40575 | C30: =IF(B30<>B29,B30,EDATE(C29,1)) -> 40817 | D30: 11000 | E30: 6000
A31: 23 | B31: =EDATE($L$2,-A31) -> 40575 | C31: =IF(B31<>B30,B31,EDATE(C30,1)) -> 40848 | D31: 24000 | E31: 0
A32: 23 | B32: =EDATE($L$2,-A32) -> 40575 | C32: =IF(B32<>B31,B32,EDATE(C31,1)) -> 40878 | D32: 29000 | E32: 1000
A33: 23 | B33: =EDATE($L$2,-A33) -> 40575 | C33: =IF(B33<>B32,B33,EDATE(C32,1)) -> 40909 | D33: 10000 | E33: 0
A34: 23 | B34: =EDATE($L$2,-A34) -> 40575 | C34: =IF(B34<>B33,B34,EDATE(C33,1)) -> 40940 | D34: 2000 | E34: 0
A35: 23 | B35: =EDATE($L$2,-A35) -> 40575 | C35: =IF(B35<>B34,B35,EDATE(C34,1)) -> 40969 | D35: 67000 | E35: 1000
A36: 23 | B36: =EDATE($L$2,-A36) -> 40575 | C36: =IF(B36<>B35,B36,EDATE(C35,1)) -> 41000 | D36: 19000 | E36: 0
A37: 23 | B37: =EDATE($L$2,-A37) -> 40575 | C37: =IF(B37<>B36,B37,EDATE(C36,1)) -> 41030 | D37: 2000 | E37: 0
A38: 23 | B38: =EDATE($L$2,-A38) -> 40575 | C38: =IF(B38<>B37,B38,EDATE(C37,1)) -> 41061 | D38: 7000 | E38: 0
A39: 23 | B39: =EDATE($L$2,-A39) -> 40575 | C39: =IF(B39<>B38,B39,EDATE(C38,1)) -> 41091 | D39: 12000 | E39: 0
... A282: 1 | B282: =EDATE($L$2,-A282) -> 41244 | C282: =IF(B282<>B281,B282,EDATE(C281,1)) -> 41244 | D282: 1938000 | E282: 1420125
A283: =(YEAR($L$2)-YEAR(B283))*12+MONTH($L$2)-MONTH(B283) -> 1356
