Workbook
Name AssetM: [1]Table!$J$3:$K$13
Name Benjamin: OFFSET('[2]Weight Watch'!$B$9,'[2]Weight Watch'!$I$3-9,2,'[2]Weight Watch'!$I$2,1)
Name Client: [1]X!$C$9
Name DateF: OFFSET('[2]Weight Watch'!$B$9,'[2]Weight Watch'!$I$3-9,0,'[2]Weight Watch'!$I$2,1)
Name DefaultB: [1]X!$F$5
Name Difference: OFFSET([3]Salman!$G$9,0,0,[3]Salman!$B$4,1)
Name Eric: OFFSET('[2]Weight Watch'!$B$9,'[2]Weight Watch'!$I$3-9,4,'[2]Weight Watch'!$I$2,1)
Name FanF: OFFSET('[2]Weight Watch'!$B$9,'[2]Weight Watch'!$I$3-9,3,'[2]Weight Watch'!$I$2,1)
Name Footer: [1]X!$C$10
Name George: OFFSET('[2]Weight Watch'!$B$9,'[2]Weight Watch'!$I$3-9,3,'[2]Weight Watch'!$I$2,1)
Name GradeTable: Records!$A$16:$X$27
Name LetterGrades: Records!$E$3:$E$12
Name LiF: OFFSET('[2]Weight Watch'!$B$9,'[2]Weight Watch'!$I$3-9,2,'[2]Weight Watch'!$I$2,1)
Name MeasDate: OFFSET('[2]Weight Watch'!$B$9,'[2]Weight Watch'!$I$3-9,0,'[2]Weight Watch'!$I$2,1)
Name MetMRV: [4]Table!$C$21:$D$31
Name Rate: OFFSET([5]Rate!$C$4,0,0,COUNT([5]Rate!$C:$C))
Name Version: [1]X!$A$2
Name WangF: OFFSET('[2]Weight Watch'!$B$9,'[2]Weight Watch'!$I$3-9,4,'[2]Weight Watch'!$I$2,1)
Name Year: OFFSET([5]Rate!$B$4,0,0,COUNT([5]Rate!$B:$B))
Name Year158: '[6]FAS 158 Input'!$H$4

Sheet Benefits
B3: Input Information
B4: Average Salary | H4: 60000
B5: Percentage for each year of service | H5: 0.03
B6: Early retirement reduction percentage | H6: 0.04
B7: Late Retirement Increase Percentage | H7: 0.05
B8: Normal Retirement Age
B9: Early retirement eligibility provisions
B10: Age requirement for early retirement
B11: Service requirement for early retirement
B12: =IF(ISBLANK(H8),65,H8) -> 65 | D12: =IF(ISBLANK(H10),55,H10) -> 55 | F12: =IF(ISBLANK(H11),10,H11) -> 10
B14: Retirement Benefit at Each Retirement Age
B15: ="Normal Retirement Age: "&B12 -> Normal Retirement Age: 65
B16: ="Early Retirement Requirements: Age " & D12 & " with " & F12 & " years of Service" -> Early Retirement Requirements: Age 55 with 10 years of Service
B17: Years of Service | C17: Retirement Age
C18: 70 | D18: 65 | E18: 62 | F18: 60 | G18: 55 | H18: 50
B19: 5 | C19: =IF(AND(OR($B19>=$F$12,C$18>=$B$12),NOT(C$18<$D$12)),$H$4*$H$5*$B19 * IF(C$18>=$B$12, (1+$H$7*(C$18-$B$12)),(1-$H$6*($B$12-C$18))),0) -> 11250 | D19: =IF(AND(OR($B19>=$F$12,D$18>=$B$12),NOT(D$18<$D$12)),$H$4*$H$5*$B19 * IF(D$18>=$B$12, (1+$H$7*(D$18-$B$12)),(1-$H$6*($B$12-D$18))),0) -> 9000 | E19: =IF(AND(OR($B19>=$F$12,E$18>=$B$12),NOT(E$18<$D$12)),$H$4*$H$5*$B19 * IF(E$18>=$B$12, (1+$H$7*(E$18-$B$12)),(1-$H$6*($B$12-E$18))),0) -> 0 | F19: =IF(AND(OR($B19>=$F$12,F$18>=$B$12),NOT(F$18<$D$12)),$H$4*$H$5*$B19 * IF(F$18>=$B$12, (1+$H$7*(F$18-$B$12)),(1-$H$6*($B$12-F$18))),0) -> 0 | G19: =IF(AND(OR($B19>=$F$12,G$18>=$B$12),NOT(G$18<$D$12)),$H$4*$H$5*$B19 * IF(G$18>=$B$12, (1+$H$7*(G$18-$B$12)),(1-$H$6*($B$12-G$18))),0) -> 0 | H19: =IF(AND(OR($B19>=$F$12,H$18>=$B$12),NOT(H$18<$D$12)),$H$4*$H$5*$B19 * IF(H$18>=$B$12, (1+$H$7*(H$18-$B$12)),(1-$H$6*($B$12-H$18))),0) -> 0
B20: 10 | C20: =IF(AND(OR($B20>=$F$12,C$18>=$B$12),NOT(C$18<$D$12)),$H$4*$H$5*$B20 * IF(C$18>=$B$12, (1+$H$7*(C$18-$B$12)),(1-$H$6*($B$12-C$18))),0) -> 22500 | D20: =IF(AND(OR($B20>=$F$12,D$18>=$B$12),NOT(D$18<$D$12)),$H$4*$H$5*$B20 * IF(D$18>=$B$12, (1+$H$7*(D$18-$B$12)),(1-$H$6*($B$12-D$18))),0) -> 18000 | E20: =IF(AND(OR($B20>=$F$12,E$18>=$B$12),NOT(E$18<$D$12)),$H$4*$H$5*$B20 * IF(E$18>=$B$12, (1+$H$7*(E$18-$B$12)),(1-$H$6*($B$12-E$18))),0) -> 15840 | F20: =IF(AND(OR($B20>=$F$12,F$18>=$B$12),NOT(F$18<$D$12)),$H$4*$H$5*$B20 * IF(F$18>=$B$12, (1+$H$7*(F$18-$B$12)),(1-$H$6*($B$12-F$18))),0) -> 14400 | G20: =IF(AND(OR($B20>=$F$12,G$18>=$B$12),NOT(G$18<$D$12)),$H$4*$H$5*$B20 * IF(G$18>=$B$12, (1+$H$7*(G$18-$B$12)),(1-$H$6*($B$12-G$18))),0) -> 10800 | H20: =IF(AND(OR($B20>=$F$12,H$18>=$B$12),NOT(H$18<$D$12)),$H$4*$H$5*$B20 * IF(H$18>=$B$12, (1+$H$7*(H$18-$B$12)),(1-$H$6*($B$12-H$18))),0) -> 0
B21: 15 | C21: =IF(AND(OR($B21>=$F$12,C$18>=$B$12),NOT(C$18<$D$12)),$H$4*$H$5*$B21 * IF(C$18>=$B$12, (1+$H$7*(C$18-$B$12)),(1-$H$6*($B$12-C$18))),0) -> 33750 | D21: =IF(AND(OR($B21>=$F$12,D$18>=$B$12),NOT(D$18<$D$12)),$H$4*$H$5*$B21 * IF(D$18>=$B$12, (1+$H$7*(D$18-$B$12)),(1-$H$6*($B$12-D$18))),0) -> 27000 | E21: =IF(AND(OR($B21>=$F$12,E$18>=$B$12),NOT(E$18<$D$12)),$H$4*$H$5*$B21 * IF(E$18>=$B$12, (1+$H$7*(E$18-$B$12)),(1-$H$6*($B$12-E$18))),0) -> 23760 | F21: =IF(AND(OR($B21>=$F$12,F$18>=$B$12),NOT(F$18<$D$12)),$H$4*$H$5*$B21 * IF(F$18>=$B$12, (1+$H$7*(F$18-$B$12)),(1-$H$6*($B$12-F$18))),0) -> 21600 | G21: =IF(AND(OR($B21>=$F$12,G$18>=$B$12),NOT(G$18<$D$12)),$H$4*$H$5*$B21 * IF(G$18>=$B$12, (1+$H$7*(G$18-$B$12)),(1-$H$6*($B$12-G$18))),0) -> 16200 | H21: =IF(AND(OR($B21>=$F$12,H$18>=$B$12),NOT(H$18<$D$12)),$H$4*$H$5*$B21 * IF(H$18>=$B$12, (1+$H$7*(H$18-$B$12)),(1-$H$6*($B$12-H$18))),0) -> 0
B22: 20 | C22: =IF(AND(OR($B22>=$F$12,C$18>=$B$12),NOT(C$18<$D$12)),$H$4*$H$5*$B22 * IF(C$18>=$B$12, (1+$H$7*(C$18-$B$12)),(1-$H$6*($B$12-C$18))),0) -> 45000 | D22: =IF(AND(OR($B22>=$F$12,D$18>=$B$12),NOT(D$18<$D$12)),$H$4*$H$5*$B22 * IF(D$18>=$B$12, (1+$H$7*(D$18-$B$12)),(1-$H$6*($B$12-D$18))),0) -> 36000 | E22: =IF(AND(OR($B22>=$F$12,E$18>=$B$12),NOT(E$18<$D$12)),$H$4*$H$5*$B22 * IF(E$18>=$B$12, (1+$H$7*(E$18-$B$12)),(1-$H$6*($B$12-E$18))),0) -> 31680 | F22: =IF(AND(OR($B22>=$F$12,F$18>=$B$12),NOT(F$18<$D$12)),$H$4*$H$5*$B22 * IF(F$18>=$B$12, (1+$H$7*(F$18-$B$12)),(1-$H$6*($B$12-F$18))),0) -> 28800 | G22: =IF(AND(OR($B22>=$F$12,G$18>=$B$12),NOT(G$18<$D$12)),$H$4*$H$5*$B22 * IF(G$18>=$B$12, (1+$H$7*(G$18-$B$12)),(1-$H$6*($B$12-G$18))),0) -> 21600 | H22: =IF(AND(OR($B22>=$F$12,H$18>=$B$12),NOT(H$18<$D$12)),$H$4*$H$5*$B22 * IF(H$18>=$B$12, (1+$H$7*(H$18-$B$12)),(1-$H$6*($B$12-H$18))),0) -> 0
B23: 25 | C23: =IF(AND(OR($B23>=$F$12,C$18>=$B$12),NOT(C$18<$D$12)),$H$4*$H$5*$B23 * IF(C$18>=$B$12, (1+$H$7*(C$18-$B$12)),(1-$H$6*($B$12-C$18))),0) -> 56250 | D23: =IF(AND(OR($B23>=$F$12,D$18>=$B$12),NOT(D$18<$D$12)),$H$4*$H$5*$B23 * IF(D$18>=$B$12, (1+$H$7*(D$18-$B$12)),(1-$H$6*($B$12-D$18))),0) -> 45000 | E23: =IF(AND(OR($B23>=$F$12,E$18>=$B$12),NOT(E$18<$D$12)),$H$4*$H$5*$B23 * IF(E$18>=$B$12, (1+$H$7*(E$18-$B$12)),(1-$H$6*($B$12-E$18))),0) -> 39600 | F23: =IF(AND(OR($B23>=$F$12,F$18>=$B$12),NOT(F$18<$D$12)),$H$4*$H$5*$B23 * IF(F$18>=$B$12, (1+$H$7*(F$18-$B$12)),(1-$H$6*($B$12-F$18))),0) -> 36000 | G23: =IF(AND(OR($B23>=$F$12,G$18>=$B$12),NOT(G$18<$D$12)),$H$4*$H$5*$B23 * IF(G$18>=$B$12, (1+$H$7*(G$18-$B$12)),(1-$H$6*($B$12-G$18))),0) -> 27000 | H23: =IF(AND(OR($B23>=$F$12,H$18>=$B$12),NOT(H$18<$D$12)),$H$4*$H$5*$B23 * IF(H$18>=$B$12, (1+$H$7*(H$18-$B$12)),(1-$H$6*($B$12-H$18))),0) -> 0
B24: 30 | C24: =IF(AND(OR($B24>=$F$12,C$18>=$B$12),NOT(C$18<$D$12)),$H$4*$H$5*$B24 * IF(C$18>=$B$12, (1+$H$7*(C$18-$B$12)),(1-$H$6*($B$12-C$18))),0) -> 67500 | D24: =IF(AND(OR($B24>=$F$12,D$18>=$B$12),NOT(D$18<$D$12)),$H$4*$H$5*$B24 * IF(D$18>=$B$12, (1+$H$7*(D$18-$B$12)),(1-$H$6*($B$12-D$18))),0) -> 54000 | E24: =IF(AND(OR($B24>=$F$12,E$18>=$B$12),NOT(E$18<$D$12)),$H$4*$H$5*$B24 * IF(E$18>=$B$12, (1+$H$7*(E$18-$B$12)),(1-$H$6*($B$12-E$18))),0) -> 47520 | F24: =IF(AND(OR($B24>=$F$12,F$18>=$B$12),NOT(F$18<$D$12)),$H$4*$H$5*$B24 * IF(F$18>=$B$12, (1+$H$7*(F$18-$B$12)),(1-$H$6*($B$12-F$18))),0) -> 43200 | G24: =IF(AND(OR($B24>=$F$12,G$18>=$B$12),NOT(G$18<$D$12)),$H$4*$H$5*$B24 * IF(G$18>=$B$12, (1+$H$7*(G$18-$B$12)),(1-$H$6*($B$12-G$18))),0) -> 32400 | H24: =IF(AND(OR($B24>=$F$12,H$18>=$B$12),NOT(H$18<$D$12)),$H$4*$H$5*$B24 * IF(H$18>=$B$12, (1+$H$7*(H$18-$B$12)),(1-$H$6*($B$12-H$18))),0) -> 0
B25: 35 | C25: =IF(AND(OR($B25>=$F$12,C$18>=$B$12),NOT(C$18<$D$12)),$H$4*$H$5*$B25 * IF(C$18>=$B$12, (1+$H$7*(C$18-$B$12)),(1-$H$6*($B$12-C$18))),0) -> 78750 | D25: =IF(AND(OR($B25>=$F$12,D$18>=$B$12),NOT(D$18<$D$12)),$H$4*$H$5*$B25 * IF(D$18>=$B$12, (1+$H$7*(D$18-$B$12)),(1-$H$6*($B$12-D$18))),0) -> 63000 | E25: =IF(AND(OR($B25>=$F$12,E$18>=$B$12),NOT(E$18<$D$12)),$H$4*$H$5*$B25 * IF(E$18>=$B$12, (1+$H$7*(E$18-$B$12)),(1-$H$6*($B$12-E$18))),0) -> 55440 | F25: =IF(AND(OR($B25>=$F$12,F$18>=$B$12),NOT(F$18<$D$12)),$H$4*$H$5*$B25 * IF(F$18>=$B$12, (1+$H$7*(F$18-$B$12)),(1-$H$6*($B$12-F$18))),0) -> 50400 | G25: =IF(AND(OR($B25>=$F$12,G$18>=$B$12),NOT(G$18<$D$12)),$H$4*$H$5*$B25 * IF(G$18>=$B$12, (1+$H$7*(G$18-$B$12)),(1-$H$6*($B$12-G$18))),0) -> 37800 | H25: =IF(AND(OR($B25>=$F$12,H$18>=$B$12),NOT(H$18<$D$12)),$H$4*$H$5*$B25 * IF(H$18>=$B$12, (1+$H$7*(H$18-$B$12)),(1-$H$6*($B$12-H$18))),0) -> 0

Sheet EeData
A1: Employee Database
A5: ID | B5: Company Code | C5: Current Salary | D5: Prior Salary | E5: Age | F5: Service | G5: Status Code | H5: Prior Status
A6: 375757 | B6: 2 | C6: 96000 | D6: 91428.571 | E6: 55 | F6: 7 | G6: A | H6: A
A7: 384691 | B7: 1 | C7: 89000 | D7: 84761.905 | E7: 52 | F7: 5 | G7: A | H7: A
A8: 396332 | B8: 3 | C8: 85000 | E8: 48 | F8: 1 | G8: A
A9: 401073 | B9: 1 | D9: 80000 | E9: 66 | G9: R | H9: R
A10: 409118 | B10: 1 | C10: 83000 | D10: 71000 | E10: 28 | F10: 11 | G10: A | H10: A
A11: 411380 | B11: 1 | C11: 86000 | D11: 74000 | E11: 57 | F11: 27 | G11: A | H11: A
A12: 412092 | B12: 1 | C12: 87000 | E12: 32 | F12: 2 | G12: A
A13: 413369 | B13: 1 | C13: 86000 | E13: 44 | F13: 14 | G13: A
A14: 415179 | B14: 1 | C14: 75000 | D14: 63000 | E14: 32 | F14: 2 | G14: A | H14: A
A15: 422576 | B15: 1 | C15: 86000 | D15: 80000 | E15: 55 | G15: R | H15: A
A16: 424060 | B16: 3 | C16: 250000 | D16: 230000 | E16: 51 | F16: 10 | G16: A | H16: A
A17: 431411 | B17: 3 | C17: 91000 | D17: 86666.667 | E17: 49 | F17: 6 | G17: A | H17: A
A18: 436028 | B18: 1 | C18: 86000 | D18: 74000 | E18: 23 | F18: 3 | G18: A | H18: A
A19: 437293 | B19: 3 | C19: 86000 | D19: 80000 | E19: 51 | G19: V | H19: A
A20: 438052 | B20: 1 | C20: 86000 | D20: 74000 | E20: 32 | F20: 9 | G20: A | H20: A
A21: 438638 | B21: 2 | C21: 87000 | D21: 82857.143 | E21: 47 | F21: 12 | G21: A | H21: A
A22: 449418 | B22: 1 | C22: 76000 | D22: 64000 | E22: 45 | F22: 15 | G22: A | H22: A
A23: 449944 | B23: 1 | C23: 86000 | D23: 80000 | E23: 45 | G23: V | H23: A
A24: 452656 | B24: 2 | C24: 93000 | D24: 88571.429 | E24: 46 | F24: 18 | G24: A | H24: A
A25: 463271 | B25: 1 | C25: 54000 | D25: 42000 | E25: 32 | F25: 8 | G25: A | H25: A
A26: 463938 | B26: 1 | C26: 96000 | D26: 84000 | E26: 32 | F26: 2 | G26: A | H26: A
A27: 479102 | B27: 3 | C27: 85000 | E27: 48 | F27: 1 | G27: A
A28: 481800 | B28: 2 | D28: 80000 | E28: 64 | G28: R | H28: R
A29: 482078 | B29: 1 | C29: 110000 | D29: 98000 | E29: 32 | F29: 8 | G29: A | H29: A
A30: 486583 | B30: 1 | C30: 86000 | D30: 80000 | E30: 32 | G30: T | H30: A
A31: 492053 | B31: 1 | C31: 86000 | D31: 74000 | E31: 32 | F31: 2 | G31: A | H31: A
A32: 492133 | B32: 1 | C32: 100000 | D32: 88000 | E32: 32 | F32: 10 | G32: A | H32: A
A33: 492176 | B33: 1 | C33: 86000 | D33: 80000 | E33: 34 | G33: T | H33: A
A34: 496907 | B34: 2 | D34: 80000 | E34: 59 | G34: R | H34: V
A35: 507242 | B35: 1 | C35: 92000 | D35: 40000 | E35: 44 | F35: 7 | G35: A | H35: A
A36: 513820 | B36: 1 | D36: 80000 | E36: 62 | G36: R | H36: V
A37: 514774 | B37: 3 | D37: 80000 | E37: 44 | G37: V | H37: V
A38: 520201 | B38: 2 | D38: 80000 | E38: 36 | G38: V | H38: V
A39: 520938 | B39: 1 | C39: 23000 | D39: 11000 | E39: 36 | F39: 10 | G39: A | H39: A
A40: 521501 | B40: 1 | C40: 79000 | D40: 67000 | E40: 26 | F40: 8 | G40: A | H40: A
A41: 526149 | B41: 3 | C41: 97000 | D41: 92380.952 | E41: 55 | F41: 9 | G41: A | H41: A
A42: 539134 | B42: 1 | C42: 94000 | D42: 82000 | E42: 32 | F42: 10 | G42: A | H42: A
A43: 540346 | B43: 1 | C43: 95000 | D43: 90476.19 | E43: 49 | F43: 10 | G43: A | H43: A
...

Sheet Age Distributions
B2: Highlighted cells are for ages and are the only input cells
B4: Age Breakpoint | F4: Distribution by Age with Total and Average Salary
B5: Age is | F5: (Actives Only)
B6: at least | C6: but | D6: less than | F6: Age | H6: Count | J6: Total Salary | L6: Average Salary
B7: 0 | D7: 20 | F7: =IF(B7="","",IF(B7=0,"<"&D7,IF(D7="",B7&" <=",B7&" - "&D7))) -> <20 | H7: =IF(B7="","",COUNTIFS(EeData!$G:$G,"A",EeData!$E:$E,">="&$B7,EeData!$E:$E,"<"& IF($D7="",200, $D7))) -> 0 | J7: =IF(B7="","",SUMIFS(EeData!$C:$C,EeData!$G:$G,"A",EeData!$E:$E,">="&$B7,EeData!$E:$E,"<"&IF($D7="",200,$D7))) -> 0 | L7: =IF(B7="","",IF($H7=0,0,$J7/$H7)) -> 0
B8: =IF(D7="","",D7) -> 20 | D8: =D7 + 10 -> 30 | F8: =IF(B8="","",IF(B8=0,"<"&D8,IF(D8="",B8&" <=",B8&" - "&D8))) -> 20 - 30 | H8: =IF(B8="","",COUNTIFS(EeData!$G:$G,"A",EeData!$E:$E,">="&$B8,EeData!$E:$E,"<"& IF($D8="",200, $D8))) -> 3 | J8: =IF(B8="","",SUMIFS(EeData!$C:$C,EeData!$G:$G,"A",EeData!$E:$E,">="&$B8,EeData!$E:$E,"<"&IF($D8="",200,$D8))) -> 248000 | L8: =IF(B8="","",IF($H8=0,0,$J8/$H8)) -> 82666.667
B9: =IF(D8="","",D8) -> 30 | D9: =D8 + 10 -> 40 | F9: =IF(B9="","",IF(B9=0,"<"&D9,IF(D9="",B9&" <=",B9&" - "&D9))) -> 30 - 40 | H9: =IF(B9="","",COUNTIFS(EeData!$G:$G,"A",EeData!$E:$E,">="&$B9,EeData!$E:$E,"<"& IF($D9="",200, $D9))) -> 11 | J9: =IF(B9="","",SUMIFS(EeData!$C:$C,EeData!$G:$G,"A",EeData!$E:$E,">="&$B9,EeData!$E:$E,"<"&IF($D9="",200,$D9))) -> 1011000 | L9: =IF(B9="","",IF($H9=0,0,$J9/$H9)) -> 91909.091
B10: =IF(D9="","",D9) -> 40 | D10: =D9 + 10 -> 50 | F10: =IF(B10="","",IF(B10=0,"<"&D10,IF(D10="",B10&" <=",B10&" - "&D10))) -> 40 - 50 | H10: =IF(B10="","",COUNTIFS(EeData!$G:$G,"A",EeData!$E:$E,">="&$B10,EeData!$E:$E,"<"& IF($D10="",200, $D10))) -> 13 | J10: =IF(B10="","",SUMIFS(EeData!$C:$C,EeData!$G:$G,"A",EeData!$E:$E,">="&$B10,EeData!$E:$E,"<"&IF($D10="",200,$D10))) -> 1150000 | L10: =IF(B10="","",IF($H10=0,0,$J10/$H10)) -> 88461.538
B11: =IF(D10="","",D10) -> 50 | D11: =D10 + 10 -> 60 | F11: =IF(B11="","",IF(B11=0,"<"&D11,IF(D11="",B11&" <=",B11&" - "&D11))) -> 50 - 60 | H11: =IF(B11="","",COUNTIFS(EeData!$G:$G,"A",EeData!$E:$E,">="&$B11,EeData!$E:$E,"<"& IF($D11="",200, $D11))) -> 9 | J11: =IF(B11="","",SUMIFS(EeData!$C:$C,EeData!$G:$G,"A",EeData!$E:$E,">="&$B11,EeData!$E:$E,"<"&IF($D11="",200,$D11))) -> 1209000 | L11: =IF(B11="","",IF($H11=0,0,$J11/$H11)) -> 134333.33
B12: =IF(D11="","",D11) -> 60 | F12: =IF(B12="","",IF(B12=0,"<"&D12,IF(D12="",B12&" <=",B12&" - "&D12))) -> 60 <= | H12: =IF(B12="","",COUNTIFS(EeData!$G:$G,"A",EeData!$E:$E,">="&$B12,EeData!$E:$E,"<"& IF($D12="",200, $D12))) -> 1 | J12: =IF(B12="","",SUMIFS(EeData!$C:$C,EeData!$G:$G,"A",EeData!$E:$E,">="&$B12,EeData!$E:$E,"<"&IF($D12="",200,$D12))) -> 86000 | L12: =IF(B12="","",IF($H12=0,0,$J12/$H12)) -> 86000
B13: =IF(D12="","",D12) | F13: =IF(B13="","",IF(B13=0,"<"&D13,IF(D13="",B13&" <=",B13&" - "&D13))) | H13: =IF(B13="","",COUNTIFS(EeData!$G:$G,"A",EeData!$E:$E,">="&$B13,EeData!$E:$E,"<"& IF($D13="",200, $D13))) | J13: =IF(B13="","",SUMIFS(EeData!$C:$C,EeData!$G:$G,"A",EeData!$E:$E,">="&$B13,EeData!$E:$E,"<"&IF($D13="",200,$D13))) | L13: =IF(B13="","",IF($H13=0,0,$J13/$H13))
B14: =IF(D13="","",D13) | F14: =IF(B14="","",IF(B14=0,"<"&D14,IF(D14="",B14&" <=",B14&" - "&D14))) | H14: =IF(B14="","",COUNTIFS(EeData!$G:$G,"A",EeData!$E:$E,">="&$B14,EeData!$E:$E,"<"& IF($D14="",200, $D14))) | J14: =IF(B14="","",SUMIFS(EeData!$C:$C,EeData!$G:$G,"A",EeData!$E:$E,">="&$B14,EeData!$E:$E,"<"&IF($D14="",200,$D14))) | L14: =IF(B14="","",IF($H14=0,0,$J14/$H14))
B15: =IF(D14="","",D14) | F15: =IF(B15="","",IF(B15=0,"<"&D15,IF(D15="",B15&" <=",B15&" - "&D15))) | H15: =IF(B15="","",COUNTIFS(EeData!$G:$G,"A",EeData!$E:$E,">="&$B15,EeData!$E:$E,"<"& IF($D15="",200, $D15))) | J15: =IF(B15="","",SUMIFS(EeData!$C:$C,EeData!$G:$G,"A",EeData!$E:$E,">="&$B15,EeData!$E:$E,"<"&IF($D15="",200,$D15))) | L15: =IF(B15="","",IF($H15=0,0,$J15/$H15))
B16: =IF(D15="","",D15) | F16: =IF(B16="","",IF(B16=0,"<"&D16,IF(D16="",B16&" <=",B16&" - "&D16))) | H16: =IF(B16="","",COUNTIFS(EeData!$G:$G,"A",EeData!$E:$E,">="&$B16,EeData!$E:$E,"<"& IF($D16="",200, $D16))) | J16: =IF(B16="","",SUMIFS(EeData!$C:$C,EeData!$G:$G,"A",EeData!$E:$E,">="&$B16,EeData!$E:$E,"<"&IF($D16="",200,$D16))) | L16: =IF(B16="","",IF($H16=0,0,$J16/$H16))
B17: =IF(D16="","",D16) | F17: =IF(B17="","",IF(B17=0,"<"&D17,IF(D17="",B17&" <=",B17&" - "&D17))) | H17: =IF(B17="","",COUNTIFS(EeData!$G:$G,"A",EeData!$E:$E,">="&$B17,EeData!$E:$E,"<"& IF($D17="",200, $D17))) | J17: =IF(B17="","",SUMIFS(EeData!$C:$C,EeData!$G:$G,"A",EeData!$E:$E,">="&$B17,EeData!$E:$E,"<"&IF($D17="",200,$D17))) | L17: =IF(B17="","",IF($H17=0,0,$J17/$H17))
B18: =IF(D17="","",D17) | F18: =IF(B18="","",IF(B18=0,"<"&D18,IF(D18="",B18&" <=",B18&" - "&D18))) | H18: =IF(B18="","",COUNTIFS(EeData!$G:$G,"A",EeData!$E:$E,">="&$B18,EeData!$E:$E,"<"& IF($D18="",200, $D18))) | J18: =IF(B18="","",SUMIFS(EeData!$C:$C,EeData!$G:$G,"A",EeData!$E:$E,">="&$B18,EeData!$E:$E,"<"&IF($D18="",200,$D18))) | L18: =IF(B18="","",IF($H18=0,0,$J18/$H18))
B19: =IF(D18="","",D18) | F19: =IF(B19="","",IF(B19=0,"<"&D19,IF(D19="",B19&" <=",B19&" - "&D19))) | H19: =IF(B19="","",COUNTIFS(EeData!$G:$G,"A",EeData!$E:$E,">="&$B19,EeData!$E:$E,"<"& IF($D19="",200, $D19))) | J19: =IF(B19="","",SUMIFS(EeData!$C:$C,EeData!$G:$G,"A",EeData!$E:$E,">="&$B19,EeData!$E:$E,"<"&IF($D19="",200,$D19))) | L19: =IF(B19="","",IF($H19=0,0,$J19/$H19))
B20: =IF(D19="","",D19) | F20: =IF(B20="","",IF(B20=0,"<"&D20,IF(D20="",B20&" <=",B20&" - "&D20))) | H20: =IF(B20="","",COUNTIFS(EeData!$G:$G,"A",EeData!$E:$E,">="&$B20,EeData!$E:$E,"<"& IF($D20="",200, $D20))) | J20: =IF(B20="","",SUMIFS(EeData!$C:$C,EeData!$G:$G,"A",EeData!$E:$E,">="&$B20,EeData!$E:$E,"<"&IF($D20="",200,$D20))) | L20: =IF(B20="","",IF($H20=0,0,$J20/$H20))
B21: =IF(D20="","",D20) | F21: =IF(B21="","",IF(B21=0,"<"&D21,IF(D21="",B21&" <=",B21&" - "&D21))) | H21: =IF(B21="","",COUNTIFS(EeData!$G:$G,"A",EeData!$E:$E,">="&$B21,EeData!$E:$E,"<"& IF($D21="",200, $D21))) | J21: =IF(B21="","",SUMIFS(EeData!$C:$C,EeData!$G:$G,"A",EeData!$E:$E,">="&$B21,EeData!$E:$E,"<"&IF($D21="",200,$D21))) | L21: =IF(B21="","",IF($H21=0,0,$J21/$H21))
B22: =IF(D21="","",D21) | F22: =IF(B22="","",IF(B22=0,"<"&D22,IF(D22="",B22&" <=",B22&" - "&D22))) | H22: =IF(B22="","",COUNTIFS(EeData!$G:$G,"A",EeData!$E:$E,">="&$B22,EeData!$E:$E,"<"& IF($D22="",200, $D22))) | J22: =IF(B22="","",SUMIFS(EeData!$C:$C,EeData!$G:$G,"A",EeData!$E:$E,">="&$B22,EeData!$E:$E,"<"&IF($D22="",200,$D22))) | L22: =IF(B22="","",IF($H22=0,0,$J22/$H22))
B23: =IF(D22="","",D22) | F23: =IF(B23="","",IF(B23=0,"<"&D23,IF(D23="",B23&" <=",B23&" - "&D23))) | H23: =IF(B23="","",COUNTIFS(EeData!$G:$G,"A",EeData!$E:$E,">="&$B23,EeData!$E:$E,"<"& IF($D23="",200, $D23))) | J23: =IF(B23="","",SUMIFS(EeData!$C:$C,EeData!$G:$G,"A",EeData!$E:$E,">="&$B23,EeData!$E:$E,"<"&IF($D23="",200,$D23))) | L23: =IF(B23="","",IF($H23=0,0,$J23/$H23))
... B34: =IF(D33="","",D33) | F34: =IF(B34="","",IF(B34=0,"<"&D34,IF(D34="",B34&" <=",B34&" - "&D34))) | H34: =IF(B34="","",COUNTIFS(EeData!$G:$G,"A",EeData!$E:$E,">="&$B34,EeData!$E:$E,"<"& IF($D34="",200, $D34))) | J34: =IF(B34="","",SUMIFS(EeData!$C:$C,EeData!$G:$G,"A",EeData!$E:$E,">="&$B34,EeData!$E:$E,"<"&IF($D34="",200,$D34))) | L34: =IF(B34="","",IF($H34=0,0,$J34/$H34))
F35: Total | H35: =SUM(H7:H34) -> 37 | J35: =SUM(J7:J34) -> 3704000 | L35: =$J$35/$H$35 -> 100108.11

Sheet Records
A1: Grading Policy
B2: Grade | C2: Percentage
B3: A | C3: 0.95 | D3: to | E3: 1
B4: A- | C4: 0.92 | D4: to | E4: 0.9499
B5: B+ | C5: 0.9 | D5: to | E5: 0.9199
B6: B | C6: 0.85 | D6: to | E6: 0.8999
B7: B- | C7: 0.82 | D7: to | E7: 0.8499
B8: C+ | C8: 0.8 | D8: to | E8: 0.8199
B9: C | C9: 0.77 | D9: to | E9: 0.7999
B10: C- | C10: 0.75 | D10: to | E10: 0.7699
B11: D | C11: 0.65 | D11: to | E11: 0.7499
B12: F | C12: 0 | D12: to | E12: 0.6499
C14: Total | G14: Quizzes | M14: Homework
A15: Name | C15: Points | D15: Final | E15: Mid-Term | G15: 1 | H15: 2 | I15: 3 | J15: 4 | K15: 5 | L15: Total | M15: 1 | N15: 2 | O15: 3 | P15: 4 | Q15: 5 | R15: 6 | S15: 7 | T15: 8 | U15: 9 | V15: 10 | W15: 11 | X15: Total
A16: Klendshoj,Roxanne L | C16: 488 | D16: 195 | E16: 98 | G16: 24 | H16: 23 | I16: 18 | J16: 23 | K16: 21 | L16: 109 | M16: 10 | N16: 9 | O16: 7 | P16: 8 | Q16: 6 | R16: 8 | S16: 7 | T16: 6 | U16: 8 | V16: 10 | W16: 7 | X16: 86
A17: Doll Woolley,Jeanne M | C17: 439 | D17: 190 | E17: 96 | G17: 23 | H17: 22 | I17: 17 | J17: 22 | K17: 20 | L17: 104 | M17: 9 | N17: 8 | O17: 0 | P17: 7 | Q17: 0 | R17: 2 | S17: 5 | T17: 4 | U17: 6 | V17: 8 | X17: 49
A18: Bartho,Jerome F | C18: 458 | D18: 185 | E18: 94 | G18: 22 | H18: 25 | I18: 25 | J18: 25 | K18: 25 | L18: 122 | M18: 8 | N18: 7 | O18: 9 | P18: 7 | Q18: 10 | R18: 7 | S18: 3 | T18: 2 | U18: 4 | X18: 57
A19: Benson,Scott G | C19: 430 | D19: 180 | E19: 92 | G19: 21 | H19: 20 | I19: 25 | J19: 20 | K19: 22 | L19: 108 | M19: 7 | N19: 6 | O19: 8 | P19: 10 | Q19: 7 | R19: 9 | S19: 2 | T19: 1 | X19: 50
A20: Aho,Diane M | C20: 458 | D20: 198 | E20: 90 | G20: 25 | H20: 25 | I20: 25 | J20: 25 | K20: 21 | L20: 121 | M20: 6 | N20: 5 | O20: 7 | P20: 9 | Q20: 6 | R20: 8 | S20: 8 | X20: 49
A21: Larson,DeeAnn S | C21: 391 | D21: 170 | E21: 88 | G21: 19 | H21: 18 | I21: 23 | J21: 18 | K21: 20 | L21: 98 | M21: 5 | N21: 4 | O21: 6 | P21: 8 | Q21: 5 | R21: 7 | X21: 35
A22: Nelson,Susann K | C22: 420 | D22: 200 | E22: 86 | G22: 18 | H22: 17 | I22: 22 | J22: 17 | K22: 19 | L22: 93 | M22: 10 | N22: 6 | O22: 8 | P22: 10 | Q22: 7 | X22: 41
A23: Asche,Tracy A | C23: 319 | D23: 160 | E23: 84 | G23: 17 | H23: 16 | I23: 25 | K23: 2 | L23: 60 | M23: 3 | N23: 2 | O23: 4 | P23: 6 | X23: 15
A24: Carlson,Robert L | C24: 416 | D24: 200 | E24: 100 | G24: 16 | H24: 15 | I24: 20 | J24: 25 | K24: 23 | L24: 99 | M24: 10 | N24: 2 | O24: 5 | X24: 17
A25: Donovan,Richard G | C25: 305 | D25: 180 | E25: 90 | G25: 15 | L25: 15 | M25: 10 | N25: 10 | X25: 20
A26: Shapiro,Susan R | C26: 234 | D26: 145 | E26: 78 | K26: 2 | L26: 2 | M26: 9 | X26: 9
A27: Johnson,Bruce D | C27: 447 | D27: 200 | E27: 100 | G27: 13 | H27: 12 | I27: 17 | J27: 22 | K27: 20 | L27: 84 | M27: 5 | N27: 4 | O27: 6 | P27: 8 | Q27: 5 | R27: 7 | S27: 5 | T27: 4 | U27: 6 | V27: 8 | W27: 5 | X27: 63

Sheet Grade_Report
B2: Student Grade Report
B4: Student Name | D4: Doll Woolley,Jeanne M
B6: Total Point Available | D6: 500
B7: Total Earned Points | D7: =SUM(D11:D14) -> 439
B8: Achieved Percentage | D8: =D7/D6 -> 0.878
B9: Letter Grade | D9: =INDEX(Records!B3:B12,MATCH(D8,LetterGrades,-1)) -> B
B11: Final | D11: =VLOOKUP($D$4,GradeTable,4,FALSE) -> 190
B12: Midterm | D12: =VLOOKUP($D$4,GradeTable,5,FALSE) -> 96
B13: Quiz | D13: =VLOOKUP($D$4,GradeTable,12,FALSE) -> 104
B14: Homework | D14: =VLOOKUP($D$4,GradeTable,24,FALSE) -> 49
