Workbook
Name AssetM: [1]Table!$J$3:$K$13
Name Benjamin: OFFSET('[2]Weight Watch'!$B$9,'[2]Weight Watch'!$I$3-9,2,'[2]Weight Watch'!$I$2,1)
Name Client: [1]X!$C$9
Name DateF: OFFSET('[2]Weight Watch'!$B$9,'[2]Weight Watch'!$I$3-9,0,'[2]Weight Watch'!$I$2,1)
Name DefaultB: [1]X!$F$5
Name Difference: OFFSET([3]Salman!$G$9,0,0,[3]Salman!$B$4,1)
Name Eric: OFFSET('[2]Weight Watch'!$B$9,'[2]Weight Watch'!$I$3-9,4,'[2]Weight Watch'!$I$2,1)
Name FanF: OFFSET('[2]Weight Watch'!$B$9,'[2]Weight Watch'!$I$3-9,3,'[2]Weight Watch'!$I$2,1)
Name Footer: [1]X!$C$10
Name George: OFFSET('[2]Weight Watch'!$B$9,'[2]Weight Watch'!$I$3-9,3,'[2]Weight Watch'!$I$2,1)
Name LiF: OFFSET('[2]Weight Watch'!$B$9,'[2]Weight Watch'!$I$3-9,2,'[2]Weight Watch'!$I$2,1)
Name MeasDate: OFFSET('[2]Weight Watch'!$B$9,'[2]Weight Watch'!$I$3-9,0,'[2]Weight Watch'!$I$2,1)
Name MetMRV: [4]Table!$C$21:$D$31
Name Rate: OFFSET([5]Rate!$C$4,0,0,COUNT([5]Rate!$C:$C))
Name Version: [1]X!$A$2
Name WangF: OFFSET('[2]Weight Watch'!$B$9,'[2]Weight Watch'!$I$3-9,4,'[2]Weight Watch'!$I$2,1)
Name Year: OFFSET([5]Rate!$B$4,0,0,COUNT([5]Rate!$B:$B))
Name Year158: '[6]FAS 158 Input'!$H$4

Sheet Service Distributions
B2: Highlighted cells are for ages and are the only input cells
B4: Service Breakpoint | F4: Distribution by Service
B5: Service is | F5: Actives Only
B6: at least | C6: but | D6: less than | F6: Age | H6: Count
B7: 0 | D7: 5 | F7: =IF(B7="","",IF(B7=0,"<"&D7,IF(D7="",B7&" <=",B7&" - "&D7))) -> <5 | H7: =IF(B7="","",COUNTIFS(EeData!$G:$G,"A",EeData!$F:$F,">="&$B7,EeData!$F:$F,"<"& IF($D7="",200, $D7))) -> 7
B8: =IF(D7="","",D7) -> 5 | D8: =D7 + 5 -> 10 | F8: =IF(B8="","",IF(B8=0,"<"&D8,IF(D8="",B8&" <=",B8&" - "&D8))) -> 5 - 10 | H8: =IF(B8="","",COUNTIFS(EeData!$G:$G,"A",EeData!$F:$F,">="&$B8,EeData!$F:$F,"<"& IF($D8="",200, $D8))) -> 11
B9: =IF(D8="","",D8) -> 10 | D9: =D8 + 5 -> 15 | F9: =IF(B9="","",IF(B9=0,"<"&D9,IF(D9="",B9&" <=",B9&" - "&D9))) -> 10 - 15 | H9: =IF(B9="","",COUNTIFS(EeData!$G:$G,"A",EeData!$F:$F,">="&$B9,EeData!$F:$F,"<"& IF($D9="",200, $D9))) -> 11
B10: =IF(D9="","",D9) -> 15 | D10: =D9 + 5 -> 20 | F10: =IF(B10="","",IF(B10=0,"<"&D10,IF(D10="",B10&" <=",B10&" - "&D10))) -> 15 - 20 | H10: =IF(B10="","",COUNTIFS(EeData!$G:$G,"A",EeData!$F:$F,">="&$B10,EeData!$F:$F,"<"& IF($D10="",200, $D10))) -> 3
B11: =IF(D10="","",D10) -> 20 | D11: =D10 + 5 -> 25 | F11: =IF(B11="","",IF(B11=0,"<"&D11,IF(D11="",B11&" <=",B11&" - "&D11))) -> 20 - 25 | H11: =IF(B11="","",COUNTIFS(EeData!$G:$G,"A",EeData!$F:$F,">="&$B11,EeData!$F:$F,"<"& IF($D11="",200, $D11))) -> 3
B12: =IF(D11="","",D11) -> 25 | F12: =IF(B12="","",IF(B12=0,"<"&D12,IF(D12="",B12&" <=",B12&" - "&D12))) -> 25 <= | H12: =IF(B12="","",COUNTIFS(EeData!$G:$G,"A",EeData!$F:$F,">="&$B12,EeData!$F:$F,"<"& IF($D12="",200, $D12))) -> 2
B13: =IF(D12="","",D12) | F13: =IF(B13="","",IF(B13=0,"<"&D13,IF(D13="",B13&" <=",B13&" - "&D13))) | H13: =IF(B13="","",COUNTIFS(EeData!$G:$G,"A",EeData!$F:$F,">="&$B13,EeData!$F:$F,"<"& IF($D13="",200, $D13)))
B14: =IF(D13="","",D13) | F14: =IF(B14="","",IF(B14=0,"<"&D14,IF(D14="",B14&" <=",B14&" - "&D14))) | H14: =IF(B14="","",COUNTIFS(EeData!$G:$G,"A",EeData!$F:$F,">="&$B14,EeData!$F:$F,"<"& IF($D14="",200, $D14)))
B15: =IF(D14="","",D14) | F15: =IF(B15="","",IF(B15=0,"<"&D15,IF(D15="",B15&" <=",B15&" - "&D15))) | H15: =IF(B15="","",COUNTIFS(EeData!$G:$G,"A",EeData!$F:$F,">="&$B15,EeData!$F:$F,"<"& IF($D15="",200, $D15)))
B16: =IF(D15="","",D15) | F16: =IF(B16="","",IF(B16=0,"<"&D16,IF(D16="",B16&" <=",B16&" - "&D16))) | H16: =IF(B16="","",COUNTIFS(EeData!$G:$G,"A",EeData!$F:$F,">="&$B16,EeData!$F:$F,"<"& IF($D16="",200, $D16)))
B17: =IF(D16="","",D16) | F17: =IF(B17="","",IF(B17=0,"<"&D17,IF(D17="",B17&" <=",B17&" - "&D17))) | H17: =IF(B17="","",COUNTIFS(EeData!$G:$G,"A",EeData!$F:$F,">="&$B17,EeData!$F:$F,"<"& IF($D17="",200, $D17)))
B18: =IF(D17="","",D17) | F18: =IF(B18="","",IF(B18=0,"<"&D18,IF(D18="",B18&" <=",B18&" - "&D18))) | H18: =IF(B18="","",COUNTIFS(EeData!$G:$G,"A",EeData!$F:$F,">="&$B18,EeData!$F:$F,"<"& IF($D18="",200, $D18)))
B19: =IF(D18="","",D18) | F19: =IF(B19="","",IF(B19=0,"<"&D19,IF(D19="",B19&" <=",B19&" - "&D19))) | H19: =IF(B19="","",COUNTIFS(EeData!$G:$G,"A",EeData!$F:$F,">="&$B19,EeData!$F:$F,"<"& IF($D19="",200, $D19)))
B20: =IF(D19="","",D19) | F20: =IF(B20="","",IF(B20=0,"<"&D20,IF(D20="",B20&" <=",B20&" - "&D20))) | H20: =IF(B20="","",COUNTIFS(EeData!$G:$G,"A",EeData!$F:$F,">="&$B20,EeData!$F:$F,"<"& IF($D20="",200, $D20)))
B21: =IF(D20="","",D20) | F21: =IF(B21="","",IF(B21=0,"<"&D21,IF(D21="",B21&" <=",B21&" - "&D21))) | H21: =IF(B21="","",COUNTIFS(EeData!$G:$G,"A",EeData!$F:$F,">="&$B21,EeData!$F:$F,"<"& IF($D21="",200, $D21)))
B22: =IF(D21="","",D21) | F22: =IF(B22="","",IF(B22=0,"<"&D22,IF(D22="",B22&" <=",B22&" - "&D22))) | H22: =IF(B22="","",COUNTIFS(EeData!$G:$G,"A",EeData!$F:$F,">="&$B22,EeData!$F:$F,"<"& IF($D22="",200, $D22)))
B23: =IF(D22="","",D22) | F23: =IF(B23="","",IF(B23=0,"<"&D23,IF(D23="",B23&" <=",B23&" - "&D23))) | H23: =IF(B23="","",COUNTIFS(EeData!$G:$G,"A",EeData!$F:$F,">="&$B23,EeData!$F:$F,"<"& IF($D23="",200, $D23)))
... B34: =IF(D33="","",D33) | F34: =IF(B34="","",IF(B34=0,"<"&D34,IF(D34="",B34&" <=",B34&" - "&D34))) | H34: =IF(B34="","",COUNTIFS(EeData!$G:$G,"A",EeData!$F:$F,">="&$B34,EeData!$F:$F,"<"& IF($D34="",200, $D34)))

Sheet EeData
A1: Employee Database
A5: ID | B5: Company Code | C5: Current Salary | D5: Prior Salary | E5: Age | F5: Service | G5: Status Code | H5: Prior Status
A6: 375757 | B6: 2 | C6: 96000 | D6: 91428.571 | E6: 55 | F6: 7 | G6: A | H6: A
A7: 384691 | B7: 1 | C7: 89000 | D7: 84761.905 | E7: 52 | F7: 5 | G7: A | H7: A
A8: 396332 | B8: 3 | C8: 85000 | E8: 48 | F8: 1 | G8: A
A9: 401073 | B9: 1 | D9: 80000 | E9: 66 | G9: R | H9: R
A10: 409118 | B10: 1 | C10: 83000 | D10: 71000 | E10: 28 | F10: 11 | G10: A | H10: A
A11: 411380 | B11: 1 | C11: 86000 | D11: 74000 | E11: 57 | F11: 27 | G11: A | H11: A
A12: 412092 | B12: 1 | C12: 87000 | E12: 32 | F12: 2 | G12: A
A13: 413369 | B13: 1 | C13: 86000 | E13: 44 | F13: 14 | G13: A
A14: 415179 | B14: 1 | C14: 75000 | D14: 63000 | E14: 32 | F14: 2 | G14: A | H14: A
A15: 422576 | B15: 1 | C15: 86000 | D15: 80000 | E15: 55 | G15: R | H15: A
A16: 424060 | B16: 3 | C16: 250000 | D16: 230000 | E16: 51 | F16: 10 | G16: A | H16: A
A17: 431411 | B17: 3 | C17: 91000 | D17: 86666.667 | E17: 49 | F17: 6 | G17: A | H17: A
A18: 436028 | B18: 1 | C18: 86000 | D18: 74000 | E18: 23 | F18: 3 | G18: A | H18: A
A19: 437293 | B19: 3 | C19: 86000 | D19: 80000 | E19: 51 | G19: V | H19: A
A20: 438052 | B20: 1 | C20: 86000 | D20: 74000 | E20: 32 | F20: 9 | G20: A | H20: A
A21: 438638 | B21: 2 | C21: 87000 | D21: 82857.143 | E21: 47 | F21: 12 | G21: A | H21: A
A22: 449418 | B22: 1 | C22: 76000 | D22: 64000 | E22: 45 | F22: 15 | G22: A | H22: A
A23: 449944 | B23: 1 | C23: 86000 | D23: 80000 | E23: 45 | G23: V | H23: A
A24: 452656 | B24: 2 | C24: 93000 | D24: 88571.429 | E24: 46 | F24: 18 | G24: A | H24: A
A25: 463271 | B25: 1 | C25: 54000 | D25: 42000 | E25: 32 | F25: 8 | G25: A | H25: A
A26: 463938 | B26: 1 | C26: 96000 | D26: 84000 | E26: 32 | F26: 2 | G26: A | H26: A
A27: 479102 | B27: 3 | C27: 85000 | E27: 48 | F27: 1 | G27: A
A28: 481800 | B28: 2 | D28: 80000 | E28: 64 | G28: R | H28: R
A29: 482078 | B29: 1 | C29: 110000 | D29: 98000 | E29: 32 | F29: 8 | G29: A | H29: A
A30: 486583 | B30: 1 | C30: 86000 | D30: 80000 | E30: 32 | G30: T | H30: A
A31: 492053 | B31: 1 | C31: 86000 | D31: 74000 | E31: 32 | F31: 2 | G31: A | H31: A
A32: 492133 | B32: 1 | C32: 100000 | D32: 88000 | E32: 32 | F32: 10 | G32: A | H32: A
A33: 492176 | B33: 1 | C33: 86000 | D33: 80000 | E33: 34 | G33: T | H33: A
A34: 496907 | B34: 2 | D34: 80000 | E34: 59 | G34: R | H34: V
A35: 507242 | B35: 1 | C35: 92000 | D35: 40000 | E35: 44 | F35: 7 | G35: A | H35: A
A36: 513820 | B36: 1 | D36: 80000 | E36: 62 | G36: R | H36: V
A37: 514774 | B37: 3 | D37: 80000 | E37: 44 | G37: V | H37: V
A38: 520201 | B38: 2 | D38: 80000 | E38: 36 | G38: V | H38: V
A39: 520938 | B39: 1 | C39: 23000 | D39: 11000 | E39: 36 | F39: 10 | G39: A | H39: A
A40: 521501 | B40: 1 | C40: 79000 | D40: 67000 | E40: 26 | F40: 8 | G40: A | H40: A
A41: 526149 | B41: 3 | C41: 97000 | D41: 92380.952 | E41: 55 | F41: 9 | G41: A | H41: A
A42: 539134 | B42: 1 | C42: 94000 | D42: 82000 | E42: 32 | F42: 10 | G42: A | H42: A
A43: 540346 | B43: 1 | C43: 95000 | D43: 90476.19 | E43: 49 | F43: 10 | G43: A | H43: A
...
