Workbook

Sheet Data
A2: Employee Data Provided for the 2015 valuation
A3: valuation date | C3: 42005
A5: ID | B5: Name | C5: Date of Birth | D5: Date of Hire | E5: 2014 Salary | F5: 2013 Salary | G5: 2012 Salary | H5: Retirement Date | I5: Retirement Benefit | J5: 1/1/2015 Status | K5: 1/1/2014 Status | L5: Age | M5: Service | N5: Average Salary | O5: Salary Increase
A6: 123451 | B6: Lee, Gordon | C6: 13789 | D6: 37462 | H6: 37530 | I6: 7800 | J6: R | K6: R | L6: =(YEAR($C$3)-YEAR(C6))+(MONTH($C$3)-MONTH(C6))/12+(DAY($C$3)-DAY(C6))/365 -> 77.25 | M6: =(YEAR($C$3)-YEAR(D6))+(MONTH($C$3)-MONTH(D6))/12+(DAY($C$3)-DAY(D6))/365 -> 12.434247 | N6: =IF(AND(E6="",F6="",G6=""),"",AVERAGE(E6:G6)) | O6: =IF(OR(M6<2,E6="",F6=""),"",E6/F6-1)
A7: 123465 | B7: Clinton, Bills | C7: 16803 | D7: 37462 | H7: 40544 | I7: 10349 | J7: R | K7: R | L7: =(YEAR($C$3)-YEAR(C7))+(MONTH($C$3)-MONTH(C7))/12+(DAY($C$3)-DAY(C7))/365 -> 69 | M7: =(YEAR($C$3)-YEAR(D7))+(MONTH($C$3)-MONTH(D7))/12+(DAY($C$3)-DAY(D7))/365 -> 12.434247 | N7: =IF(AND(E7="",F7="",G7=""),"",AVERAGE(E7:G7)) | O7: =IF(OR(M7<2,E7="",F7=""),"",E7/F7-1)
A8: 123466 | B8: Jordon, Hillary | C8: 22098 | D8: 37462 | H8: 45839 | I8: 15804 | J8: V | K8: V | L8: =(YEAR($C$3)-YEAR(C8))+(MONTH($C$3)-MONTH(C8))/12+(DAY($C$3)-DAY(C8))/365 -> 54.5 | M8: =(YEAR($C$3)-YEAR(D8))+(MONTH($C$3)-MONTH(D8))/12+(DAY($C$3)-DAY(D8))/365 -> 12.434247 | N8: =IF(AND(E8="",F8="",G8=""),"",AVERAGE(E8:G8)) | O8: =IF(OR(M8<2,E8="",F8=""),"",E8/F8-1)
A9: 123472 | B9: Jobs, Benjamin | C9: 19725 | D9: 37462 | H9: 43466 | I9: 5840 | J9: V | K9: A | L9: =(YEAR($C$3)-YEAR(C9))+(MONTH($C$3)-MONTH(C9))/12+(DAY($C$3)-DAY(C9))/365 -> 61 | M9: =(YEAR($C$3)-YEAR(D9))+(MONTH($C$3)-MONTH(D9))/12+(DAY($C$3)-DAY(D9))/365 -> 12.434247 | N9: =IF(AND(E9="",F9="",G9=""),"",AVERAGE(E9:G9)) | O9: =IF(OR(M9<2,E9="",F9=""),"",E9/F9-1)
A10: 123484 | B10: Larson, George | C10: 18203 | D10: 37462 | H10: 41944 | I10: 9625 | J10: R | K10: A | L10: =(YEAR($C$3)-YEAR(C10))+(MONTH($C$3)-MONTH(C10))/12+(DAY($C$3)-DAY(C10))/365 -> 65.166667 | M10: =(YEAR($C$3)-YEAR(D10))+(MONTH($C$3)-MONTH(D10))/12+(DAY($C$3)-DAY(D10))/365 -> 12.434247 | N10: =IF(AND(E10="",F10="",G10=""),"",AVERAGE(E10:G10)) | O10: =IF(OR(M10<2,E10="",F10=""),"",E10/F10-1)
A11: 123485 | B11: Larson, Chris | C11: 16254 | D11: 37462 | H11: 39995 | I11: 18047 | J11: R | K11: R | L11: =(YEAR($C$3)-YEAR(C11))+(MONTH($C$3)-MONTH(C11))/12+(DAY($C$3)-DAY(C11))/365 -> 70.5 | M11: =(YEAR($C$3)-YEAR(D11))+(MONTH($C$3)-MONTH(D11))/12+(DAY($C$3)-DAY(D11))/365 -> 12.434247 | N11: =IF(AND(E11="",F11="",G11=""),"",AVERAGE(E11:G11)) | O11: =IF(OR(M11<2,E11="",F11=""),"",E11/F11-1)
A12: 123486 | B12: Wang, Eric | C12: 19725 | D12: 37462 | H12: 43466 | I12: 8990 | J12: V | K12: V | L12: =(YEAR($C$3)-YEAR(C12))+(MONTH($C$3)-MONTH(C12))/12+(DAY($C$3)-DAY(C12))/365 -> 61 | M12: =(YEAR($C$3)-YEAR(D12))+(MONTH($C$3)-MONTH(D12))/12+(DAY($C$3)-DAY(D12))/365 -> 12.434247 | N12: =IF(AND(E12="",F12="",G12=""),"",AVERAGE(E12:G12)) | O12: =IF(OR(M12<2,E12="",F12=""),"",E12/F12-1)
A13: 123491 | B13: Shapiro, Amanda | C13: 24017 | D13: 34809 | E13: 250000 | F13: 230000 | G13: 210000 | J13: A | K13: A | L13: =(YEAR($C$3)-YEAR(C13))+(MONTH($C$3)-MONTH(C13))/12+(DAY($C$3)-DAY(C13))/365 -> 49.24726 | M13: =(YEAR($C$3)-YEAR(D13))+(MONTH($C$3)-MONTH(D13))/12+(DAY($C$3)-DAY(D13))/365 -> 19.697945 | N13: =IF(AND(E13="",F13="",G13=""),"",AVERAGE(E13:G13)) -> 230000 | O13: =IF(OR(M13<2,E13="",F13=""),"",E13/F13-1) -> 0.086956522
A14: 144983 | B14: Donovan, Adrienne | C14: 27601 | D14: 38001 | E14: 99000 | F14: 94300 | G14: 89800 | J14: A | K14: A | L14: =(YEAR($C$3)-YEAR(C14))+(MONTH($C$3)-MONTH(C14))/12+(DAY($C$3)-DAY(C14))/365 -> 39.431507 | M14: =(YEAR($C$3)-YEAR(D14))+(MONTH($C$3)-MONTH(D14))/12+(DAY($C$3)-DAY(D14))/365 -> 10.961644 | N14: =IF(AND(E14="",F14="",G14=""),"",AVERAGE(E14:G14)) -> 94366.667 | O14: =IF(OR(M14<2,E14="",F14=""),"",E14/F14-1) -> 0.049840933
A15: 187427 | B15: Tiedens, Bret | C15: 21170 | D15: 37975 | E15: 98000 | F15: 93300 | G15: 88900 | J15: A | K15: A | L15: =(YEAR($C$3)-YEAR(C15))+(MONTH($C$3)-MONTH(C15))/12+(DAY($C$3)-DAY(C15))/365 -> 57.042237 | M15: =(YEAR($C$3)-YEAR(D15))+(MONTH($C$3)-MONTH(D15))/12+(DAY($C$3)-DAY(D15))/365 -> 11.031279 | N15: =IF(AND(E15="",F15="",G15=""),"",AVERAGE(E15:G15)) -> 93400 | O15: =IF(OR(M15<2,E15="",F15=""),"",E15/F15-1) -> 0.050375134
A16: 189508 | B16: Souers, Celina | C16: 30229 | D16: 35020 | E16: 97000 | F16: 92400 | G16: 88000 | J16: A | K16: A | L16: =(YEAR($C$3)-YEAR(C16))+(MONTH($C$3)-MONTH(C16))/12+(DAY($C$3)-DAY(C16))/365 -> 32.239041 | M16: =(YEAR($C$3)-YEAR(D16))+(MONTH($C$3)-MONTH(D16))/12+(DAY($C$3)-DAY(D16))/365 -> 19.122831 | N16: =IF(AND(E16="",F16="",G16=""),"",AVERAGE(E16:G16)) -> 92466.667 | O16: =IF(OR(M16<2,E16="",F16=""),"",E16/F16-1) -> 0.04978355
A17: 199741 | B17: Al Jaloud, Steve | C17: 16439 | D17: 35929 | E17: 96000 | F17: 91400 | G17: 87100 | J17: A | K17: A | L17: =(YEAR($C$3)-YEAR(C17))+(MONTH($C$3)-MONTH(C17))/12+(DAY($C$3)-DAY(C17))/365 -> 69.99726 | M17: =(YEAR($C$3)-YEAR(D17))+(MONTH($C$3)-MONTH(D17))/12+(DAY($C$3)-DAY(D17))/365 -> 16.63105 | N17: =IF(AND(E17="",F17="",G17=""),"",AVERAGE(E17:G17)) -> 91500 | O17: =IF(OR(M17<2,E17="",F17=""),"",E17/F17-1) -> 0.050328228
A18: 205217 | B18: Butina, Natalie | C18: 17620 | D18: 34867 | E18: 95000 | F18: 90500 | G18: 86200 | J18: A | K18: A | L18: =(YEAR($C$3)-YEAR(C18))+(MONTH($C$3)-MONTH(C18))/12+(DAY($C$3)-DAY(C18))/365 -> 66.759361 | M18: =(YEAR($C$3)-YEAR(D18))+(MONTH($C$3)-MONTH(D18))/12+(DAY($C$3)-DAY(D18))/365 -> 19.539498 | N18: =IF(AND(E18="",F18="",G18=""),"",AVERAGE(E18:G18)) -> 90566.667 | O18: =IF(OR(M18<2,E18="",F18=""),"",E18/F18-1) -> 0.049723757
A19: 206418 | B19: Olson, Nicholas | C19: 20874 | D19: 40497 | E19: 320000 | F19: 32000 | J19: A | K19: A | L19: =(YEAR($C$3)-YEAR(C19))+(MONTH($C$3)-MONTH(C19))/12+(DAY($C$3)-DAY(C19))/365 -> 57.856393 | M19: =(YEAR($C$3)-YEAR(D19))+(MONTH($C$3)-MONTH(D19))/12+(DAY($C$3)-DAY(D19))/365 -> 4.1283105 | N19: =IF(AND(E19="",F19="",G19=""),"",AVERAGE(E19:G19)) -> 176000 | O19: =IF(OR(M19<2,E19="",F19=""),"",E19/F19-1) -> 9
A20: 218201 | B20: Richman, Michelle | C20: 15818 | D20: 35362 | E20: 93000 | F20: 88600 | G20: 84400 | J20: A | K20: A | L20: =(YEAR($C$3)-YEAR(C20))+(MONTH($C$3)-MONTH(C20))/12+(DAY($C$3)-DAY(C20))/365 -> 71.692466 | M20: =(YEAR($C$3)-YEAR(D20))+(MONTH($C$3)-MONTH(D20))/12+(DAY($C$3)-DAY(D20))/365 -> 18.186986 | N20: =IF(AND(E20="",F20="",G20=""),"",AVERAGE(E20:G20)) -> 88666.667 | O20: =IF(OR(M20<2,E20="",F20=""),"",E20/F20-1) -> 0.0496614
A21: 225139 | B21: Johnson, Aaron | C21: 33987 | D21: 41074 | E21: 92000 | F21: 40000 | J21: A | K21: A | L21: =(YEAR($C$3)-YEAR(C21))+(MONTH($C$3)-MONTH(C21))/12+(DAY($C$3)-DAY(C21))/365 -> 21.953425 | M21: =(YEAR($C$3)-YEAR(D21))+(MONTH($C$3)-MONTH(D21))/12+(DAY($C$3)-DAY(D21))/365 -> 2.5477169 | N21: =IF(AND(E21="",F21="",G21=""),"",AVERAGE(E21:G21)) -> 66000 | O21: =IF(OR(M21<2,E21="",F21=""),"",E21/F21-1) -> 1.3
A22: 232072 | B22: Brinkley, Jeanne M | C22: 24290 | D22: 39634 | E22: 91000 | F22: 86700 | G22: 82500 | J22: A | K22: A | L22: =(YEAR($C$3)-YEAR(C22))+(MONTH($C$3)-MONTH(C22))/12+(DAY($C$3)-DAY(C22))/365 -> 48.49726 | M22: =(YEAR($C$3)-YEAR(D22))+(MONTH($C$3)-MONTH(D22))/12+(DAY($C$3)-DAY(D22))/365 -> 6.4890411 | N22: =IF(AND(E22="",F22="",G22=""),"",AVERAGE(E22:G22)) -> 86733.333 | O22: =IF(OR(M22<2,E22="",F22=""),"",E22/F22-1) -> 0.049596309
A23: 250067 | B23: Brinkley, Roxanne L | C23: 21975 | D23: 40073 | E23: 90000 | F23: 85700 | G23: 81600 | J23: A | K23: A | L23: =(YEAR($C$3)-YEAR(C23))+(MONTH($C$3)-MONTH(C23))/12+(DAY($C$3)-DAY(C23))/365 -> 54.839954 | M23: =(YEAR($C$3)-YEAR(D23))+(MONTH($C$3)-MONTH(D23))/12+(DAY($C$3)-DAY(D23))/365 -> 5.2894977 | N23: =IF(AND(E23="",F23="",G23=""),"",AVERAGE(E23:G23)) -> 85766.667 | O23: =IF(OR(M23<2,E23="",F23=""),"",E23/F23-1) -> 0.050175029
A24: 253862 | B24: Nelson, Yuyang | C24: 23332 | D24: 40339 | E24: 89000 | F24: 84800 | G24: 80700 | J24: A | K24: A | L24: =(YEAR($C$3)-YEAR(C24))+(MONTH($C$3)-MONTH(C24))/12+(DAY($C$3)-DAY(C24))/365 -> 51.122831 | M24: =(YEAR($C$3)-YEAR(D24))+(MONTH($C$3)-MONTH(D24))/12+(DAY($C$3)-DAY(D24))/365 -> 4.5586758 | N24: =IF(AND(E24="",F24="",G24=""),"",AVERAGE(E24:G24)) -> 84833.333 | O24: =IF(OR(M24<2,E24="",F24=""),"",E24/F24-1) -> 0.049528302
A25: 255179 | B25: Bossler, Bill | C25: 22281 | D25: 40774 | E25: 88000 | F25: 83800 | G25: 40000 | J25: A | K25: A | L25: =(YEAR($C$3)-YEAR(C25))+(MONTH($C$3)-MONTH(C25))/12+(DAY($C$3)-DAY(C25))/365 -> 54.001142 | M25: =(YEAR($C$3)-YEAR(D25))+(MONTH($C$3)-MONTH(D25))/12+(DAY($C$3)-DAY(D25))/365 -> 3.3673516 | N25: =IF(AND(E25="",F25="",G25=""),"",AVERAGE(E25:G25)) -> 70600 | O25: =IF(OR(M25<2,E25="",F25=""),"",E25/F25-1) -> 0.050119332
A26: 258130 | B26: Cress, Scott G | C26: 29124 | D26: 37462 | E26: 87000 | F26: 82900 | G26: 78900 | J26: A | K26: A | L26: =(YEAR($C$3)-YEAR(C26))+(MONTH($C$3)-MONTH(C26))/12+(DAY($C$3)-DAY(C26))/365 -> 35.26484 | M26: =(YEAR($C$3)-YEAR(D26))+(MONTH($C$3)-MONTH(D26))/12+(DAY($C$3)-DAY(D26))/365 -> 12.434247 | N26: =IF(AND(E26="",F26="",G26=""),"",AVERAGE(E26:G26)) -> 82933.333 | O26: =IF(OR(M26<2,E26="",F26=""),"",E26/F26-1) -> 0.049457177
A27: 286491 | B27: Aljebreen, Patric | C27: 16018 | D27: 31071 | E27: 86000 | F27: 81900 | G27: 78000 | J27: A | K27: A | L27: =(YEAR($C$3)-YEAR(C27))+(MONTH($C$3)-MONTH(C27))/12+(DAY($C$3)-DAY(C27))/365 -> 71.147489 | M27: =(YEAR($C$3)-YEAR(D27))+(MONTH($C$3)-MONTH(D27))/12+(DAY($C$3)-DAY(D27))/365 -> 29.936986 | N27: =IF(AND(E27="",F27="",G27=""),"",AVERAGE(E27:G27)) -> 81966.667 | O27: =IF(OR(M27<2,E27="",F27=""),"",E27/F27-1) -> 0.05006105
A28: 290999 | B28: Dehn, Diane M | C28: 25991 | D28: 41600 | E28: 85000 | F28: 2000 | J28: A | L28: =(YEAR($C$3)-YEAR(C28))+(MONTH($C$3)-MONTH(C28))/12+(DAY($C$3)-DAY(C28))/365 -> 43.845434 | M28: =(YEAR($C$3)-YEAR(D28))+(MONTH($C$3)-MONTH(D28))/12+(DAY($C$3)-DAY(D28))/365 -> 1.1091324 | N28: =IF(AND(E28="",F28="",G28=""),"",AVERAGE(E28:G28)) -> 43500 | O28: =IF(OR(M28<2,E28="",F28=""),"",E28/F28-1)
A29: 300843 | B29: Baker, Eric | C29: 17659 | D29: 31876 | E29: 84000 | F29: 80000 | G29: 76200 | J29: A | K29: A | L29: =(YEAR($C$3)-YEAR(C29))+(MONTH($C$3)-MONTH(C29))/12+(DAY($C$3)-DAY(C29))/365 -> 66.652968 | M29: =(YEAR($C$3)-YEAR(D29))+(MONTH($C$3)-MONTH(D29))/12+(DAY($C$3)-DAY(D29))/365 -> 27.728082 | N29: =IF(AND(E29="",F29="",G29=""),"",AVERAGE(E29:G29)) -> 80066.667 | O29: =IF(OR(M29<2,E29="",F29=""),"",E29/F29-1) -> 0.05
A30: 302798 | B30: Asche, Ryan | C30: 28924 | D30: 35009 | E30: 300000 | F30: 276000 | G30: 252000 | J30: A | K30: A | L30: =(YEAR($C$3)-YEAR(C30))+(MONTH($C$3)-MONTH(C30))/12+(DAY($C$3)-DAY(C30))/365 -> 35.808676 | M30: =(YEAR($C$3)-YEAR(D30))+(MONTH($C$3)-MONTH(D30))/12+(DAY($C$3)-DAY(D30))/365 -> 19.152968 | N30: =IF(AND(E30="",F30="",G30=""),"",AVERAGE(E30:G30)) -> 276000 | O30: =IF(OR(M30<2,E30="",F30=""),"",E30/F30-1) -> 0.086956522
A31: 310267 | B31: Chen, Jerome F | C31: 23532 | D31: 38201 | E31: 118800 | F31: 113100 | G31: 107800 | J31: A | K31: A | L31: =(YEAR($C$3)-YEAR(C31))+(MONTH($C$3)-MONTH(C31))/12+(DAY($C$3)-DAY(C31))/365 -> 50.575114 | M31: =(YEAR($C$3)-YEAR(D31))+(MONTH($C$3)-MONTH(D31))/12+(DAY($C$3)-DAY(D31))/365 -> 10.413927 | N31: =IF(AND(E31="",F31="",G31=""),"",AVERAGE(E31:G31)) -> 113233.33 | O31: =IF(OR(M31<2,E31="",F31=""),"",E31/F31-1) -> 0.050397878
A32: 313615 | B32: Gist, Tracy A | C32: 34187 | D32: 38175 | E32: 117600 | F32: 112000 | G32: 106700 | J32: A | K32: A | L32: =(YEAR($C$3)-YEAR(C32))+(MONTH($C$3)-MONTH(C32))/12+(DAY($C$3)-DAY(C32))/365 -> 21.402968 | M32: =(YEAR($C$3)-YEAR(D32))+(MONTH($C$3)-MONTH(D32))/12+(DAY($C$3)-DAY(D32))/365 -> 10.483562 | N32: =IF(AND(E32="",F32="",G32=""),"",AVERAGE(E32:G32)) -> 112100 | O32: =IF(OR(M32<2,E32="",F32=""),"",E32/F32-1) -> 0.05
A33: 320387 | B33: Carlson, Jeremy | C33: 25791 | D33: 35220 | E33: 116400 | F33: 110900 | G33: 105600 | J33: A | K33: A | L33: =(YEAR($C$3)-YEAR(C33))+(MONTH($C$3)-MONTH(C33))/12+(DAY($C$3)-DAY(C33))/365 -> 44.389269 | M33: =(YEAR($C$3)-YEAR(D33))+(MONTH($C$3)-MONTH(D33))/12+(DAY($C$3)-DAY(D33))/365 -> 18.575114 | N33: =IF(AND(E33="",F33="",G33=""),"",AVERAGE(E33:G33)) -> 110966.67 | O33: =IF(OR(M33<2,E33="",F33=""),"",E33/F33-1) -> 0.049594229
A34: 340436 | B34: Duvall, DeeAnn S | C34: 27791 | D34: 36129 | E34: 115200 | F34: 109700 | G34: 104500 | J34: A | K34: A | L34: =(YEAR($C$3)-YEAR(C34))+(MONTH($C$3)-MONTH(C34))/12+(DAY($C$3)-DAY(C34))/365 -> 38.916667 | M34: =(YEAR($C$3)-YEAR(D34))+(MONTH($C$3)-MONTH(D34))/12+(DAY($C$3)-DAY(D34))/365 -> 16.087215 | N34: =IF(AND(E34="",F34="",G34=""),"",AVERAGE(E34:G34)) -> 109800 | O34: =IF(OR(M34<2,E34="",F34=""),"",E34/F34-1) -> 0.050136737
A35: 345767 | B35: Gall, Susann K | C35: 24217 | D35: 35067 | E35: 114000 | F35: 108600 | G35: 103400 | J35: A | K35: A | L35: =(YEAR($C$3)-YEAR(C35))+(MONTH($C$3)-MONTH(C35))/12+(DAY($C$3)-DAY(C35))/365 -> 48.697945 | M35: =(YEAR($C$3)-YEAR(D35))+(MONTH($C$3)-MONTH(D35))/12+(DAY($C$3)-DAY(D35))/365 -> 18.994521 | N35: =IF(AND(E35="",F35="",G35=""),"",AVERAGE(E35:G35)) -> 108666.67 | O35: =IF(OR(M35<2,E35="",F35=""),"",E35/F35-1) -> 0.049723757
A36: 352244 | B36: Harvestine, Susan R | C36: 21370 | D36: 41429 | E36: 384000 | F36: 38400 | J36: A | L36: =(YEAR($C$3)-YEAR(C36))+(MONTH($C$3)-MONTH(C36))/12+(DAY($C$3)-DAY(C36))/365 -> 56.491781 | M36: =(YEAR($C$3)-YEAR(D36))+(MONTH($C$3)-MONTH(D36))/12+(DAY($C$3)-DAY(D36))/365 -> 1.5751142 | N36: =IF(AND(E36="",F36="",G36=""),"",AVERAGE(E36:G36)) -> 211200 | O36: =IF(OR(M36<2,E36="",F36=""),"",E36/F36-1)
A37: 357982 | B37: Harada, Richard G | C37: 17820 | D37: 35562 | E37: 111600 | F37: 106300 | G37: 101200 | J37: A | K37: A | L37: =(YEAR($C$3)-YEAR(C37))+(MONTH($C$3)-MONTH(C37))/12+(DAY($C$3)-DAY(C37))/365 -> 66.214384 | M37: =(YEAR($C$3)-YEAR(D37))+(MONTH($C$3)-MONTH(D37))/12+(DAY($C$3)-DAY(D37))/365 -> 17.63653 | N37: =IF(AND(E37="",F37="",G37=""),"",AVERAGE(E37:G37)) -> 106366.67 | O37: =IF(OR(M37<2,E37="",F37=""),"",E37/F37-1) -> 0.04985889
A38: 369257 | B38: Guy, Robert L | C38: 3651 | D38: 41274 | E38: 110400 | F38: 48000 | J38: A | K38: A | L38: =(YEAR($C$3)-YEAR(C38))+(MONTH($C$3)-MONTH(C38))/12+(DAY($C$3)-DAY(C38))/365 -> 105.00662 | M38: =(YEAR($C$3)-YEAR(D38))+(MONTH($C$3)-MONTH(D38))/12+(DAY($C$3)-DAY(D38))/365 -> 2.0011416 | N38: =IF(AND(E38="",F38="",G38=""),"",AVERAGE(E38:G38)) -> 79200 | O38: =IF(OR(M38<2,E38="",F38=""),"",E38/F38-1) -> 1.3
A39: 375122 | B39: Kampwerth, Rebecca M | C39: 17859 | D39: 39834 | E39: 109200 | F39: 104000 | G39: 99000 | J39: A | K39: A | L39: =(YEAR($C$3)-YEAR(C39))+(MONTH($C$3)-MONTH(C39))/12+(DAY($C$3)-DAY(C39))/365 -> 66.109132 | M39: =(YEAR($C$3)-YEAR(D39))+(MONTH($C$3)-MONTH(D39))/12+(DAY($C$3)-DAY(D39))/365 -> 5.9452055 | N39: =IF(AND(E39="",F39="",G39=""),"",AVERAGE(E39:G39)) -> 104066.67 | O39: =IF(OR(M39<2,E39="",F39=""),"",E39/F39-1) -> 0.05
A40: 406300 | B40: Asche, Alexis | C40: 1 | D40: 40273 | E40: 108000 | F40: 102900 | G40: 98000 | J40: A | K40: A | L40: =(YEAR($C$3)-YEAR(C40))+(MONTH($C$3)-MONTH(C40))/12+(DAY($C$3)-DAY(C40))/365 -> 115 | M40: =(YEAR($C$3)-YEAR(D40))+(MONTH($C$3)-MONTH(D40))/12+(DAY($C$3)-DAY(D40))/365 -> 4.7390411 | N40: =IF(AND(E40="",F40="",G40=""),"",AVERAGE(E40:G40)) -> 102966.67 | O40: =IF(OR(M40<2,E40="",F40=""),"",E40/F40-1) -> 0.049562682
A41: 422365 | B41: Hitpas, Bruce D | C41: 21074 | D41: 40539 | E41: 106800 | F41: 101700 | G41: 96900 | J41: A | K41: A | L41: =(YEAR($C$3)-YEAR(C41))+(MONTH($C$3)-MONTH(C41))/12+(DAY($C$3)-DAY(C41))/365 -> 57.305936 | M41: =(YEAR($C$3)-YEAR(D41))+(MONTH($C$3)-MONTH(D41))/12+(DAY($C$3)-DAY(D41))/365 -> 4.0121005 | N41: =IF(AND(E41="",F41="",G41=""),"",AVERAGE(E41:G41)) -> 101800 | O41: =IF(OR(M41<2,E41="",F41=""),"",E41/F41-1) -> 0.050147493
A42: 423109 | B42: Jumaan, Casey A | C42: 16218 | D42: 40974 | E42: 105600 | F42: 100600 | G42: 48000 | J42: A | K42: A | L42: =(YEAR($C$3)-YEAR(C42))+(MONTH($C$3)-MONTH(C42))/12+(DAY($C$3)-DAY(C42))/365 -> 70.598174 | M42: =(YEAR($C$3)-YEAR(D42))+(MONTH($C$3)-MONTH(D42))/12+(DAY($C$3)-DAY(D42))/365 -> 2.8196347 | N42: =IF(AND(E42="",F42="",G42=""),"",AVERAGE(E42:G42)) -> 84733.333 | O42: =IF(OR(M42<2,E42="",F42=""),"",E42/F42-1) -> 0.049701789
...

Sheet Data1
A2: Employee Data Provided for the 2015 valuation
A3: valuation date | C3: 42005
A5: ID | B5: Name | C5: Date of Birth | D5: Date of Hire | E5: 2014 Salary | F5: 2013 Salary | G5: 2012 Salary | H5: Retirement Date | I5: Retirement Benefit | J5: 1/1/2015 Status | K5: 1/1/2014 Status | L5: Age | M5: Service | N5: Average Salary | O5: Salary Increase
A6: 123451 | B6: =TRIM(RIGHT(Data!B6,LEN(Data!B6)-SEARCH(",",Data!B6))&" "&LEFT(Data!B6,SEARCH(",",Data!B6)-1)) -> Gordon Lee | C6: 13789 | D6: 37462 | H6: 37530 | I6: 7800 | J6: R | K6: R | L6: =(YEAR($C$3)-YEAR(C6))+(MONTH($C$3)-MONTH(C6))/12+(DAY($C$3)-DAY(C6))/365 -> 77.25 | M6: =(YEAR($C$3)-YEAR(D6))+(MONTH($C$3)-MONTH(D6))/12+(DAY($C$3)-DAY(D6))/365 -> 12.434247 | N6: =IF(AND(E6="",F6="",G6=""),"",AVERAGE(E6:G6)) | O6: =IF(OR(M6<2,E6="",F6=""),"",E6/F6-1)
A7: 123465 | B7: =TRIM(RIGHT(Data!B7,LEN(Data!B7)-SEARCH(",",Data!B7))&" "&LEFT(Data!B7,SEARCH(",",Data!B7)-1)) -> Bills Clinton | C7: 16803 | D7: 37462 | H7: 40544 | I7: 10349 | J7: R | K7: R | L7: =(YEAR($C$3)-YEAR(C7))+(MONTH($C$3)-MONTH(C7))/12+(DAY($C$3)-DAY(C7))/365 -> 69 | M7: =(YEAR($C$3)-YEAR(D7))+(MONTH($C$3)-MONTH(D7))/12+(DAY($C$3)-DAY(D7))/365 -> 12.434247 | N7: =IF(AND(E7="",F7="",G7=""),"",AVERAGE(E7:G7)) | O7: =IF(OR(M7<2,E7="",F7=""),"",E7/F7-1)
A8: 123466 | B8: =TRIM(RIGHT(Data!B8,LEN(Data!B8)-SEARCH(",",Data!B8))&" "&LEFT(Data!B8,SEARCH(",",Data!B8)-1)) -> Hillary Jordon | C8: 22098 | D8: 37462 | H8: 45839 | I8: 15804 | J8: V | K8: V | L8: =(YEAR($C$3)-YEAR(C8))+(MONTH($C$3)-MONTH(C8))/12+(DAY($C$3)-DAY(C8))/365 -> 54.5 | M8: =(YEAR($C$3)-YEAR(D8))+(MONTH($C$3)-MONTH(D8))/12+(DAY($C$3)-DAY(D8))/365 -> 12.434247 | N8: =IF(AND(E8="",F8="",G8=""),"",AVERAGE(E8:G8)) | O8: =IF(OR(M8<2,E8="",F8=""),"",E8/F8-1)
A9: 123472 | B9: =TRIM(RIGHT(Data!B9,LEN(Data!B9)-SEARCH(",",Data!B9))&" "&LEFT(Data!B9,SEARCH(",",Data!B9)-1)) -> Benjamin Jobs | C9: 19725 | D9: 37462 | H9: 43466 | I9: 5840 | J9: V | K9: A | L9: =(YEAR($C$3)-YEAR(C9))+(MONTH($C$3)-MONTH(C9))/12+(DAY($C$3)-DAY(C9))/365 -> 61 | M9: =(YEAR($C$3)-YEAR(D9))+(MONTH($C$3)-MONTH(D9))/12+(DAY($C$3)-DAY(D9))/365 -> 12.434247 | N9: =IF(AND(E9="",F9="",G9=""),"",AVERAGE(E9:G9)) | O9: =IF(OR(M9<2,E9="",F9=""),"",E9/F9-1)
A10: 123484 | B10: =TRIM(RIGHT(Data!B10,LEN(Data!B10)-SEARCH(",",Data!B10))&" "&LEFT(Data!B10,SEARCH(",",Data!B10)-1)) -> George Larson | C10: 18203 | D10: 37462 | H10: 41944 | I10: 9625 | J10: R | K10: A | L10: =(YEAR($C$3)-YEAR(C10))+(MONTH($C$3)-MONTH(C10))/12+(DAY($C$3)-DAY(C10))/365 -> 65.166667 | M10: =(YEAR($C$3)-YEAR(D10))+(MONTH($C$3)-MONTH(D10))/12+(DAY($C$3)-DAY(D10))/365 -> 12.434247 | N10: =IF(AND(E10="",F10="",G10=""),"",AVERAGE(E10:G10)) | O10: =IF(OR(M10<2,E10="",F10=""),"",E10/F10-1)
A11: 123485 | B11: =TRIM(RIGHT(Data!B11,LEN(Data!B11)-SEARCH(",",Data!B11))&" "&LEFT(Data!B11,SEARCH(",",Data!B11)-1)) -> Chris Larson | C11: 16254 | D11: 37462 | H11: 39995 | I11: 18047 | J11: R | K11: R | L11: =(YEAR($C$3)-YEAR(C11))+(MONTH($C$3)-MONTH(C11))/12+(DAY($C$3)-DAY(C11))/365 -> 70.5 | M11: =(YEAR($C$3)-YEAR(D11))+(MONTH($C$3)-MONTH(D11))/12+(DAY($C$3)-DAY(D11))/365 -> 12.434247 | N11: =IF(AND(E11="",F11="",G11=""),"",AVERAGE(E11:G11)) | O11: =IF(OR(M11<2,E11="",F11=""),"",E11/F11-1)
A12: 123486 | B12: =TRIM(RIGHT(Data!B12,LEN(Data!B12)-SEARCH(",",Data!B12))&" "&LEFT(Data!B12,SEARCH(",",Data!B12)-1)) -> Eric Wang | C12: 19725 | D12: 37462 | H12: 43466 | I12: 8990 | J12: V | K12: V | L12: =(YEAR($C$3)-YEAR(C12))+(MONTH($C$3)-MONTH(C12))/12+(DAY($C$3)-DAY(C12))/365 -> 61 | M12: =(YEAR($C$3)-YEAR(D12))+(MONTH($C$3)-MONTH(D12))/12+(DAY($C$3)-DAY(D12))/365 -> 12.434247 | N12: =IF(AND(E12="",F12="",G12=""),"",AVERAGE(E12:G12)) | O12: =IF(OR(M12<2,E12="",F12=""),"",E12/F12-1)
A13: 123491 | B13: =TRIM(RIGHT(Data!B13,LEN(Data!B13)-SEARCH(",",Data!B13))&" "&LEFT(Data!B13,SEARCH(",",Data!B13)-1)) -> Amanda Shapiro | C13: 24017 | D13: 34809 | E13: 250000 | F13: 230000 | G13: 210000 | J13: A | K13: A | L13: =(YEAR($C$3)-YEAR(C13))+(MONTH($C$3)-MONTH(C13))/12+(DAY($C$3)-DAY(C13))/365 -> 49.24726 | M13: =(YEAR($C$3)-YEAR(D13))+(MONTH($C$3)-MONTH(D13))/12+(DAY($C$3)-DAY(D13))/365 -> 19.697945 | N13: =IF(AND(E13="",F13="",G13=""),"",AVERAGE(E13:G13)) -> 230000 | O13: =IF(OR(M13<2,E13="",F13=""),"",E13/F13-1) -> 0.086956522
A14: 144983 | B14: =TRIM(RIGHT(Data!B14,LEN(Data!B14)-SEARCH(",",Data!B14))&" "&LEFT(Data!B14,SEARCH(",",Data!B14)-1)) -> Adrienne Donovan | C14: 27601 | D14: 38001 | E14: 99000 | F14: 94300 | G14: 89800 | J14: A | K14: A | L14: =(YEAR($C$3)-YEAR(C14))+(MONTH($C$3)-MONTH(C14))/12+(DAY($C$3)-DAY(C14))/365 -> 39.431507 | M14: =(YEAR($C$3)-YEAR(D14))+(MONTH($C$3)-MONTH(D14))/12+(DAY($C$3)-DAY(D14))/365 -> 10.961644 | N14: =IF(AND(E14="",F14="",G14=""),"",AVERAGE(E14:G14)) -> 94366.667 | O14: =IF(OR(M14<2,E14="",F14=""),"",E14/F14-1) -> 0.049840933
A15: 187427 | B15: =TRIM(RIGHT(Data!B15,LEN(Data!B15)-SEARCH(",",Data!B15))&" "&LEFT(Data!B15,SEARCH(",",Data!B15)-1)) -> Bret Tiedens | C15: 21170 | D15: 37975 | E15: 98000 | F15: 93300 | G15: 88900 | J15: A | K15: A | L15: =(YEAR($C$3)-YEAR(C15))+(MONTH($C$3)-MONTH(C15))/12+(DAY($C$3)-DAY(C15))/365 -> 57.042237 | M15: =(YEAR($C$3)-YEAR(D15))+(MONTH($C$3)-MONTH(D15))/12+(DAY($C$3)-DAY(D15))/365 -> 11.031279 | N15: =IF(AND(E15="",F15="",G15=""),"",AVERAGE(E15:G15)) -> 93400 | O15: =IF(OR(M15<2,E15="",F15=""),"",E15/F15-1) -> 0.050375134
A16: 189508 | B16: =TRIM(RIGHT(Data!B16,LEN(Data!B16)-SEARCH(",",Data!B16))&" "&LEFT(Data!B16,SEARCH(",",Data!B16)-1)) -> Celina Souers | C16: 30229 | D16: 35020 | E16: 97000 | F16: 92400 | G16: 88000 | J16: A | K16: A | L16: =(YEAR($C$3)-YEAR(C16))+(MONTH($C$3)-MONTH(C16))/12+(DAY($C$3)-DAY(C16))/365 -> 32.239041 | M16: =(YEAR($C$3)-YEAR(D16))+(MONTH($C$3)-MONTH(D16))/12+(DAY($C$3)-DAY(D16))/365 -> 19.122831 | N16: =IF(AND(E16="",F16="",G16=""),"",AVERAGE(E16:G16)) -> 92466.667 | O16: =IF(OR(M16<2,E16="",F16=""),"",E16/F16-1) -> 0.04978355
A17: 199741 | B17: =TRIM(RIGHT(Data!B17,LEN(Data!B17)-SEARCH(",",Data!B17))&" "&LEFT(Data!B17,SEARCH(",",Data!B17)-1)) -> Steve Al Jaloud | C17: 16439 | D17: 35929 | E17: 96000 | F17: 91400 | G17: 87100 | J17: A | K17: A | L17: =(YEAR($C$3)-YEAR(C17))+(MONTH($C$3)-MONTH(C17))/12+(DAY($C$3)-DAY(C17))/365 -> 69.99726 | M17: =(YEAR($C$3)-YEAR(D17))+(MONTH($C$3)-MONTH(D17))/12+(DAY($C$3)-DAY(D17))/365 -> 16.63105 | N17: =IF(AND(E17="",F17="",G17=""),"",AVERAGE(E17:G17)) -> 91500 | O17: =IF(OR(M17<2,E17="",F17=""),"",E17/F17-1) -> 0.050328228
A18: 205217 | B18: =TRIM(RIGHT(Data!B18,LEN(Data!B18)-SEARCH(",",Data!B18))&" "&LEFT(Data!B18,SEARCH(",",Data!B18)-1)) -> Natalie Butina | C18: 17620 | D18: 34867 | E18: 95000 | F18: 90500 | G18: 86200 | J18: A | K18: A | L18: =(YEAR($C$3)-YEAR(C18))+(MONTH($C$3)-MONTH(C18))/12+(DAY($C$3)-DAY(C18))/365 -> 66.759361 | M18: =(YEAR($C$3)-YEAR(D18))+(MONTH($C$3)-MONTH(D18))/12+(DAY($C$3)-DAY(D18))/365 -> 19.539498 | N18: =IF(AND(E18="",F18="",G18=""),"",AVERAGE(E18:G18)) -> 90566.667 | O18: =IF(OR(M18<2,E18="",F18=""),"",E18/F18-1) -> 0.049723757
A19: 206418 | B19: =TRIM(RIGHT(Data!B19,LEN(Data!B19)-SEARCH(",",Data!B19))&" "&LEFT(Data!B19,SEARCH(",",Data!B19)-1)) -> Nicholas Olson | C19: 20874 | D19: 40497 | E19: 320000 | F19: 32000 | J19: A | K19: A | L19: =(YEAR($C$3)-YEAR(C19))+(MONTH($C$3)-MONTH(C19))/12+(DAY($C$3)-DAY(C19))/365 -> 57.856393 | M19: =(YEAR($C$3)-YEAR(D19))+(MONTH($C$3)-MONTH(D19))/12+(DAY($C$3)-DAY(D19))/365 -> 4.1283105 | N19: =IF(AND(E19="",F19="",G19=""),"",AVERAGE(E19:G19)) -> 176000 | O19: =IF(OR(M19<2,E19="",F19=""),"",E19/F19-1) -> 9
A20: 218201 | B20: =TRIM(RIGHT(Data!B20,LEN(Data!B20)-SEARCH(",",Data!B20))&" "&LEFT(Data!B20,SEARCH(",",Data!B20)-1)) -> Michelle Richman | C20: 15818 | D20: 35362 | E20: 93000 | F20: 88600 | G20: 84400 | J20: A | K20: A | L20: =(YEAR($C$3)-YEAR(C20))+(MONTH($C$3)-MONTH(C20))/12+(DAY($C$3)-DAY(C20))/365 -> 71.692466 | M20: =(YEAR($C$3)-YEAR(D20))+(MONTH($C$3)-MONTH(D20))/12+(DAY($C$3)-DAY(D20))/365 -> 18.186986 | N20: =IF(AND(E20="",F20="",G20=""),"",AVERAGE(E20:G20)) -> 88666.667 | O20: =IF(OR(M20<2,E20="",F20=""),"",E20/F20-1) -> 0.0496614
A21: 225139 | B21: =TRIM(RIGHT(Data!B21,LEN(Data!B21)-SEARCH(",",Data!B21))&" "&LEFT(Data!B21,SEARCH(",",Data!B21)-1)) -> Aaron Johnson | C21: 33987 | D21: 41074 | E21: 92000 | F21: 40000 | J21: A | K21: A | L21: =(YEAR($C$3)-YEAR(C21))+(MONTH($C$3)-MONTH(C21))/12+(DAY($C$3)-DAY(C21))/365 -> 21.953425 | M21: =(YEAR($C$3)-YEAR(D21))+(MONTH($C$3)-MONTH(D21))/12+(DAY($C$3)-DAY(D21))/365 -> 2.5477169 | N21: =IF(AND(E21="",F21="",G21=""),"",AVERAGE(E21:G21)) -> 66000 | O21: =IF(OR(M21<2,E21="",F21=""),"",E21/F21-1) -> 1.3
A22: 232072 | B22: =TRIM(RIGHT(Data!B22,LEN(Data!B22)-SEARCH(",",Data!B22))&" "&LEFT(Data!B22,SEARCH(",",Data!B22)-1)) -> Jeanne M Brinkley | C22: 24290 | D22: 39634 | E22: 91000 | F22: 86700 | G22: 82500 | J22: A | K22: A | L22: =(YEAR($C$3)-YEAR(C22))+(MONTH($C$3)-MONTH(C22))/12+(DAY($C$3)-DAY(C22))/365 -> 48.49726 | M22: =(YEAR($C$3)-YEAR(D22))+(MONTH($C$3)-MONTH(D22))/12+(DAY($C$3)-DAY(D22))/365 -> 6.4890411 | N22: =IF(AND(E22="",F22="",G22=""),"",AVERAGE(E22:G22)) -> 86733.333 | O22: =IF(OR(M22<2,E22="",F22=""),"",E22/F22-1) -> 0.049596309
A23: 250067 | B23: =TRIM(RIGHT(Data!B23,LEN(Data!B23)-SEARCH(",",Data!B23))&" "&LEFT(Data!B23,SEARCH(",",Data!B23)-1)) -> Roxanne L Brinkley | C23: 21975 | D23: 40073 | E23: 90000 | F23: 85700 | G23: 81600 | J23: A | K23: A | L23: =(YEAR($C$3)-YEAR(C23))+(MONTH($C$3)-MONTH(C23))/12+(DAY($C$3)-DAY(C23))/365 -> 54.839954 | M23: =(YEAR($C$3)-YEAR(D23))+(MONTH($C$3)-MONTH(D23))/12+(DAY($C$3)-DAY(D23))/365 -> 5.2894977 | N23: =IF(AND(E23="",F23="",G23=""),"",AVERAGE(E23:G23)) -> 85766.667 | O23: =IF(OR(M23<2,E23="",F23=""),"",E23/F23-1) -> 0.050175029
A24: 253862 | B24: =TRIM(RIGHT(Data!B24,LEN(Data!B24)-SEARCH(",",Data!B24))&" "&LEFT(Data!B24,SEARCH(",",Data!B24)-1)) -> Yuyang Nelson | C24: 23332 | D24: 40339 | E24: 89000 | F24: 84800 | G24: 80700 | J24: A | K24: A | L24: =(YEAR($C$3)-YEAR(C24))+(MONTH($C$3)-MONTH(C24))/12+(DAY($C$3)-DAY(C24))/365 -> 51.122831 | M24: =(YEAR($C$3)-YEAR(D24))+(MONTH($C$3)-MONTH(D24))/12+(DAY($C$3)-DAY(D24))/365 -> 4.5586758 | N24: =IF(AND(E24="",F24="",G24=""),"",AVERAGE(E24:G24)) -> 84833.333 | O24: =IF(OR(M24<2,E24="",F24=""),"",E24/F24-1) -> 0.049528302
A25: 255179 | B25: =TRIM(RIGHT(Data!B25,LEN(Data!B25)-SEARCH(",",Data!B25))&" "&LEFT(Data!B25,SEARCH(",",Data!B25)-1)) -> Bill Bossler | C25: 22281 | D25: 40774 | E25: 88000 | F25: 83800 | G25: 40000 | J25: A | K25: A | L25: =(YEAR($C$3)-YEAR(C25))+(MONTH($C$3)-MONTH(C25))/12+(DAY($C$3)-DAY(C25))/365 -> 54.001142 | M25: =(YEAR($C$3)-YEAR(D25))+(MONTH($C$3)-MONTH(D25))/12+(DAY($C$3)-DAY(D25))/365 -> 3.3673516 | N25: =IF(AND(E25="",F25="",G25=""),"",AVERAGE(E25:G25)) -> 70600 | O25: =IF(OR(M25<2,E25="",F25=""),"",E25/F25-1) -> 0.050119332
A26: 258130 | B26: =TRIM(RIGHT(Data!B26,LEN(Data!B26)-SEARCH(",",Data!B26))&" "&LEFT(Data!B26,SEARCH(",",Data!B26)-1)) -> Scott G Cress | C26: 29124 | D26: 37462 | E26: 87000 | F26: 82900 | G26: 78900 | J26: A | K26: A | L26: =(YEAR($C$3)-YEAR(C26))+(MONTH($C$3)-MONTH(C26))/12+(DAY($C$3)-DAY(C26))/365 -> 35.26484 | M26: =(YEAR($C$3)-YEAR(D26))+(MONTH($C$3)-MONTH(D26))/12+(DAY($C$3)-DAY(D26))/365 -> 12.434247 | N26: =IF(AND(E26="",F26="",G26=""),"",AVERAGE(E26:G26)) -> 82933.333 | O26: =IF(OR(M26<2,E26="",F26=""),"",E26/F26-1) -> 0.049457177
A27: 286491 | B27: =TRIM(RIGHT(Data!B27,LEN(Data!B27)-SEARCH(",",Data!B27))&" "&LEFT(Data!B27,SEARCH(",",Data!B27)-1)) -> Patric Aljebreen | C27: 16018 | D27: 31071 | E27: 86000 | F27: 81900 | G27: 78000 | J27: A | K27: A | L27: =(YEAR($C$3)-YEAR(C27))+(MONTH($C$3)-MONTH(C27))/12+(DAY($C$3)-DAY(C27))/365 -> 71.147489 | M27: =(YEAR($C$3)-YEAR(D27))+(MONTH($C$3)-MONTH(D27))/12+(DAY($C$3)-DAY(D27))/365 -> 29.936986 | N27: =IF(AND(E27="",F27="",G27=""),"",AVERAGE(E27:G27)) -> 81966.667 | O27: =IF(OR(M27<2,E27="",F27=""),"",E27/F27-1) -> 0.05006105
A28: 290999 | B28: =TRIM(RIGHT(Data!B28,LEN(Data!B28)-SEARCH(",",Data!B28))&" "&LEFT(Data!B28,SEARCH(",",Data!B28)-1)) -> Diane M Dehn | C28: 25991 | D28: 41600 | E28: 85000 | F28: 2000 | J28: A | L28: =(YEAR($C$3)-YEAR(C28))+(MONTH($C$3)-MONTH(C28))/12+(DAY($C$3)-DAY(C28))/365 -> 43.845434 | M28: =(YEAR($C$3)-YEAR(D28))+(MONTH($C$3)-MONTH(D28))/12+(DAY($C$3)-DAY(D28))/365 -> 1.1091324 | N28: =IF(AND(E28="",F28="",G28=""),"",AVERAGE(E28:G28)) -> 43500 | O28: =IF(OR(M28<2,E28="",F28=""),"",E28/F28-1)
A29: 300843 | B29: =TRIM(RIGHT(Data!B29,LEN(Data!B29)-SEARCH(",",Data!B29))&" "&LEFT(Data!B29,SEARCH(",",Data!B29)-1)) -> Eric Baker | C29: 17659 | D29: 31876 | E29: 84000 | F29: 80000 | G29: 76200 | J29: A | K29: A | L29: =(YEAR($C$3)-YEAR(C29))+(MONTH($C$3)-MONTH(C29))/12+(DAY($C$3)-DAY(C29))/365 -> 66.652968 | M29: =(YEAR($C$3)-YEAR(D29))+(MONTH($C$3)-MONTH(D29))/12+(DAY($C$3)-DAY(D29))/365 -> 27.728082 | N29: =IF(AND(E29="",F29="",G29=""),"",AVERAGE(E29:G29)) -> 80066.667 | O29: =IF(OR(M29<2,E29="",F29=""),"",E29/F29-1) -> 0.05
A30: 302798 | B30: =TRIM(RIGHT(Data!B30,LEN(Data!B30)-SEARCH(",",Data!B30))&" "&LEFT(Data!B30,SEARCH(",",Data!B30)-1)) -> Ryan Asche | C30: 28924 | D30: 35009 | E30: 300000 | F30: 276000 | G30: 252000 | J30: A | K30: A | L30: =(YEAR($C$3)-YEAR(C30))+(MONTH($C$3)-MONTH(C30))/12+(DAY($C$3)-DAY(C30))/365 -> 35.808676 | M30: =(YEAR($C$3)-YEAR(D30))+(MONTH($C$3)-MONTH(D30))/12+(DAY($C$3)-DAY(D30))/365 -> 19.152968 | N30: =IF(AND(E30="",F30="",G30=""),"",AVERAGE(E30:G30)) -> 276000 | O30: =IF(OR(M30<2,E30="",F30=""),"",E30/F30-1) -> 0.086956522
A31: 310267 | B31: =TRIM(RIGHT(Data!B31,LEN(Data!B31)-SEARCH(",",Data!B31))&" "&LEFT(Data!B31,SEARCH(",",Data!B31)-1)) -> Jerome F Chen | C31: 23532 | D31: 38201 | E31: 118800 | F31: 113100 | G31: 107800 | J31: A | K31: A | L31: =(YEAR($C$3)-YEAR(C31))+(MONTH($C$3)-MONTH(C31))/12+(DAY($C$3)-DAY(C31))/365 -> 50.575114 | M31: =(YEAR($C$3)-YEAR(D31))+(MONTH($C$3)-MONTH(D31))/12+(DAY($C$3)-DAY(D31))/365 -> 10.413927 | N31: =IF(AND(E31="",F31="",G31=""),"",AVERAGE(E31:G31)) -> 113233.33 | O31: =IF(OR(M31<2,E31="",F31=""),"",E31/F31-1) -> 0.050397878
A32: 313615 | B32: =TRIM(RIGHT(Data!B32,LEN(Data!B32)-SEARCH(",",Data!B32))&" "&LEFT(Data!B32,SEARCH(",",Data!B32)-1)) -> Tracy A Gist | C32: 34187 | D32: 38175 | E32: 117600 | F32: 112000 | G32: 106700 | J32: A | K32: A | L32: =(YEAR($C$3)-YEAR(C32))+(MONTH($C$3)-MONTH(C32))/12+(DAY($C$3)-DAY(C32))/365 -> 21.402968 | M32: =(YEAR($C$3)-YEAR(D32))+(MONTH($C$3)-MONTH(D32))/12+(DAY($C$3)-DAY(D32))/365 -> 10.483562 | N32: =IF(AND(E32="",F32="",G32=""),"",AVERAGE(E32:G32)) -> 112100 | O32: =IF(OR(M32<2,E32="",F32=""),"",E32/F32-1) -> 0.05
A33: 320387 | B33: =TRIM(RIGHT(Data!B33,LEN(Data!B33)-SEARCH(",",Data!B33))&" "&LEFT(Data!B33,SEARCH(",",Data!B33)-1)) -> Jeremy Carlson | C33: 25791 | D33: 35220 | E33: 116400 | F33: 110900 | G33: 105600 | J33: A | K33: A | L33: =(YEAR($C$3)-YEAR(C33))+(MONTH($C$3)-MONTH(C33))/12+(DAY($C$3)-DAY(C33))/365 -> 44.389269 | M33: =(YEAR($C$3)-YEAR(D33))+(MONTH($C$3)-MONTH(D33))/12+(DAY($C$3)-DAY(D33))/365 -> 18.575114 | N33: =IF(AND(E33="",F33="",G33=""),"",AVERAGE(E33:G33)) -> 110966.67 | O33: =IF(OR(M33<2,E33="",F33=""),"",E33/F33-1) -> 0.049594229
A34: 340436 | B34: =TRIM(RIGHT(Data!B34,LEN(Data!B34)-SEARCH(",",Data!B34))&" "&LEFT(Data!B34,SEARCH(",",Data!B34)-1)) -> DeeAnn S Duvall | C34: 27791 | D34: 36129 | E34: 115200 | F34: 109700 | G34: 104500 | J34: A | K34: A | L34: =(YEAR($C$3)-YEAR(C34))+(MONTH($C$3)-MONTH(C34))/12+(DAY($C$3)-DAY(C34))/365 -> 38.916667 | M34: =(YEAR($C$3)-YEAR(D34))+(MONTH($C$3)-MONTH(D34))/12+(DAY($C$3)-DAY(D34))/365 -> 16.087215 | N34: =IF(AND(E34="",F34="",G34=""),"",AVERAGE(E34:G34)) -> 109800 | O34: =IF(OR(M34<2,E34="",F34=""),"",E34/F34-1) -> 0.050136737
A35: 345767 | B35: =TRIM(RIGHT(Data!B35,LEN(Data!B35)-SEARCH(",",Data!B35))&" "&LEFT(Data!B35,SEARCH(",",Data!B35)-1)) -> Susann K Gall | C35: 24217 | D35: 35067 | E35: 114000 | F35: 108600 | G35: 103400 | J35: A | K35: A | L35: =(YEAR($C$3)-YEAR(C35))+(MONTH($C$3)-MONTH(C35))/12+(DAY($C$3)-DAY(C35))/365 -> 48.697945 | M35: =(YEAR($C$3)-YEAR(D35))+(MONTH($C$3)-MONTH(D35))/12+(DAY($C$3)-DAY(D35))/365 -> 18.994521 | N35: =IF(AND(E35="",F35="",G35=""),"",AVERAGE(E35:G35)) -> 108666.67 | O35: =IF(OR(M35<2,E35="",F35=""),"",E35/F35-1) -> 0.049723757
A36: 352244 | B36: =TRIM(RIGHT(Data!B36,LEN(Data!B36)-SEARCH(",",Data!B36))&" "&LEFT(Data!B36,SEARCH(",",Data!B36)-1)) -> Susan R Harvestine | C36: 21370 | D36: 41429 | E36: 384000 | F36: 38400 | J36: A | L36: =(YEAR($C$3)-YEAR(C36))+(MONTH($C$3)-MONTH(C36))/12+(DAY($C$3)-DAY(C36))/365 -> 56.491781 | M36: =(YEAR($C$3)-YEAR(D36))+(MONTH($C$3)-MONTH(D36))/12+(DAY($C$3)-DAY(D36))/365 -> 1.5751142 | N36: =IF(AND(E36="",F36="",G36=""),"",AVERAGE(E36:G36)) -> 211200 | O36: =IF(OR(M36<2,E36="",F36=""),"",E36/F36-1)
A37: 357982 | B37: =TRIM(RIGHT(Data!B37,LEN(Data!B37)-SEARCH(",",Data!B37))&" "&LEFT(Data!B37,SEARCH(",",Data!B37)-1)) -> Richard G Harada | C37: 17820 | D37: 35562 | E37: 111600 | F37: 106300 | G37: 101200 | J37: A | K37: A | L37: =(YEAR($C$3)-YEAR(C37))+(MONTH($C$3)-MONTH(C37))/12+(DAY($C$3)-DAY(C37))/365 -> 66.214384 | M37: =(YEAR($C$3)-YEAR(D37))+(MONTH($C$3)-MONTH(D37))/12+(DAY($C$3)-DAY(D37))/365 -> 17.63653 | N37: =IF(AND(E37="",F37="",G37=""),"",AVERAGE(E37:G37)) -> 106366.67 | O37: =IF(OR(M37<2,E37="",F37=""),"",E37/F37-1) -> 0.04985889
A38: 369257 | B38: =TRIM(RIGHT(Data!B38,LEN(Data!B38)-SEARCH(",",Data!B38))&" "&LEFT(Data!B38,SEARCH(",",Data!B38)-1)) -> Robert L Guy | C38: 3651 | D38: 41274 | E38: 110400 | F38: 48000 | J38: A | K38: A | L38: =(YEAR($C$3)-YEAR(C38))+(MONTH($C$3)-MONTH(C38))/12+(DAY($C$3)-DAY(C38))/365 -> 105.00662 | M38: =(YEAR($C$3)-YEAR(D38))+(MONTH($C$3)-MONTH(D38))/12+(DAY($C$3)-DAY(D38))/365 -> 2.0011416 | N38: =IF(AND(E38="",F38="",G38=""),"",AVERAGE(E38:G38)) -> 79200 | O38: =IF(OR(M38<2,E38="",F38=""),"",E38/F38-1) -> 1.3
A39: 375122 | B39: =TRIM(RIGHT(Data!B39,LEN(Data!B39)-SEARCH(",",Data!B39))&" "&LEFT(Data!B39,SEARCH(",",Data!B39)-1)) -> Rebecca M Kampwerth | C39: 17859 | D39: 39834 | E39: 109200 | F39: 104000 | G39: 99000 | J39: A | K39: A | L39: =(YEAR($C$3)-YEAR(C39))+(MONTH($C$3)-MONTH(C39))/12+(DAY($C$3)-DAY(C39))/365 -> 66.109132 | M39: =(YEAR($C$3)-YEAR(D39))+(MONTH($C$3)-MONTH(D39))/12+(DAY($C$3)-DAY(D39))/365 -> 5.9452055 | N39: =IF(AND(E39="",F39="",G39=""),"",AVERAGE(E39:G39)) -> 104066.67 | O39: =IF(OR(M39<2,E39="",F39=""),"",E39/F39-1) -> 0.05
A40: 406300 | B40: =TRIM(RIGHT(Data!B40,LEN(Data!B40)-SEARCH(",",Data!B40))&" "&LEFT(Data!B40,SEARCH(",",Data!B40)-1)) -> Alexis Asche | C40: 1 | D40: 40273 | E40: 108000 | F40: 102900 | G40: 98000 | J40: A | K40: A | L40: =(YEAR($C$3)-YEAR(C40))+(MONTH($C$3)-MONTH(C40))/12+(DAY($C$3)-DAY(C40))/365 -> 115 | M40: =(YEAR($C$3)-YEAR(D40))+(MONTH($C$3)-MONTH(D40))/12+(DAY($C$3)-DAY(D40))/365 -> 4.7390411 | N40: =IF(AND(E40="",F40="",G40=""),"",AVERAGE(E40:G40)) -> 102966.67 | O40: =IF(OR(M40<2,E40="",F40=""),"",E40/F40-1) -> 0.049562682
A41: 422365 | B41: =TRIM(RIGHT(Data!B41,LEN(Data!B41)-SEARCH(",",Data!B41))&" "&LEFT(Data!B41,SEARCH(",",Data!B41)-1)) -> Bruce D Hitpas | C41: 21074 | D41: 40539 | E41: 106800 | F41: 101700 | G41: 96900 | J41: A | K41: A | L41: =(YEAR($C$3)-YEAR(C41))+(MONTH($C$3)-MONTH(C41))/12+(DAY($C$3)-DAY(C41))/365 -> 57.305936 | M41: =(YEAR($C$3)-YEAR(D41))+(MONTH($C$3)-MONTH(D41))/12+(DAY($C$3)-DAY(D41))/365 -> 4.0121005 | N41: =IF(AND(E41="",F41="",G41=""),"",AVERAGE(E41:G41)) -> 101800 | O41: =IF(OR(M41<2,E41="",F41=""),"",E41/F41-1) -> 0.050147493
A42: 423109 | B42: =TRIM(RIGHT(Data!B42,LEN(Data!B42)-SEARCH(",",Data!B42))&" "&LEFT(Data!B42,SEARCH(",",Data!B42)-1)) -> Casey A Jumaan | C42: 16218 | D42: 40974 | E42: 105600 | F42: 100600 | G42: 48000 | J42: A | K42: A | L42: =(YEAR($C$3)-YEAR(C42))+(MONTH($C$3)-MONTH(C42))/12+(DAY($C$3)-DAY(C42))/365 -> 70.598174 | M42: =(YEAR($C$3)-YEAR(D42))+(MONTH($C$3)-MONTH(D42))/12+(DAY($C$3)-DAY(D42))/365 -> 2.8196347 | N42: =IF(AND(E42="",F42="",G42=""),"",AVERAGE(E42:G42)) -> 84733.333 | O42: =IF(OR(M42<2,E42="",F42=""),"",E42/F42-1) -> 0.049701789
...

Sheet Data2
A1: ID | B1: Name | C1: Date of Birth | D1: Date of Hire | E1: 2014 Salary | F1: 2013 Salary | G1: 2012 Salary
A2: =Data!A6 -> 123451 | B2: =IF(LEN(Data1!B6)<30,REPT(" ",30-LEN(Data1!B6))&Data1!B6, LEFT(Data1!B6,30)) -> Gordon Lee | C2: =TEXT(Data!C6,"mm/dd/yyy") -> 10/01/1937 | D2: =TEXT(Data!D6,"mm/dd/yyy") -> 07/25/2002 | E2: =TEXT(Data!E6,"0000000") -> 0000000 | F2: =TEXT(Data!F6,"0000000") -> 0000000 | G2: =TEXT(Data!G6,"0000000") -> 0000000
A3: =Data!A7 -> 123465 | B3: =IF(LEN(Data1!B7)<30,REPT(" ",30-LEN(Data1!B7))&Data1!B7, LEFT(Data1!B7,30)) -> Bills Clinton | C3: =TEXT(Data!C7,"mm/dd/yyy") -> 01/01/1946 | D3: =TEXT(Data!D7,"mm/dd/yyy") -> 07/25/2002 | E3: =TEXT(Data!E7,"0000000") -> 0000000 | F3: =TEXT(Data!F7,"0000000") -> 0000000 | G3: =TEXT(Data!G7,"0000000") -> 0000000
A4: =Data!A8 -> 123466 | B4: =IF(LEN(Data1!B8)<30,REPT(" ",30-LEN(Data1!B8))&Data1!B8, LEFT(Data1!B8,30)) -> Hillary Jordon | C4: =TEXT(Data!C8,"mm/dd/yyy") -> 07/01/1960 | D4: =TEXT(Data!D8,"mm/dd/yyy") -> 07/25/2002 | E4: =TEXT(Data!E8,"0000000") -> 0000000 | F4: =TEXT(Data!F8,"0000000") -> 0000000 | G4: =TEXT(Data!G8,"0000000") -> 0000000
A5: =Data!A9 -> 123472 | B5: =IF(LEN(Data1!B9)<30,REPT(" ",30-LEN(Data1!B9))&Data1!B9, LEFT(Data1!B9,30)) -> Benjamin Jobs | C5: =TEXT(Data!C9,"mm/dd/yyy") -> 01/01/1954 | D5: =TEXT(Data!D9,"mm/dd/yyy") -> 07/25/2002 | E5: =TEXT(Data!E9,"0000000") -> 0000000 | F5: =TEXT(Data!F9,"0000000") -> 0000000 | G5: =TEXT(Data!G9,"0000000") -> 0000000
A6: =Data!A10 -> 123484 | B6: =IF(LEN(Data1!B10)<30,REPT(" ",30-LEN(Data1!B10))&Data1!B10, LEFT(Data1!B10,30)) -> George Larson | C6: =TEXT(Data!C10,"mm/dd/yyy") -> 11/01/1949 | D6: =TEXT(Data!D10,"mm/dd/yyy") -> 07/25/2002 | E6: =TEXT(Data!E10,"0000000") -> 0000000 | F6: =TEXT(Data!F10,"0000000") -> 0000000 | G6: =TEXT(Data!G10,"0000000") -> 0000000
A7: =Data!A11 -> 123485 | B7: =IF(LEN(Data1!B11)<30,REPT(" ",30-LEN(Data1!B11))&Data1!B11, LEFT(Data1!B11,30)) -> Chris Larson | C7: =TEXT(Data!C11,"mm/dd/yyy") -> 07/01/1944 | D7: =TEXT(Data!D11,"mm/dd/yyy") -> 07/25/2002 | E7: =TEXT(Data!E11,"0000000") -> 0000000 | F7: =TEXT(Data!F11,"0000000") -> 0000000 | G7: =TEXT(Data!G11,"0000000") -> 0000000
A8: =Data!A12 -> 123486 | B8: =IF(LEN(Data1!B12)<30,REPT(" ",30-LEN(Data1!B12))&Data1!B12, LEFT(Data1!B12,30)) -> Eric Wang | C8: =TEXT(Data!C12,"mm/dd/yyy") -> 01/01/1954 | D8: =TEXT(Data!D12,"mm/dd/yyy") -> 07/25/2002 | E8: =TEXT(Data!E12,"0000000") -> 0000000 | F8: =TEXT(Data!F12,"0000000") -> 0000000 | G8: =TEXT(Data!G12,"0000000") -> 0000000
A9: =Data!A13 -> 123491 | B9: =IF(LEN(Data1!B13)<30,REPT(" ",30-LEN(Data1!B13))&Data1!B13, LEFT(Data1!B13,30)) -> Amanda Shapiro | C9: =TEXT(Data!C13,"mm/dd/yyy") -> 10/02/1965 | D9: =TEXT(Data!D13,"mm/dd/yyy") -> 04/20/1995 | E9: =TEXT(Data!E13,"0000000") -> 0250000 | F9: =TEXT(Data!F13,"0000000") -> 0230000 | G9: =TEXT(Data!G13,"0000000") -> 0210000
A10: =Data!A14 -> 144983 | B10: =IF(LEN(Data1!B14)<30,REPT(" ",30-LEN(Data1!B14))&Data1!B14, LEFT(Data1!B14,30)) -> Adrienne Donovan | C10: =TEXT(Data!C14,"mm/dd/yyy") -> 07/26/1975 | D10: =TEXT(Data!D14,"mm/dd/yyy") -> 01/15/2004 | E10: =TEXT(Data!E14,"0000000") -> 0099000 | F10: =TEXT(Data!F14,"0000000") -> 0094300 | G10: =TEXT(Data!G14,"0000000") -> 0089800
A11: =Data!A15 -> 187427 | B11: =IF(LEN(Data1!B15)<30,REPT(" ",30-LEN(Data1!B15))&Data1!B15, LEFT(Data1!B15,30)) -> Bret Tiedens | C11: =TEXT(Data!C15,"mm/dd/yyy") -> 12/16/1957 | D11: =TEXT(Data!D15,"mm/dd/yyy") -> 12/20/2003 | E11: =TEXT(Data!E15,"0000000") -> 0098000 | F11: =TEXT(Data!F15,"0000000") -> 0093300 | G11: =TEXT(Data!G15,"0000000") -> 0088900
A12: =Data!A16 -> 189508 | B12: =IF(LEN(Data1!B16)<30,REPT(" ",30-LEN(Data1!B16))&Data1!B16, LEFT(Data1!B16,30)) -> Celina Souers | C12: =TEXT(Data!C16,"mm/dd/yyy") -> 10/05/1982 | D12: =TEXT(Data!D16,"mm/dd/yyy") -> 11/17/1995 | E12: =TEXT(Data!E16,"0000000") -> 0097000 | F12: =TEXT(Data!F16,"0000000") -> 0092400 | G12: =TEXT(Data!G16,"0000000") -> 0088000
A13: =Data!A17 -> 199741 | B13: =IF(LEN(Data1!B17)<30,REPT(" ",30-LEN(Data1!B17))&Data1!B17, LEFT(Data1!B17,30)) -> Steve Al Jaloud | C13: =TEXT(Data!C17,"mm/dd/yyy") -> 01/02/1945 | D13: =TEXT(Data!D17,"mm/dd/yyy") -> 05/14/1998 | E13: =TEXT(Data!E17,"0000000") -> 0096000 | F13: =TEXT(Data!F17,"0000000") -> 0091400 | G13: =TEXT(Data!G17,"0000000") -> 0087100
... A54: =Data!A58 -> 579268 | B54: =IF(LEN(Data1!B58)<30,REPT(" ",30-LEN(Data1!B58))&Data1!B58, LEFT(Data1!B58,30)) -> Jessika Benson | C54: =TEXT(Data!C58,"mm/dd/yyy") -> 06/14/1960 | D54: =TEXT(Data!D58,"mm/dd/yyy") -> 08/19/2011 | E54: =TEXT(Data!E58,"0000000") -> 0088000 | F54: =TEXT(Data!F58,"0000000") -> 0083800 | G54: =TEXT(Data!G58,"0000000") -> 0040000
