Workbook
Name AssetM: [1]Table!$J$3:$K$13
Name Benjamin: OFFSET('[2]Weight Watch'!$B$9,'[2]Weight Watch'!$I$3-9,2,'[2]Weight Watch'!$I$2,1)
Name Client: [1]X!$C$9
Name DateF: OFFSET('[2]Weight Watch'!$B$9,'[2]Weight Watch'!$I$3-9,0,'[2]Weight Watch'!$I$2,1)
Name DefaultB: [1]X!$F$5
Name Difference: OFFSET([3]Salman!$G$9,0,0,[3]Salman!$B$4,1)
Name Eric: OFFSET('[2]Weight Watch'!$B$9,'[2]Weight Watch'!$I$3-9,4,'[2]Weight Watch'!$I$2,1)
Name FanF: OFFSET('[2]Weight Watch'!$B$9,'[2]Weight Watch'!$I$3-9,3,'[2]Weight Watch'!$I$2,1)
Name Footer: [1]X!$C$10
Name George: OFFSET('[2]Weight Watch'!$B$9,'[2]Weight Watch'!$I$3-9,3,'[2]Weight Watch'!$I$2,1)
Name LiF: OFFSET('[2]Weight Watch'!$B$9,'[2]Weight Watch'!$I$3-9,2,'[2]Weight Watch'!$I$2,1)
Name MeasDate: OFFSET('[2]Weight Watch'!$B$9,'[2]Weight Watch'!$I$3-9,0,'[2]Weight Watch'!$I$2,1)
Name MetMRV: [4]Table!$C$21:$D$31
Name Rate: OFFSET([5]Rate!$C$4,0,0,COUNT([5]Rate!$C:$C))
Name Version: [1]X!$A$2
Name WangF: OFFSET('[2]Weight Watch'!$B$9,'[2]Weight Watch'!$I$3-9,4,'[2]Weight Watch'!$I$2,1)
Name Year: OFFSET([5]Rate!$B$4,0,0,COUNT([5]Rate!$B:$B))
Name Year158: '[6]FAS 158 Input'!$H$4

Sheet Age by Service
B2: Service Breakpoint | E2: Serv | F2: at least | G2: 0 | H2: =IF(G4="","",G4) -> 5 | I2: =IF(H4="","",H4) -> 10 | J2: =IF(I4="","",I4) -> 15 | K2: =IF(J4="","",J4) -> 20 | L2: =IF(K4="","",K4) -> 25 | M2: =IF(L4="","",L4) | N2: =IF(M4="","",M4) | O2: =IF(N4="","",N4) | ... R2: =IF(Q4="","",Q4)
F3: but
F4: less than | G4: 5 | H4: =G4+5 -> 10 | I4: =H4+5 -> 15 | J4: =I4+5 -> 20 | K4: =J4+5 -> 25
B6: Age Breakpoint | F6: Age by Service Distribution with Total Salaries for Actives
B7: Age is
B8: at least | C8: but | D8: less than | F8: Age/Serv | G8: =IF(G2="","",IF(G2=0,"<"&G4,IF(G4="",G2&" <=",G2&" - "&G4))) -> <5 | H8: =IF(H2="","",IF(H2=0,"<"&H4,IF(H4="",H2&" <=",H2&" - "&H4))) -> 5 - 10 | I8: =IF(I2="","",IF(I2=0,"<"&I4,IF(I4="",I2&" <=",I2&" - "&I4))) -> 10 - 15 | J8: =IF(J2="","",IF(J2=0,"<"&J4,IF(J4="",J2&" <=",J2&" - "&J4))) -> 15 - 20 | K8: =IF(K2="","",IF(K2=0,"<"&K4,IF(K4="",K2&" <=",K2&" - "&K4))) -> 20 - 25 | L8: =IF(L2="","",IF(L2=0,"<"&L4,IF(L4="",L2&" <=",L2&" - "&L4))) -> 25 <= | M8: =IF(M2="","",IF(M2=0,"<"&M4,IF(M4="",M2&" <=",M2&" - "&M4))) | N8: =IF(N2="","",IF(N2=0,"<"&N4,IF(N4="",N2&" <=",N2&" - "&N4))) | ... Q8: =IF(Q2="","",IF(Q2=0,"<"&Q4,IF(Q4="",Q2&" <=",Q2&" - "&Q4))) | R8: Total
B9: 0 | D9: 20 | F9: =IF(B9="","",IF(B9=0,"<"&D9,IF(D9="",B9&" <=",B9&" - "&D9))) -> <20 | G9: =IF(OR(G$8="",$F9=""),"",COUNTIFS(EeData!$G:$G,"A",EeData!$E:$E,">="&$B9,EeData!$E:$E,"<" & IF($D9="",200,$D9),EeData!$F:$F,">="&G$2,EeData!$F:$F,"<" & IF(G$4="",100,G$4))) -> 0 | H9: =IF(OR(H$8="",$F9=""),"",COUNTIFS(EeData!$G:$G,"A",EeData!$E:$E,">="&$B9,EeData!$E:$E,"<" & IF($D9="",200,$D9),EeData!$F:$F,">="&H$2,EeData!$F:$F,"<" & IF(H$4="",100,H$4))) -> 0 | I9: =IF(OR(I$8="",$F9=""),"",COUNTIFS(EeData!$G:$G,"A",EeData!$E:$E,">="&$B9,EeData!$E:$E,"<" & IF($D9="",200,$D9),EeData!$F:$F,">="&I$2,EeData!$F:$F,"<" & IF(I$4="",100,I$4))) -> 0 | J9: =IF(OR(J$8="",$F9=""),"",COUNTIFS(EeData!$G:$G,"A",EeData!$E:$E,">="&$B9,EeData!$E:$E,"<" & IF($D9="",200,$D9),EeData!$F:$F,">="&J$2,EeData!$F:$F,"<" & IF(J$4="",100,J$4))) -> 0 | K9: =IF(OR(K$8="",$F9=""),"",COUNTIFS(EeData!$G:$G,"A",EeData!$E:$E,">="&$B9,EeData!$E:$E,"<" & IF($D9="",200,$D9),EeData!$F:$F,">="&K$2,EeData!$F:$F,"<" & IF(K$4="",100,K$4))) -> 0 | L9: =IF(OR(L$8="",$F9=""),"",COUNTIFS(EeData!$G:$G,"A",EeData!$E:$E,">="&$B9,EeData!$E:$E,"<" & IF($D9="",200,$D9),EeData!$F:$F,">="&L$2,EeData!$F:$F,"<" & IF(L$4="",100,L$4))) -> 0 | M9: =IF(OR(M$8="",$F9=""),"",COUNTIFS(EeData!$G:$G,"A",EeData!$E:$E,">="&$B9,EeData!$E:$E,"<" & IF($D9="",200,$D9),EeData!$F:$F,">="&M$2,EeData!$F:$F,"<" & IF(M$4="",100,M$4))) | N9: =IF(OR(N$8="",$F9=""),"",COUNTIFS(EeData!$G:$G,"A",EeData!$E:$E,">="&$B9,EeData!$E:$E,"<" & IF($D9="",200,$D9),EeData!$F:$F,">="&N$2,EeData!$F:$F,"<" & IF(N$4="",100,N$4))) | ... Q9: =IF(OR(Q$8="",$F9=""),"",COUNTIFS(EeData!$G:$G,"A",EeData!$E:$E,">="&$B9,EeData!$E:$E,"<" & IF($D9="",200,$D9),EeData!$F:$F,">="&Q$2,EeData!$F:$F,"<" & IF(Q$4="",100,Q$4))) | R9: =SUM(G9:Q9) -> 0
B10: =IF(D9="","",D9) -> 20 | D10: =D9+10 -> 30 | F10: =IF(B10="","",IF(B10=0,"<"&D10,IF(D10="",B10&" <=",B10&" - "&D10))) -> 20 - 30 | G10: =IF(OR(G$8="",$F10=""),"",COUNTIFS(EeData!$G:$G,"A",EeData!$E:$E,">="&$B10,EeData!$E:$E,"<" & IF($D10="",200,$D10),EeData!$F:$F,">="&G$2,EeData!$F:$F,"<" & IF(G$4="",100,G$4))) -> 1 | H10: =IF(OR(H$8="",$F10=""),"",COUNTIFS(EeData!$G:$G,"A",EeData!$E:$E,">="&$B10,EeData!$E:$E,"<" & IF($D10="",200,$D10),EeData!$F:$F,">="&H$2,EeData!$F:$F,"<" & IF(H$4="",100,H$4))) -> 1 | I10: =IF(OR(I$8="",$F10=""),"",COUNTIFS(EeData!$G:$G,"A",EeData!$E:$E,">="&$B10,EeData!$E:$E,"<" & IF($D10="",200,$D10),EeData!$F:$F,">="&I$2,EeData!$F:$F,"<" & IF(I$4="",100,I$4))) -> 1 | J10: =IF(OR(J$8="",$F10=""),"",COUNTIFS(EeData!$G:$G,"A",EeData!$E:$E,">="&$B10,EeData!$E:$E,"<" & IF($D10="",200,$D10),EeData!$F:$F,">="&J$2,EeData!$F:$F,"<" & IF(J$4="",100,J$4))) -> 0 | K10: =IF(OR(K$8="",$F10=""),"",COUNTIFS(EeData!$G:$G,"A",EeData!$E:$E,">="&$B10,EeData!$E:$E,"<" & IF($D10="",200,$D10),EeData!$F:$F,">="&K$2,EeData!$F:$F,"<" & IF(K$4="",100,K$4))) -> 0 | L10: =IF(OR(L$8="",$F10=""),"",COUNTIFS(EeData!$G:$G,"A",EeData!$E:$E,">="&$B10,EeData!$E:$E,"<" & IF($D10="",200,$D10),EeData!$F:$F,">="&L$2,EeData!$F:$F,"<" & IF(L$4="",100,L$4))) -> 0 | M10: =IF(OR(M$8="",$F10=""),"",COUNTIFS(EeData!$G:$G,"A",EeData!$E:$E,">="&$B10,EeData!$E:$E,"<" & IF($D10="",200,$D10),EeData!$F:$F,">="&M$2,EeData!$F:$F,"<" & IF(M$4="",100,M$4))) | N10: =IF(OR(N$8="",$F10=""),"",COUNTIFS(EeData!$G:$G,"A",EeData!$E:$E,">="&$B10,EeData!$E:$E,"<" & IF($D10="",200,$D10),EeData!$F:$F,">="&N$2,EeData!$F:$F,"<" & IF(N$4="",100,N$4))) | ... Q10: =IF(OR(Q$8="",$F10=""),"",COUNTIFS(EeData!$G:$G,"A",EeData!$E:$E,">="&$B10,EeData!$E:$E,"<" & IF($D10="",200,$D10),EeData!$F:$F,">="&Q$2,EeData!$F:$F,"<" & IF(Q$4="",100,Q$4))) | R10: =SUM(G10:Q10) -> 3
B11: =IF(D10="","",D10) -> 30 | D11: =D10+10 -> 40 | F11: =IF(B11="","",IF(B11=0,"<"&D11,IF(D11="",B11&" <=",B11&" - "&D11))) -> 30 - 40 | G11: =IF(OR(G$8="",$F11=""),"",COUNTIFS(EeData!$G:$G,"A",EeData!$E:$E,">="&$B11,EeData!$E:$E,"<" & IF($D11="",200,$D11),EeData!$F:$F,">="&G$2,EeData!$F:$F,"<" & IF(G$4="",100,G$4))) -> 4 | H11: =IF(OR(H$8="",$F11=""),"",COUNTIFS(EeData!$G:$G,"A",EeData!$E:$E,">="&$B11,EeData!$E:$E,"<" & IF($D11="",200,$D11),EeData!$F:$F,">="&H$2,EeData!$F:$F,"<" & IF(H$4="",100,H$4))) -> 4 | I11: =IF(OR(I$8="",$F11=""),"",COUNTIFS(EeData!$G:$G,"A",EeData!$E:$E,">="&$B11,EeData!$E:$E,"<" & IF($D11="",200,$D11),EeData!$F:$F,">="&I$2,EeData!$F:$F,"<" & IF(I$4="",100,I$4))) -> 3 | J11: =IF(OR(J$8="",$F11=""),"",COUNTIFS(EeData!$G:$G,"A",EeData!$E:$E,">="&$B11,EeData!$E:$E,"<" & IF($D11="",200,$D11),EeData!$F:$F,">="&J$2,EeData!$F:$F,"<" & IF(J$4="",100,J$4))) -> 0 | K11: =IF(OR(K$8="",$F11=""),"",COUNTIFS(EeData!$G:$G,"A",EeData!$E:$E,">="&$B11,EeData!$E:$E,"<" & IF($D11="",200,$D11),EeData!$F:$F,">="&K$2,EeData!$F:$F,"<" & IF(K$4="",100,K$4))) -> 0 | L11: =IF(OR(L$8="",$F11=""),"",COUNTIFS(EeData!$G:$G,"A",EeData!$E:$E,">="&$B11,EeData!$E:$E,"<" & IF($D11="",200,$D11),EeData!$F:$F,">="&L$2,EeData!$F:$F,"<" & IF(L$4="",100,L$4))) -> 0 | M11: =IF(OR(M$8="",$F11=""),"",COUNTIFS(EeData!$G:$G,"A",EeData!$E:$E,">="&$B11,EeData!$E:$E,"<" & IF($D11="",200,$D11),EeData!$F:$F,">="&M$2,EeData!$F:$F,"<" & IF(M$4="",100,M$4))) | N11: =IF(OR(N$8="",$F11=""),"",COUNTIFS(EeData!$G:$G,"A",EeData!$E:$E,">="&$B11,EeData!$E:$E,"<" & IF($D11="",200,$D11),EeData!$F:$F,">="&N$2,EeData!$F:$F,"<" & IF(N$4="",100,N$4))) | ... Q11: =IF(OR(Q$8="",$F11=""),"",COUNTIFS(EeData!$G:$G,"A",EeData!$E:$E,">="&$B11,EeData!$E:$E,"<" & IF($D11="",200,$D11),EeData!$F:$F,">="&Q$2,EeData!$F:$F,"<" & IF(Q$4="",100,Q$4))) | R11: =SUM(G11:Q11) -> 11
B12: =IF(D11="","",D11) -> 40 | D12: =D11+10 -> 50 | F12: =IF(B12="","",IF(B12=0,"<"&D12,IF(D12="",B12&" <=",B12&" - "&D12))) -> 40 - 50 | G12: =IF(OR(G$8="",$F12=""),"",COUNTIFS(EeData!$G:$G,"A",EeData!$E:$E,">="&$B12,EeData!$E:$E,"<" & IF($D12="",200,$D12),EeData!$F:$F,">="&G$2,EeData!$F:$F,"<" & IF(G$4="",100,G$4))) -> 2 | H12: =IF(OR(H$8="",$F12=""),"",COUNTIFS(EeData!$G:$G,"A",EeData!$E:$E,">="&$B12,EeData!$E:$E,"<" & IF($D12="",200,$D12),EeData!$F:$F,">="&H$2,EeData!$F:$F,"<" & IF(H$4="",100,H$4))) -> 2 | I12: =IF(OR(I$8="",$F12=""),"",COUNTIFS(EeData!$G:$G,"A",EeData!$E:$E,">="&$B12,EeData!$E:$E,"<" & IF($D12="",200,$D12),EeData!$F:$F,">="&I$2,EeData!$F:$F,"<" & IF(I$4="",100,I$4))) -> 5 | J12: =IF(OR(J$8="",$F12=""),"",COUNTIFS(EeData!$G:$G,"A",EeData!$E:$E,">="&$B12,EeData!$E:$E,"<" & IF($D12="",200,$D12),EeData!$F:$F,">="&J$2,EeData!$F:$F,"<" & IF(J$4="",100,J$4))) -> 3 | K12: =IF(OR(K$8="",$F12=""),"",COUNTIFS(EeData!$G:$G,"A",EeData!$E:$E,">="&$B12,EeData!$E:$E,"<" & IF($D12="",200,$D12),EeData!$F:$F,">="&K$2,EeData!$F:$F,"<" & IF(K$4="",100,K$4))) -> 1 | L12: =IF(OR(L$8="",$F12=""),"",COUNTIFS(EeData!$G:$G,"A",EeData!$E:$E,">="&$B12,EeData!$E:$E,"<" & IF($D12="",200,$D12),EeData!$F:$F,">="&L$2,EeData!$F:$F,"<" & IF(L$4="",100,L$4))) -> 0 | M12: =IF(OR(M$8="",$F12=""),"",COUNTIFS(EeData!$G:$G,"A",EeData!$E:$E,">="&$B12,EeData!$E:$E,"<" & IF($D12="",200,$D12),EeData!$F:$F,">="&M$2,EeData!$F:$F,"<" & IF(M$4="",100,M$4))) | N12: =IF(OR(N$8="",$F12=""),"",COUNTIFS(EeData!$G:$G,"A",EeData!$E:$E,">="&$B12,EeData!$E:$E,"<" & IF($D12="",200,$D12),EeData!$F:$F,">="&N$2,EeData!$F:$F,"<" & IF(N$4="",100,N$4))) | ... Q12: =IF(OR(Q$8="",$F12=""),"",COUNTIFS(EeData!$G:$G,"A",EeData!$E:$E,">="&$B12,EeData!$E:$E,"<" & IF($D12="",200,$D12),EeData!$F:$F,">="&Q$2,EeData!$F:$F,"<" & IF(Q$4="",100,Q$4))) | R12: =SUM(G12:Q12) -> 13
B13: =IF(D12="","",D12) -> 50 | D13: =D12+10 -> 60 | F13: =IF(B13="","",IF(B13=0,"<"&D13,IF(D13="",B13&" <=",B13&" - "&D13))) -> 50 - 60 | G13: =IF(OR(G$8="",$F13=""),"",COUNTIFS(EeData!$G:$G,"A",EeData!$E:$E,">="&$B13,EeData!$E:$E,"<" & IF($D13="",200,$D13),EeData!$F:$F,">="&G$2,EeData!$F:$F,"<" & IF(G$4="",100,G$4))) -> 0 | H13: =IF(OR(H$8="",$F13=""),"",COUNTIFS(EeData!$G:$G,"A",EeData!$E:$E,">="&$B13,EeData!$E:$E,"<" & IF($D13="",200,$D13),EeData!$F:$F,">="&H$2,EeData!$F:$F,"<" & IF(H$4="",100,H$4))) -> 4 | I13: =IF(OR(I$8="",$F13=""),"",COUNTIFS(EeData!$G:$G,"A",EeData!$E:$E,">="&$B13,EeData!$E:$E,"<" & IF($D13="",200,$D13),EeData!$F:$F,">="&I$2,EeData!$F:$F,"<" & IF(I$4="",100,I$4))) -> 2 | J13: =IF(OR(J$8="",$F13=""),"",COUNTIFS(EeData!$G:$G,"A",EeData!$E:$E,">="&$B13,EeData!$E:$E,"<" & IF($D13="",200,$D13),EeData!$F:$F,">="&J$2,EeData!$F:$F,"<" & IF(J$4="",100,J$4))) -> 0 | K13: =IF(OR(K$8="",$F13=""),"",COUNTIFS(EeData!$G:$G,"A",EeData!$E:$E,">="&$B13,EeData!$E:$E,"<" & IF($D13="",200,$D13),EeData!$F:$F,">="&K$2,EeData!$F:$F,"<" & IF(K$4="",100,K$4))) -> 2 | L13: =IF(OR(L$8="",$F13=""),"",COUNTIFS(EeData!$G:$G,"A",EeData!$E:$E,">="&$B13,EeData!$E:$E,"<" & IF($D13="",200,$D13),EeData!$F:$F,">="&L$2,EeData!$F:$F,"<" & IF(L$4="",100,L$4))) -> 1 | M13: =IF(OR(M$8="",$F13=""),"",COUNTIFS(EeData!$G:$G,"A",EeData!$E:$E,">="&$B13,EeData!$E:$E,"<" & IF($D13="",200,$D13),EeData!$F:$F,">="&M$2,EeData!$F:$F,"<" & IF(M$4="",100,M$4))) | N13: =IF(OR(N$8="",$F13=""),"",COUNTIFS(EeData!$G:$G,"A",EeData!$E:$E,">="&$B13,EeData!$E:$E,"<" & IF($D13="",200,$D13),EeData!$F:$F,">="&N$2,EeData!$F:$F,"<" & IF(N$4="",100,N$4))) | ... Q13: =IF(OR(Q$8="",$F13=""),"",COUNTIFS(EeData!$G:$G,"A",EeData!$E:$E,">="&$B13,EeData!$E:$E,"<" & IF($D13="",200,$D13),EeData!$F:$F,">="&Q$2,EeData!$F:$F,"<" & IF(Q$4="",100,Q$4))) | R13: =SUM(G13:Q13) -> 9
B14: =IF(D13="","",D13) -> 60 | F14: =IF(B14="","",IF(B14=0,"<"&D14,IF(D14="",B14&" <=",B14&" - "&D14))) -> 60 <= | G14: =IF(OR(G$8="",$F14=""),"",COUNTIFS(EeData!$G:$G,"A",EeData!$E:$E,">="&$B14,EeData!$E:$E,"<" & IF($D14="",200,$D14),EeData!$F:$F,">="&G$2,EeData!$F:$F,"<" & IF(G$4="",100,G$4))) -> 0 | H14: =IF(OR(H$8="",$F14=""),"",COUNTIFS(EeData!$G:$G,"A",EeData!$E:$E,">="&$B14,EeData!$E:$E,"<" & IF($D14="",200,$D14),EeData!$F:$F,">="&H$2,EeData!$F:$F,"<" & IF(H$4="",100,H$4))) -> 0 | I14: =IF(OR(I$8="",$F14=""),"",COUNTIFS(EeData!$G:$G,"A",EeData!$E:$E,">="&$B14,EeData!$E:$E,"<" & IF($D14="",200,$D14),EeData!$F:$F,">="&I$2,EeData!$F:$F,"<" & IF(I$4="",100,I$4))) -> 0 | J14: =IF(OR(J$8="",$F14=""),"",COUNTIFS(EeData!$G:$G,"A",EeData!$E:$E,">="&$B14,EeData!$E:$E,"<" & IF($D14="",200,$D14),EeData!$F:$F,">="&J$2,EeData!$F:$F,"<" & IF(J$4="",100,J$4))) -> 0 | K14: =IF(OR(K$8="",$F14=""),"",COUNTIFS(EeData!$G:$G,"A",EeData!$E:$E,">="&$B14,EeData!$E:$E,"<" & IF($D14="",200,$D14),EeData!$F:$F,">="&K$2,EeData!$F:$F,"<" & IF(K$4="",100,K$4))) -> 0 | L14: =IF(OR(L$8="",$F14=""),"",COUNTIFS(EeData!$G:$G,"A",EeData!$E:$E,">="&$B14,EeData!$E:$E,"<" & IF($D14="",200,$D14),EeData!$F:$F,">="&L$2,EeData!$F:$F,"<" & IF(L$4="",100,L$4))) -> 1 | M14: =IF(OR(M$8="",$F14=""),"",COUNTIFS(EeData!$G:$G,"A",EeData!$E:$E,">="&$B14,EeData!$E:$E,"<" & IF($D14="",200,$D14),EeData!$F:$F,">="&M$2,EeData!$F:$F,"<" & IF(M$4="",100,M$4))) | N14: =IF(OR(N$8="",$F14=""),"",COUNTIFS(EeData!$G:$G,"A",EeData!$E:$E,">="&$B14,EeData!$E:$E,"<" & IF($D14="",200,$D14),EeData!$F:$F,">="&N$2,EeData!$F:$F,"<" & IF(N$4="",100,N$4))) | ... Q14: =IF(OR(Q$8="",$F14=""),"",COUNTIFS(EeData!$G:$G,"A",EeData!$E:$E,">="&$B14,EeData!$E:$E,"<" & IF($D14="",200,$D14),EeData!$F:$F,">="&Q$2,EeData!$F:$F,"<" & IF(Q$4="",100,Q$4))) | R14: =SUM(G14:Q14) -> 1
B15: =IF(D14="","",D14) | F15: =IF(B15="","",IF(B15=0,"<"&D15,IF(D15="",B15&" <=",B15&" - "&D15))) | G15: =IF(OR(G$8="",$F15=""),"",COUNTIFS(EeData!$G:$G,"A",EeData!$E:$E,">="&$B15,EeData!$E:$E,"<" & IF($D15="",200,$D15),EeData!$F:$F,">="&G$2,EeData!$F:$F,"<" & IF(G$4="",100,G$4))) | H15: =IF(OR(H$8="",$F15=""),"",COUNTIFS(EeData!$G:$G,"A",EeData!$E:$E,">="&$B15,EeData!$E:$E,"<" & IF($D15="",200,$D15),EeData!$F:$F,">="&H$2,EeData!$F:$F,"<" & IF(H$4="",100,H$4))) | I15: =IF(OR(I$8="",$F15=""),"",COUNTIFS(EeData!$G:$G,"A",EeData!$E:$E,">="&$B15,EeData!$E:$E,"<" & IF($D15="",200,$D15),EeData!$F:$F,">="&I$2,EeData!$F:$F,"<" & IF(I$4="",100,I$4))) | J15: =IF(OR(J$8="",$F15=""),"",COUNTIFS(EeData!$G:$G,"A",EeData!$E:$E,">="&$B15,EeData!$E:$E,"<" & IF($D15="",200,$D15),EeData!$F:$F,">="&J$2,EeData!$F:$F,"<" & IF(J$4="",100,J$4))) | K15: =IF(OR(K$8="",$F15=""),"",COUNTIFS(EeData!$G:$G,"A",EeData!$E:$E,">="&$B15,EeData!$E:$E,"<" & IF($D15="",200,$D15),EeData!$F:$F,">="&K$2,EeData!$F:$F,"<" & IF(K$4="",100,K$4))) | L15: =IF(OR(L$8="",$F15=""),"",COUNTIFS(EeData!$G:$G,"A",EeData!$E:$E,">="&$B15,EeData!$E:$E,"<" & IF($D15="",200,$D15),EeData!$F:$F,">="&L$2,EeData!$F:$F,"<" & IF(L$4="",100,L$4))) | M15: =IF(OR(M$8="",$F15=""),"",COUNTIFS(EeData!$G:$G,"A",EeData!$E:$E,">="&$B15,EeData!$E:$E,"<" & IF($D15="",200,$D15),EeData!$F:$F,">="&M$2,EeData!$F:$F,"<" & IF(M$4="",100,M$4))) | N15: =IF(OR(N$8="",$F15=""),"",COUNTIFS(EeData!$G:$G,"A",EeData!$E:$E,">="&$B15,EeData!$E:$E,"<" & IF($D15="",200,$D15),EeData!$F:$F,">="&N$2,EeData!$F:$F,"<" & IF(N$4="",100,N$4))) | ... Q15: =IF(OR(Q$8="",$F15=""),"",COUNTIFS(EeData!$G:$G,"A",EeData!$E:$E,">="&$B15,EeData!$E:$E,"<" & IF($D15="",200,$D15),EeData!$F:$F,">="&Q$2,EeData!$F:$F,"<" & IF(Q$4="",100,Q$4))) | R15: =SUM(G15:Q15) -> 0
B16: =IF(D15="","",D15) | F16: =IF(B16="","",IF(B16=0,"<"&D16,IF(D16="",B16&" <=",B16&" - "&D16))) | G16: =IF(OR(G$8="",$F16=""),"",COUNTIFS(EeData!$G:$G,"A",EeData!$E:$E,">="&$B16,EeData!$E:$E,"<" & IF($D16="",200,$D16),EeData!$F:$F,">="&G$2,EeData!$F:$F,"<" & IF(G$4="",100,G$4))) | H16: =IF(OR(H$8="",$F16=""),"",COUNTIFS(EeData!$G:$G,"A",EeData!$E:$E,">="&$B16,EeData!$E:$E,"<" & IF($D16="",200,$D16),EeData!$F:$F,">="&H$2,EeData!$F:$F,"<" & IF(H$4="",100,H$4))) | I16: =IF(OR(I$8="",$F16=""),"",COUNTIFS(EeData!$G:$G,"A",EeData!$E:$E,">="&$B16,EeData!$E:$E,"<" & IF($D16="",200,$D16),EeData!$F:$F,">="&I$2,EeData!$F:$F,"<" & IF(I$4="",100,I$4))) | J16: =IF(OR(J$8="",$F16=""),"",COUNTIFS(EeData!$G:$G,"A",EeData!$E:$E,">="&$B16,EeData!$E:$E,"<" & IF($D16="",200,$D16),EeData!$F:$F,">="&J$2,EeData!$F:$F,"<" & IF(J$4="",100,J$4))) | K16: =IF(OR(K$8="",$F16=""),"",COUNTIFS(EeData!$G:$G,"A",EeData!$E:$E,">="&$B16,EeData!$E:$E,"<" & IF($D16="",200,$D16),EeData!$F:$F,">="&K$2,EeData!$F:$F,"<" & IF(K$4="",100,K$4))) | L16: =IF(OR(L$8="",$F16=""),"",COUNTIFS(EeData!$G:$G,"A",EeData!$E:$E,">="&$B16,EeData!$E:$E,"<" & IF($D16="",200,$D16),EeData!$F:$F,">="&L$2,EeData!$F:$F,"<" & IF(L$4="",100,L$4))) | M16: =IF(OR(M$8="",$F16=""),"",COUNTIFS(EeData!$G:$G,"A",EeData!$E:$E,">="&$B16,EeData!$E:$E,"<" & IF($D16="",200,$D16),EeData!$F:$F,">="&M$2,EeData!$F:$F,"<" & IF(M$4="",100,M$4))) | N16: =IF(OR(N$8="",$F16=""),"",COUNTIFS(EeData!$G:$G,"A",EeData!$E:$E,">="&$B16,EeData!$E:$E,"<" & IF($D16="",200,$D16),EeData!$F:$F,">="&N$2,EeData!$F:$F,"<" & IF(N$4="",100,N$4))) | ... Q16: =IF(OR(Q$8="",$F16=""),"",COUNTIFS(EeData!$G:$G,"A",EeData!$E:$E,">="&$B16,EeData!$E:$E,"<" & IF($D16="",200,$D16),EeData!$F:$F,">="&Q$2,EeData!$F:$F,"<" & IF(Q$4="",100,Q$4))) | R16: =SUM(G16:Q16) -> 0
B17: =IF(D16="","",D16) | F17: =IF(B17="","",IF(B17=0,"<"&D17,IF(D17="",B17&" <=",B17&" - "&D17))) | G17: =IF(OR(G$8="",$F17=""),"",COUNTIFS(EeData!$G:$G,"A",EeData!$E:$E,">="&$B17,EeData!$E:$E,"<" & IF($D17="",200,$D17),EeData!$F:$F,">="&G$2,EeData!$F:$F,"<" & IF(G$4="",100,G$4))) | H17: =IF(OR(H$8="",$F17=""),"",COUNTIFS(EeData!$G:$G,"A",EeData!$E:$E,">="&$B17,EeData!$E:$E,"<" & IF($D17="",200,$D17),EeData!$F:$F,">="&H$2,EeData!$F:$F,"<" & IF(H$4="",100,H$4))) | I17: =IF(OR(I$8="",$F17=""),"",COUNTIFS(EeData!$G:$G,"A",EeData!$E:$E,">="&$B17,EeData!$E:$E,"<" & IF($D17="",200,$D17),EeData!$F:$F,">="&I$2,EeData!$F:$F,"<" & IF(I$4="",100,I$4))) | J17: =IF(OR(J$8="",$F17=""),"",COUNTIFS(EeData!$G:$G,"A",EeData!$E:$E,">="&$B17,EeData!$E:$E,"<" & IF($D17="",200,$D17),EeData!$F:$F,">="&J$2,EeData!$F:$F,"<" & IF(J$4="",100,J$4))) | K17: =IF(OR(K$8="",$F17=""),"",COUNTIFS(EeData!$G:$G,"A",EeData!$E:$E,">="&$B17,EeData!$E:$E,"<" & IF($D17="",200,$D17),EeData!$F:$F,">="&K$2,EeData!$F:$F,"<" & IF(K$4="",100,K$4))) | L17: =IF(OR(L$8="",$F17=""),"",COUNTIFS(EeData!$G:$G,"A",EeData!$E:$E,">="&$B17,EeData!$E:$E,"<" & IF($D17="",200,$D17),EeData!$F:$F,">="&L$2,EeData!$F:$F,"<" & IF(L$4="",100,L$4))) | M17: =IF(OR(M$8="",$F17=""),"",COUNTIFS(EeData!$G:$G,"A",EeData!$E:$E,">="&$B17,EeData!$E:$E,"<" & IF($D17="",200,$D17),EeData!$F:$F,">="&M$2,EeData!$F:$F,"<" & IF(M$4="",100,M$4))) | N17: =IF(OR(N$8="",$F17=""),"",COUNTIFS(EeData!$G:$G,"A",EeData!$E:$E,">="&$B17,EeData!$E:$E,"<" & IF($D17="",200,$D17),EeData!$F:$F,">="&N$2,EeData!$F:$F,"<" & IF(N$4="",100,N$4))) | ... Q17: =IF(OR(Q$8="",$F17=""),"",COUNTIFS(EeData!$G:$G,"A",EeData!$E:$E,">="&$B17,EeData!$E:$E,"<" & IF($D17="",200,$D17),EeData!$F:$F,">="&Q$2,EeData!$F:$F,"<" & IF(Q$4="",100,Q$4))) | R17: =SUM(G17:Q17) -> 0
B18: =IF(D17="","",D17) | F18: =IF(B18="","",IF(B18=0,"<"&D18,IF(D18="",B18&" <=",B18&" - "&D18))) | G18: =IF(OR(G$8="",$F18=""),"",COUNTIFS(EeData!$G:$G,"A",EeData!$E:$E,">="&$B18,EeData!$E:$E,"<" & IF($D18="",200,$D18),EeData!$F:$F,">="&G$2,EeData!$F:$F,"<" & IF(G$4="",100,G$4))) | H18: =IF(OR(H$8="",$F18=""),"",COUNTIFS(EeData!$G:$G,"A",EeData!$E:$E,">="&$B18,EeData!$E:$E,"<" & IF($D18="",200,$D18),EeData!$F:$F,">="&H$2,EeData!$F:$F,"<" & IF(H$4="",100,H$4))) | I18: =IF(OR(I$8="",$F18=""),"",COUNTIFS(EeData!$G:$G,"A",EeData!$E:$E,">="&$B18,EeData!$E:$E,"<" & IF($D18="",200,$D18),EeData!$F:$F,">="&I$2,EeData!$F:$F,"<" & IF(I$4="",100,I$4))) | J18: =IF(OR(J$8="",$F18=""),"",COUNTIFS(EeData!$G:$G,"A",EeData!$E:$E,">="&$B18,EeData!$E:$E,"<" & IF($D18="",200,$D18),EeData!$F:$F,">="&J$2,EeData!$F:$F,"<" & IF(J$4="",100,J$4))) | K18: =IF(OR(K$8="",$F18=""),"",COUNTIFS(EeData!$G:$G,"A",EeData!$E:$E,">="&$B18,EeData!$E:$E,"<" & IF($D18="",200,$D18),EeData!$F:$F,">="&K$2,EeData!$F:$F,"<" & IF(K$4="",100,K$4))) | L18: =IF(OR(L$8="",$F18=""),"",COUNTIFS(EeData!$G:$G,"A",EeData!$E:$E,">="&$B18,EeData!$E:$E,"<" & IF($D18="",200,$D18),EeData!$F:$F,">="&L$2,EeData!$F:$F,"<" & IF(L$4="",100,L$4))) | M18: =IF(OR(M$8="",$F18=""),"",COUNTIFS(EeData!$G:$G,"A",EeData!$E:$E,">="&$B18,EeData!$E:$E,"<" & IF($D18="",200,$D18),EeData!$F:$F,">="&M$2,EeData!$F:$F,"<" & IF(M$4="",100,M$4))) | N18: =IF(OR(N$8="",$F18=""),"",COUNTIFS(EeData!$G:$G,"A",EeData!$E:$E,">="&$B18,EeData!$E:$E,"<" & IF($D18="",200,$D18),EeData!$F:$F,">="&N$2,EeData!$F:$F,"<" & IF(N$4="",100,N$4))) | ... Q18: =IF(OR(Q$8="",$F18=""),"",COUNTIFS(EeData!$G:$G,"A",EeData!$E:$E,">="&$B18,EeData!$E:$E,"<" & IF($D18="",200,$D18),EeData!$F:$F,">="&Q$2,EeData!$F:$F,"<" & IF(Q$4="",100,Q$4))) | R18: =SUM(G18:Q18) -> 0
B19: =IF(D18="","",D18) | F19: =IF(B19="","",IF(B19=0,"<"&D19,IF(D19="",B19&" <=",B19&" - "&D19))) | G19: =IF(OR(G$8="",$F19=""),"",COUNTIFS(EeData!$G:$G,"A",EeData!$E:$E,">="&$B19,EeData!$E:$E,"<" & IF($D19="",200,$D19),EeData!$F:$F,">="&G$2,EeData!$F:$F,"<" & IF(G$4="",100,G$4))) | H19: =IF(OR(H$8="",$F19=""),"",COUNTIFS(EeData!$G:$G,"A",EeData!$E:$E,">="&$B19,EeData!$E:$E,"<" & IF($D19="",200,$D19),EeData!$F:$F,">="&H$2,EeData!$F:$F,"<" & IF(H$4="",100,H$4))) | I19: =IF(OR(I$8="",$F19=""),"",COUNTIFS(EeData!$G:$G,"A",EeData!$E:$E,">="&$B19,EeData!$E:$E,"<" & IF($D19="",200,$D19),EeData!$F:$F,">="&I$2,EeData!$F:$F,"<" & IF(I$4="",100,I$4))) | J19: =IF(OR(J$8="",$F19=""),"",COUNTIFS(EeData!$G:$G,"A",EeData!$E:$E,">="&$B19,EeData!$E:$E,"<" & IF($D19="",200,$D19),EeData!$F:$F,">="&J$2,EeData!$F:$F,"<" & IF(J$4="",100,J$4))) | K19: =IF(OR(K$8="",$F19=""),"",COUNTIFS(EeData!$G:$G,"A",EeData!$E:$E,">="&$B19,EeData!$E:$E,"<" & IF($D19="",200,$D19),EeData!$F:$F,">="&K$2,EeData!$F:$F,"<" & IF(K$4="",100,K$4))) | L19: =IF(OR(L$8="",$F19=""),"",COUNTIFS(EeData!$G:$G,"A",EeData!$E:$E,">="&$B19,EeData!$E:$E,"<" & IF($D19="",200,$D19),EeData!$F:$F,">="&L$2,EeData!$F:$F,"<" & IF(L$4="",100,L$4))) | M19: =IF(OR(M$8="",$F19=""),"",COUNTIFS(EeData!$G:$G,"A",EeData!$E:$E,">="&$B19,EeData!$E:$E,"<" & IF($D19="",200,$D19),EeData!$F:$F,">="&M$2,EeData!$F:$F,"<" & IF(M$4="",100,M$4))) | N19: =IF(OR(N$8="",$F19=""),"",COUNTIFS(EeData!$G:$G,"A",EeData!$E:$E,">="&$B19,EeData!$E:$E,"<" & IF($D19="",200,$D19),EeData!$F:$F,">="&N$2,EeData!$F:$F,"<" & IF(N$4="",100,N$4))) | ... Q19: =IF(OR(Q$8="",$F19=""),"",COUNTIFS(EeData!$G:$G,"A",EeData!$E:$E,">="&$B19,EeData!$E:$E,"<" & IF($D19="",200,$D19),EeData!$F:$F,">="&Q$2,EeData!$F:$F,"<" & IF(Q$4="",100,Q$4))) | R19: =SUM(G19:Q19) -> 0
B20: =IF(D19="","",D19) | F20: =IF(B20="","",IF(B20=0,"<"&D20,IF(D20="",B20&" <=",B20&" - "&D20))) | G20: =IF(OR(G$8="",$F20=""),"",COUNTIFS(EeData!$G:$G,"A",EeData!$E:$E,">="&$B20,EeData!$E:$E,"<" & IF($D20="",200,$D20),EeData!$F:$F,">="&G$2,EeData!$F:$F,"<" & IF(G$4="",100,G$4))) | H20: =IF(OR(H$8="",$F20=""),"",COUNTIFS(EeData!$G:$G,"A",EeData!$E:$E,">="&$B20,EeData!$E:$E,"<" & IF($D20="",200,$D20),EeData!$F:$F,">="&H$2,EeData!$F:$F,"<" & IF(H$4="",100,H$4))) | I20: =IF(OR(I$8="",$F20=""),"",COUNTIFS(EeData!$G:$G,"A",EeData!$E:$E,">="&$B20,EeData!$E:$E,"<" & IF($D20="",200,$D20),EeData!$F:$F,">="&I$2,EeData!$F:$F,"<" & IF(I$4="",100,I$4))) | J20: =IF(OR(J$8="",$F20=""),"",COUNTIFS(EeData!$G:$G,"A",EeData!$E:$E,">="&$B20,EeData!$E:$E,"<" & IF($D20="",200,$D20),EeData!$F:$F,">="&J$2,EeData!$F:$F,"<" & IF(J$4="",100,J$4))) | K20: =IF(OR(K$8="",$F20=""),"",COUNTIFS(EeData!$G:$G,"A",EeData!$E:$E,">="&$B20,EeData!$E:$E,"<" & IF($D20="",200,$D20),EeData!$F:$F,">="&K$2,EeData!$F:$F,"<" & IF(K$4="",100,K$4))) | L20: =IF(OR(L$8="",$F20=""),"",COUNTIFS(EeData!$G:$G,"A",EeData!$E:$E,">="&$B20,EeData!$E:$E,"<" & IF($D20="",200,$D20),EeData!$F:$F,">="&L$2,EeData!$F:$F,"<" & IF(L$4="",100,L$4))) | M20: =IF(OR(M$8="",$F20=""),"",COUNTIFS(EeData!$G:$G,"A",EeData!$E:$E,">="&$B20,EeData!$E:$E,"<" & IF($D20="",200,$D20),EeData!$F:$F,">="&M$2,EeData!$F:$F,"<" & IF(M$4="",100,M$4))) | N20: =IF(OR(N$8="",$F20=""),"",COUNTIFS(EeData!$G:$G,"A",EeData!$E:$E,">="&$B20,EeData!$E:$E,"<" & IF($D20="",200,$D20),EeData!$F:$F,">="&N$2,EeData!$F:$F,"<" & IF(N$4="",100,N$4))) | ... Q20: =IF(OR(Q$8="",$F20=""),"",COUNTIFS(EeData!$G:$G,"A",EeData!$E:$E,">="&$B20,EeData!$E:$E,"<" & IF($D20="",200,$D20),EeData!$F:$F,">="&Q$2,EeData!$F:$F,"<" & IF(Q$4="",100,Q$4))) | R20: =SUM(G20:Q20) -> 0
B21: =IF(D20="","",D20) | F21: =IF(B21="","",IF(B21=0,"<"&D21,IF(D21="",B21&" <=",B21&" - "&D21))) | G21: =IF(OR(G$8="",$F21=""),"",COUNTIFS(EeData!$G:$G,"A",EeData!$E:$E,">="&$B21,EeData!$E:$E,"<" & IF($D21="",200,$D21),EeData!$F:$F,">="&G$2,EeData!$F:$F,"<" & IF(G$4="",100,G$4))) | H21: =IF(OR(H$8="",$F21=""),"",COUNTIFS(EeData!$G:$G,"A",EeData!$E:$E,">="&$B21,EeData!$E:$E,"<" & IF($D21="",200,$D21),EeData!$F:$F,">="&H$2,EeData!$F:$F,"<" & IF(H$4="",100,H$4))) | I21: =IF(OR(I$8="",$F21=""),"",COUNTIFS(EeData!$G:$G,"A",EeData!$E:$E,">="&$B21,EeData!$E:$E,"<" & IF($D21="",200,$D21),EeData!$F:$F,">="&I$2,EeData!$F:$F,"<" & IF(I$4="",100,I$4))) | J21: =IF(OR(J$8="",$F21=""),"",COUNTIFS(EeData!$G:$G,"A",EeData!$E:$E,">="&$B21,EeData!$E:$E,"<" & IF($D21="",200,$D21),EeData!$F:$F,">="&J$2,EeData!$F:$F,"<" & IF(J$4="",100,J$4))) | K21: =IF(OR(K$8="",$F21=""),"",COUNTIFS(EeData!$G:$G,"A",EeData!$E:$E,">="&$B21,EeData!$E:$E,"<" & IF($D21="",200,$D21),EeData!$F:$F,">="&K$2,EeData!$F:$F,"<" & IF(K$4="",100,K$4))) | L21: =IF(OR(L$8="",$F21=""),"",COUNTIFS(EeData!$G:$G,"A",EeData!$E:$E,">="&$B21,EeData!$E:$E,"<" & IF($D21="",200,$D21),EeData!$F:$F,">="&L$2,EeData!$F:$F,"<" & IF(L$4="",100,L$4))) | M21: =IF(OR(M$8="",$F21=""),"",COUNTIFS(EeData!$G:$G,"A",EeData!$E:$E,">="&$B21,EeData!$E:$E,"<" & IF($D21="",200,$D21),EeData!$F:$F,">="&M$2,EeData!$F:$F,"<" & IF(M$4="",100,M$4))) | N21: =IF(OR(N$8="",$F21=""),"",COUNTIFS(EeData!$G:$G,"A",EeData!$E:$E,">="&$B21,EeData!$E:$E,"<" & IF($D21="",200,$D21),EeData!$F:$F,">="&N$2,EeData!$F:$F,"<" & IF(N$4="",100,N$4))) | ... Q21: =IF(OR(Q$8="",$F21=""),"",COUNTIFS(EeData!$G:$G,"A",EeData!$E:$E,">="&$B21,EeData!$E:$E,"<" & IF($D21="",200,$D21),EeData!$F:$F,">="&Q$2,EeData!$F:$F,"<" & IF(Q$4="",100,Q$4))) | R21: =SUM(G21:Q21) -> 0
B22: =IF(D21="","",D21) | F22: =IF(B22="","",IF(B22=0,"<"&D22,IF(D22="",B22&" <=",B22&" - "&D22))) | G22: =IF(OR(G$8="",$F22=""),"",COUNTIFS(EeData!$G:$G,"A",EeData!$E:$E,">="&$B22,EeData!$E:$E,"<" & IF($D22="",200,$D22),EeData!$F:$F,">="&G$2,EeData!$F:$F,"<" & IF(G$4="",100,G$4))) | H22: =IF(OR(H$8="",$F22=""),"",COUNTIFS(EeData!$G:$G,"A",EeData!$E:$E,">="&$B22,EeData!$E:$E,"<" & IF($D22="",200,$D22),EeData!$F:$F,">="&H$2,EeData!$F:$F,"<" & IF(H$4="",100,H$4))) | I22: =IF(OR(I$8="",$F22=""),"",COUNTIFS(EeData!$G:$G,"A",EeData!$E:$E,">="&$B22,EeData!$E:$E,"<" & IF($D22="",200,$D22),EeData!$F:$F,">="&I$2,EeData!$F:$F,"<" & IF(I$4="",100,I$4))) | J22: =IF(OR(J$8="",$F22=""),"",COUNTIFS(EeData!$G:$G,"A",EeData!$E:$E,">="&$B22,EeData!$E:$E,"<" & IF($D22="",200,$D22),EeData!$F:$F,">="&J$2,EeData!$F:$F,"<" & IF(J$4="",100,J$4))) | K22: =IF(OR(K$8="",$F22=""),"",COUNTIFS(EeData!$G:$G,"A",EeData!$E:$E,">="&$B22,EeData!$E:$E,"<" & IF($D22="",200,$D22),EeData!$F:$F,">="&K$2,EeData!$F:$F,"<" & IF(K$4="",100,K$4))) | L22: =IF(OR(L$8="",$F22=""),"",COUNTIFS(EeData!$G:$G,"A",EeData!$E:$E,">="&$B22,EeData!$E:$E,"<" & IF($D22="",200,$D22),EeData!$F:$F,">="&L$2,EeData!$F:$F,"<" & IF(L$4="",100,L$4))) | M22: =IF(OR(M$8="",$F22=""),"",COUNTIFS(EeData!$G:$G,"A",EeData!$E:$E,">="&$B22,EeData!$E:$E,"<" & IF($D22="",200,$D22),EeData!$F:$F,">="&M$2,EeData!$F:$F,"<" & IF(M$4="",100,M$4))) | N22: =IF(OR(N$8="",$F22=""),"",COUNTIFS(EeData!$G:$G,"A",EeData!$E:$E,">="&$B22,EeData!$E:$E,"<" & IF($D22="",200,$D22),EeData!$F:$F,">="&N$2,EeData!$F:$F,"<" & IF(N$4="",100,N$4))) | ... Q22: =IF(OR(Q$8="",$F22=""),"",COUNTIFS(EeData!$G:$G,"A",EeData!$E:$E,">="&$B22,EeData!$E:$E,"<" & IF($D22="",200,$D22),EeData!$F:$F,">="&Q$2,EeData!$F:$F,"<" & IF(Q$4="",100,Q$4))) | R22: =SUM(G22:Q22) -> 0
B23: =IF(D22="","",D22) | F23: =IF(B23="","",IF(B23=0,"<"&D23,IF(D23="",B23&" <=",B23&" - "&D23))) | G23: =IF(OR(G$8="",$F23=""),"",COUNTIFS(EeData!$G:$G,"A",EeData!$E:$E,">="&$B23,EeData!$E:$E,"<" & IF($D23="",200,$D23),EeData!$F:$F,">="&G$2,EeData!$F:$F,"<" & IF(G$4="",100,G$4))) | H23: =IF(OR(H$8="",$F23=""),"",COUNTIFS(EeData!$G:$G,"A",EeData!$E:$E,">="&$B23,EeData!$E:$E,"<" & IF($D23="",200,$D23),EeData!$F:$F,">="&H$2,EeData!$F:$F,"<" & IF(H$4="",100,H$4))) | I23: =IF(OR(I$8="",$F23=""),"",COUNTIFS(EeData!$G:$G,"A",EeData!$E:$E,">="&$B23,EeData!$E:$E,"<" & IF($D23="",200,$D23),EeData!$F:$F,">="&I$2,EeData!$F:$F,"<" & IF(I$4="",100,I$4))) | J23: =IF(OR(J$8="",$F23=""),"",COUNTIFS(EeData!$G:$G,"A",EeData!$E:$E,">="&$B23,EeData!$E:$E,"<" & IF($D23="",200,$D23),EeData!$F:$F,">="&J$2,EeData!$F:$F,"<" & IF(J$4="",100,J$4))) | K23: =IF(OR(K$8="",$F23=""),"",COUNTIFS(EeData!$G:$G,"A",EeData!$E:$E,">="&$B23,EeData!$E:$E,"<" & IF($D23="",200,$D23),EeData!$F:$F,">="&K$2,EeData!$F:$F,"<" & IF(K$4="",100,K$4))) | L23: =IF(OR(L$8="",$F23=""),"",COUNTIFS(EeData!$G:$G,"A",EeData!$E:$E,">="&$B23,EeData!$E:$E,"<" & IF($D23="",200,$D23),EeData!$F:$F,">="&L$2,EeData!$F:$F,"<" & IF(L$4="",100,L$4))) | M23: =IF(OR(M$8="",$F23=""),"",COUNTIFS(EeData!$G:$G,"A",EeData!$E:$E,">="&$B23,EeData!$E:$E,"<" & IF($D23="",200,$D23),EeData!$F:$F,">="&M$2,EeData!$F:$F,"<" & IF(M$4="",100,M$4))) | N23: =IF(OR(N$8="",$F23=""),"",COUNTIFS(EeData!$G:$G,"A",EeData!$E:$E,">="&$B23,EeData!$E:$E,"<" & IF($D23="",200,$D23),EeData!$F:$F,">="&N$2,EeData!$F:$F,"<" & IF(N$4="",100,N$4))) | ... Q23: =IF(OR(Q$8="",$F23=""),"",COUNTIFS(EeData!$G:$G,"A",EeData!$E:$E,">="&$B23,EeData!$E:$E,"<" & IF($D23="",200,$D23),EeData!$F:$F,">="&Q$2,EeData!$F:$F,"<" & IF(Q$4="",100,Q$4))) | R23: =SUM(G23:Q23) -> 0
B24: =IF(D23="","",D23) | F24: =IF(B24="","",IF(B24=0,"<"&D24,IF(D24="",B24&" <=",B24&" - "&D24))) | G24: =IF(OR(G$8="",$F24=""),"",COUNTIFS(EeData!$G:$G,"A",EeData!$E:$E,">="&$B24,EeData!$E:$E,"<" & IF($D24="",200,$D24),EeData!$F:$F,">="&G$2,EeData!$F:$F,"<" & IF(G$4="",100,G$4))) | H24: =IF(OR(H$8="",$F24=""),"",COUNTIFS(EeData!$G:$G,"A",EeData!$E:$E,">="&$B24,EeData!$E:$E,"<" & IF($D24="",200,$D24),EeData!$F:$F,">="&H$2,EeData!$F:$F,"<" & IF(H$4="",100,H$4))) | I24: =IF(OR(I$8="",$F24=""),"",COUNTIFS(EeData!$G:$G,"A",EeData!$E:$E,">="&$B24,EeData!$E:$E,"<" & IF($D24="",200,$D24),EeData!$F:$F,">="&I$2,EeData!$F:$F,"<" & IF(I$4="",100,I$4))) | J24: =IF(OR(J$8="",$F24=""),"",COUNTIFS(EeData!$G:$G,"A",EeData!$E:$E,">="&$B24,EeData!$E:$E,"<" & IF($D24="",200,$D24),EeData!$F:$F,">="&J$2,EeData!$F:$F,"<" & IF(J$4="",100,J$4))) | K24: =IF(OR(K$8="",$F24=""),"",COUNTIFS(EeData!$G:$G,"A",EeData!$E:$E,">="&$B24,EeData!$E:$E,"<" & IF($D24="",200,$D24),EeData!$F:$F,">="&K$2,EeData!$F:$F,"<" & IF(K$4="",100,K$4))) | L24: =IF(OR(L$8="",$F24=""),"",COUNTIFS(EeData!$G:$G,"A",EeData!$E:$E,">="&$B24,EeData!$E:$E,"<" & IF($D24="",200,$D24),EeData!$F:$F,">="&L$2,EeData!$F:$F,"<" & IF(L$4="",100,L$4))) | M24: =IF(OR(M$8="",$F24=""),"",COUNTIFS(EeData!$G:$G,"A",EeData!$E:$E,">="&$B24,EeData!$E:$E,"<" & IF($D24="",200,$D24),EeData!$F:$F,">="&M$2,EeData!$F:$F,"<" & IF(M$4="",100,M$4))) | N24: =IF(OR(N$8="",$F24=""),"",COUNTIFS(EeData!$G:$G,"A",EeData!$E:$E,">="&$B24,EeData!$E:$E,"<" & IF($D24="",200,$D24),EeData!$F:$F,">="&N$2,EeData!$F:$F,"<" & IF(N$4="",100,N$4))) | ... Q24: =IF(OR(Q$8="",$F24=""),"",COUNTIFS(EeData!$G:$G,"A",EeData!$E:$E,">="&$B24,EeData!$E:$E,"<" & IF($D24="",200,$D24),EeData!$F:$F,">="&Q$2,EeData!$F:$F,"<" & IF(Q$4="",100,Q$4))) | R24: =SUM(G24:Q24) -> 0
B25: =IF(D24="","",D24) | F25: Total | G25: =SUM(G9:G24) -> 7 | H25: =SUM(H9:H24) -> 11 | I25: =SUM(I9:I24) -> 11 | J25: =SUM(J9:J24) -> 3 | K25: =SUM(K9:K24) -> 3 | L25: =SUM(L9:L24) -> 2 | M25: =SUM(M9:M24) -> 0 | N25: =SUM(N9:N24) -> 0 | ... R25: =SUM(R9:R24) -> 37

Sheet EeData
A1: Employee Database
A5: ID | B5: Company Code | C5: Current Salary | D5: Prior Salary | E5: Age | F5: Service | G5: Status Code | H5: Prior Status
A6: 375757 | B6: 2 | C6: 96000 | D6: 91428.571 | E6: 55 | F6: 7 | G6: A | H6: A
A7: 384691 | B7: 1 | C7: 89000 | D7: 84761.905 | E7: 52 | F7: 5 | G7: A | H7: A
A8: 396332 | B8: 3 | C8: 85000 | E8: 48 | F8: 1 | G8: A
A9: 401073 | B9: 1 | D9: 80000 | E9: 66 | G9: R | H9: R
A10: 409118 | B10: 1 | C10: 83000 | D10: 71000 | E10: 28 | F10: 11 | G10: A | H10: A
A11: 411380 | B11: 1 | C11: 86000 | D11: 74000 | E11: 57 | F11: 27 | G11: A | H11: A
A12: 412092 | B12: 1 | C12: 87000 | E12: 32 | F12: 2 | G12: A
A13: 413369 | B13: 1 | C13: 86000 | E13: 44 | F13: 14 | G13: A
A14: 415179 | B14: 1 | C14: 75000 | D14: 63000 | E14: 32 | F14: 2 | G14: A | H14: A
A15: 422576 | B15: 1 | C15: 86000 | D15: 80000 | E15: 55 | G15: R | H15: A
A16: 424060 | B16: 3 | C16: 250000 | D16: 230000 | E16: 51 | F16: 10 | G16: A | H16: A
A17: 431411 | B17: 3 | C17: 91000 | D17: 86666.667 | E17: 49 | F17: 6 | G17: A | H17: A
A18: 436028 | B18: 1 | C18: 86000 | D18: 74000 | E18: 23 | F18: 3 | G18: A | H18: A
A19: 437293 | B19: 3 | C19: 86000 | D19: 80000 | E19: 51 | G19: V | H19: A
A20: 438052 | B20: 1 | C20: 86000 | D20: 74000 | E20: 32 | F20: 9 | G20: A | H20: A
A21: 438638 | B21: 2 | C21: 87000 | D21: 82857.143 | E21: 47 | F21: 12 | G21: A | H21: A
A22: 449418 | B22: 1 | C22: 76000 | D22: 64000 | E22: 45 | F22: 15 | G22: A | H22: A
A23: 449944 | B23: 1 | C23: 86000 | D23: 80000 | E23: 45 | G23: V | H23: A
A24: 452656 | B24: 2 | C24: 93000 | D24: 88571.429 | E24: 46 | F24: 18 | G24: A | H24: A
A25: 463271 | B25: 1 | C25: 54000 | D25: 42000 | E25: 32 | F25: 8 | G25: A | H25: A
A26: 463938 | B26: 1 | C26: 96000 | D26: 84000 | E26: 32 | F26: 2 | G26: A | H26: A
A27: 479102 | B27: 3 | C27: 85000 | E27: 48 | F27: 1 | G27: A
A28: 481800 | B28: 2 | D28: 80000 | E28: 64 | G28: R | H28: R
A29: 482078 | B29: 1 | C29: 110000 | D29: 98000 | E29: 32 | F29: 8 | G29: A | H29: A
A30: 486583 | B30: 1 | C30: 86000 | D30: 80000 | E30: 32 | G30: T | H30: A
A31: 492053 | B31: 1 | C31: 86000 | D31: 74000 | E31: 32 | F31: 2 | G31: A | H31: A
A32: 492133 | B32: 1 | C32: 100000 | D32: 88000 | E32: 32 | F32: 10 | G32: A | H32: A
A33: 492176 | B33: 1 | C33: 86000 | D33: 80000 | E33: 34 | G33: T | H33: A
A34: 496907 | B34: 2 | D34: 80000 | E34: 59 | G34: R | H34: V
A35: 507242 | B35: 1 | C35: 92000 | D35: 40000 | E35: 44 | F35: 7 | G35: A | H35: A
A36: 513820 | B36: 1 | D36: 80000 | E36: 62 | G36: R | H36: V
A37: 514774 | B37: 3 | D37: 80000 | E37: 44 | G37: V | H37: V
A38: 520201 | B38: 2 | D38: 80000 | E38: 36 | G38: V | H38: V
A39: 520938 | B39: 1 | C39: 23000 | D39: 11000 | E39: 36 | F39: 10 | G39: A | H39: A
A40: 521501 | B40: 1 | C40: 79000 | D40: 67000 | E40: 26 | F40: 8 | G40: A | H40: A
A41: 526149 | B41: 3 | C41: 97000 | D41: 92380.952 | E41: 55 | F41: 9 | G41: A | H41: A
A42: 539134 | B42: 1 | C42: 94000 | D42: 82000 | E42: 32 | F42: 10 | G42: A | H42: A
A43: 540346 | B43: 1 | C43: 95000 | D43: 90476.19 | E43: 49 | F43: 10 | G43: A | H43: A
...
