Workbook
Name AssetM: [1]Table!$J$3:$K$13
Name Benjamin: OFFSET('[2]Weight Watch'!$B$9,'[2]Weight Watch'!$I$3-9,2,'[2]Weight Watch'!$I$2,1)
Name Client: [1]X!$C$9
Name DateF: OFFSET('[2]Weight Watch'!$B$9,'[2]Weight Watch'!$I$3-9,0,'[2]Weight Watch'!$I$2,1)
Name DefaultB: [1]X!$F$5
Name Difference: OFFSET([3]Salman!$G$9,0,0,[3]Salman!$B$4,1)
Name Eric: OFFSET('[2]Weight Watch'!$B$9,'[2]Weight Watch'!$I$3-9,4,'[2]Weight Watch'!$I$2,1)
Name FanF: OFFSET('[2]Weight Watch'!$B$9,'[2]Weight Watch'!$I$3-9,3,'[2]Weight Watch'!$I$2,1)
Name Footer: [1]X!$C$10
Name George: OFFSET('[2]Weight Watch'!$B$9,'[2]Weight Watch'!$I$3-9,3,'[2]Weight Watch'!$I$2,1)
Name LiF: OFFSET('[2]Weight Watch'!$B$9,'[2]Weight Watch'!$I$3-9,2,'[2]Weight Watch'!$I$2,1)
Name MeasDate: OFFSET('[2]Weight Watch'!$B$9,'[2]Weight Watch'!$I$3-9,0,'[2]Weight Watch'!$I$2,1)
Name MetMRV: [4]Table!$C$21:$D$31
Name Rate: OFFSET([5]Rate!$C$4,0,0,COUNT([5]Rate!$C:$C))
Name Version: [1]X!$A$2
Name WangF: OFFSET('[2]Weight Watch'!$B$9,'[2]Weight Watch'!$I$3-9,4,'[2]Weight Watch'!$I$2,1)
Name Year: OFFSET([5]Rate!$B$4,0,0,COUNT([5]Rate!$B:$B))
Name Year158: '[6]FAS 158 Input'!$H$4

Sheet Client Data
A1: ID | B1: Date of Birth | C1: Date of Hire | D1: Salary | E1: Retirement Date | F1: Retirement Benefit | G1: Status
A2: 123491 | B2: 24017 | C2: 34809 | D2: 250000 | G2: A
A3: 144983 | B3: 27601 | C3: 38001 | D3: 99000 | G3: A
A4: 187427 | B4: 21170 | C4: 37975 | D4: 98000 | G4: A
A5: 189508 | B5: 30229 | C5: 35020 | D5: 97000 | G5: A
A6: 199741 | B6: 16439 | C6: 35929 | D6: 96000 | G6: A
A7: 205217 | B7: 17620 | C7: 34867 | D7: 95000 | G7: A
A8: 206418 | B8: 20874 | C8: 40497 | D8: 320000 | G8: A
A9: 218201 | B9: 15818 | C9: 35362 | D9: 93000 | G9: A
A10: 225139 | B10: 33987 | C10: 41074 | D10: 92000 | G10: A
A11: 232072 | B11: 24290 | C11: 39634 | D11: 91000 | G11: A
A12: 250067 | B12: 2/30/1960 | C12: 40073 | D12: 90000 | G12: A
A13: 253862 | B13: 23332 | C13: 40339 | D13: 89000 | G13: A
A14: 255179 | B14: 22281 | C14: 40774 | D14: 88000 | G14: A
A15: 258130 | B15: 29124 | C15: 29006 | D15: 87000 | G15: A
A16: 286491 | B16: 16018 | C16: 31071 | D16: 86000 | G16: A
A17: 290999 | B17: 25991 | C17: 41600 | D17: 85000 | G17: A
A18: 300843 | B18: 17659 | C18: 31876 | D18: 84000 | G18: A
A19: 302798 | B19: 28924 | C19: 35009 | D19: 86000 | G19: A
A20: 310267 | B20: 23532 | C20: 38201 | D20: 86000 | G20: A
A21: 313615 | B21: 34187 | C21: 38175 | D21: 87000 | G21: A
A22: 320387 | B22: 25791 | C22: 35220 | D22: 76000 | G22: A
A23: 340436 | B23: 27801 | C23: 36129 | D23: 75000 | G23: A
A24: 345767 | B24: 24217 | C24: 35067 | D24: 86000 | G24: A
... A43: 545776 | B43: 24090 | C43: 35762 | D43: 86000 | G43: A
A44: 123486 | B44: 19725 | C44: 41474 | E44: 43466 | F44: 8990 | G44: V
A45: 123485 | B45: 16254 | C45: 40073 | E45: 39995 | F45: 18047 | G45: R
A46: 123484 | B46: 18203 | C46: 40339 | E46: 41944 | F46: 9625 | G46: R
A47: 123472 | B47: 19725 | C47: 40774 | E47: 43466 | F47: 5840 | G47: V
A48: 123466 | B48: 22098 | E48: 45839 | F48: 15804 | G48: V
A49: 123465 | B49: 16803 | E49: 40544 | F49: 10349 | G49: R
A50: 579277 | B50: 22084 | D50: 85000 | G50: A
A51: 565414 | B51: 21758 | D51: 110000 | G51: A
A52: 570202 | B52: 16239
A53: 578408 | B53: 17459
A54: 579268 | B54: 22081 | D54: 83000 | G54: A
A55: 579271 | B55: 22069
A56: 579274 | B56: 20256 | D56: 200000 | G56: A
A57: 579414 | B57: 32874 | C57: 41974 | D57: 110000 | G57: A

Sheet Employee Database
A2: Employee Data Provided for the 2015 valuation
A5: ID | B5: Name | C5: Date of Birth | D5: Date of Hire | E5: 2014 Salary | F5: 2013 Salary | G5: 2012 Salary | H5: Retirement Date | I5: Retirement Benefit | J5: 1/1/2015 Status | K5: 1/1/2014 Status | L5: Age | M5: Service | N5: Average Salary | O5: Salary Increase
A6: 123491 | B6: Shapiro, Amanda | C6: 24017 | D6: 34809 | E6: 250000 | F6: 230000 | G6: 210000 | J6: A | K6: A
A7: 144983 | B7: Donovan, Adrienne | C7: 27601 | D7: 38001 | E7: 99000 | F7: 94300 | G7: 89800 | J7: A | K7: A
A8: 187427 | B8: Tiedens, Bret | C8: 21170 | D8: 37975 | E8: 98000 | F8: 93300 | G8: 88900 | J8: A | K8: A
A9: 189508 | B9: Souers, Celina | C9: 30229 | D9: 35020 | E9: 97000 | F9: 92400 | G9: 88000 | J9: A | K9: A
A10: 199741 | B10: Al Jaloud, Steve | C10: 16439 | D10: 35929 | E10: 96000 | F10: 91400 | G10: 87100 | J10: A | K10: A
A11: 205217 | B11: Butina, Natalie | C11: 17620 | D11: 34867 | E11: 95000 | F11: 90500 | G11: 86200 | J11: A | K11: A
A12: 206418 | B12: Olson, Nicholas | C12: 20874 | D12: 40497 | E12: 320000 | F12: 32000 | J12: A | K12: A
A13: 218201 | B13: Richman, Michelle | C13: 15818 | D13: 35362 | E13: 93000 | F13: 88600 | G13: 84400 | J13: A | K13: A
A14: 225139 | B14: Johnson, Aaron | C14: 33987 | D14: 41074 | E14: 92000 | F14: 40000 | J14: A | K14: A
A15: 232072 | B15: Brinkley, Jeanne M | C15: 24290 | D15: 39634 | E15: 91000 | F15: 86700 | G15: 82500 | J15: A | K15: A
A16: 250067 | B16: Brinkley, Roxanne L | C16: 2/30/1960 | D16: 40073 | E16: 90000 | F16: 85700 | G16: 81600 | J16: A | K16: A
A17: 253862 | B17: Nelson, Yuyang | C17: 23332 | D17: 40339 | E17: 89000 | F17: 84800 | G17: 80700 | J17: A | K17: A
A18: 255179 | B18: Bossler, Bill | C18: 22281 | D18: 40774 | E18: 88000 | F18: 83800 | G18: 40000 | J18: A | K18: A
A19: 258130 | B19: Cress, Scott G | C19: 29124 | D19: 29006 | E19: 87000 | F19: 82900 | G19: 78900 | J19: A | K19: A
A20: 286491 | B20: Aljebreen, Patric | C20: 16018 | D20: 31071 | E20: 86000 | F20: 81900 | G20: 78000 | J20: A | K20: A
A21: 290999 | B21: Dehn, Diane M | C21: 25991 | D21: 41600 | E21: 85000 | F21: 2000 | J21: A
A22: 300843 | B22: Baker, Eric | C22: 17659 | D22: 31876 | E22: 84000 | F22: 80000 | G22: 76200 | J22: A | K22: A
A23: 302798 | B23: Asche, Ryan | C23: 28924 | D23: 35009 | E23: 300000 | F23: 276000 | G23: 252000 | J23: A | K23: A
A24: 310267 | B24: Chen, Jerome F | C24: 23532 | D24: 38201 | E24: 118800 | F24: 113100 | G24: 107800 | J24: A | K24: A
A25: 313615 | B25: Gist, Tracy A | C25: 34187 | D25: 38175 | E25: 117600 | F25: 112000 | G25: 106700 | J25: A | K25: A
A26: 320387 | B26: Carlson, Jeremy | C26: 25791 | D26: 35220 | E26: 116400 | F26: 110900 | G26: 105600 | J26: A | K26: A
A27: 340436 | B27: Duvall, DeeAnn S | C27: 27791 | D27: 36129 | E27: 115200 | F27: 109700 | G27: 104500 | J27: A | K27: A
A28: 345767 | B28: Gall, Susann K | C28: 24217 | D28: 35067 | E28: 114000 | F28: 108600 | G28: 103400 | J28: A | K28: A
A29: 352244 | B29: Harvestine, Susan R | C29: 21370 | D29: 41429 | E29: 384000 | F29: 38400 | J29: A
A30: 357982 | B30: Harada, Richard G | C30: 17820 | D30: 35562 | E30: 111600 | F30: 106300 | G30: 101200 | J30: A | K30: A
A31: 369257 | B31: Guy, Robert L | C31: 3651 | D31: 41274 | E31: 110400 | F31: 48000 | J31: A | K31: A
A32: 375122 | B32: Kampwerth, Rebecca M | C32: 17859 | D32: 39834 | E32: 109200 | F32: 104000 | G32: 99000 | J32: A | K32: A
A33: 406300 | B33: Asche, Alexis | C33: 1 | D33: 40273 | E33: 108000 | F33: 102900 | G33: 98000 | J33: A | K33: A
A34: 422365 | B34: Hitpas, Bruce D | C34: 21074 | D34: 40539 | E34: 106800 | F34: 101700 | G34: 96900 | J34: A | K34: A
A35: 423109 | B35: Jumaan, Casey A | C35: 16218 | D35: 40974 | E35: 105600 | F35: 100600 | G35: 48000 | J35: A | K35: A
A36: 426223 | B36: Donovan, Alina | C36: 26191 | D36: 27116 | E36: 104400 | F36: 99400 | G36: 94700 | J36: A | K36: A
A37: 430276 | B37: Carlson, Austin | C37: 29324 | D37: 31271 | E37: 103200 | F37: 98300 | G37: 93600 | J37: A | K37: A
A38: 430534 | B38: Hohl, David L | C38: 16018 | D38: 1 | E38: 102000 | F38: 2400 | J38: A | K38: A
A39: 443913 | B39: Jackson, Dawn E | C39: 16639 | D39: 32076 | E39: 100800 | F39: 96000 | G39: 91400 | J39: A | K39: A
A40: 446641 | B40: Shapiro, Amanda | C40: 23652 | D40: 35209 | E40: 360000 | F40: 331200 | G40: 302400 | J40: A | K40: A
A41: 462488 | B41: Lam, Jacqueline E | C41: 22481 | D41: 38401 | E41: 142600 | F41: 135700 | G41: 129400 | J41: A | K41: A
A42: 472297 | B42: Johnson, Aaron | C42: 33987 | D42: 38375 | E42: 141100 | F42: 134400 | G42: 128000 | J42: A | K42: A
A43: 489909 | B43: Nelson, Jumaan | C43: 24490 | D43: 1 | E43: 139700 | F43: 133100 | G43: 126700 | J43: A | K43: A
...

Sheet Spec
A1: ID | B1: Date of Birth | C1: Date of Hire | D1: 2015 Salary | E1: 2014 Salary | F1: 2013 Salary | G1: Retirement Date | H1: Retirement Benefit | I1: Status Code | J1: Prior Status
A2: Employee Database | B2: 3 | C2: 4 | E2: 5 | F2: 6 | G2: 8 | H2: 9 | J2: 10
A3: Client Data | B3: 2 | C3: 3 | D3: 4 | G3: 5 | H3: 6 | I3: 7

Sheet ValData
A1: ID | B1: Name | C1: Date of Birth | D1: Date of Hire | E1: 2015 Salary | F1: 2014 Salary | G1: 2013 Salary | H1: Retirement Date | I1: Retirement Benefit | J1: Status Code | K1: Prior Status | M1: Client Data Index | N1: Emplyee Database Index | O1: New Record | P1: Gone Record | R1: Difference in DOB | S1: Difference in DOH | T1: Difference in DOR | U1: Difference in Benefit
A2: 123491 | B2: =IF(ISNA(MATCH(A2,'Employee Database'!$A$6:$A$58,0)),"Not Available",INDEX('Employee Database'!$B$6:$B$58,MATCH(A2,'Employee Database'!$A$6:$A$58,0))) -> Shapiro, Amanda | C2: =IF(NOT(ISNA($N2)),VLOOKUP($A2,'Employee Database'!$A:$K,Spec!B$2,FALSE), IF(NOT(ISNA($M2)), VLOOKUP($A2,'Client Data'!$A:$G,Spec!B$3,FALSE),"")) -> 24017 | D2: =IF(NOT(ISNA($N2)),VLOOKUP($A2,'Employee Database'!$A:$K,Spec!C$2,FALSE), IF(NOT(ISNA($M2)), VLOOKUP($A2,'Client Data'!$A:$G,Spec!C$3,FALSE),"")) -> 34809 | E2: =IF(NOT(ISNA($M2)), VLOOKUP($A2,'Client Data'!$A:$G,Spec!D$3,FALSE), "") -> 250000 | F2: =IF(NOT(ISNA($N2)), VLOOKUP($A2,'Employee Database'!$A:$K,Spec!E$2,FALSE), "") -> 250000 | G2: =IF(NOT(ISNA($N2)), VLOOKUP($A2,'Employee Database'!$A:$K,Spec!F$2,FALSE), "") -> 230000 | H2: =IF(ISNA($M2), "", IF(VLOOKUP($A2,'Client Data'!$A:$G,Spec!G$3,FALSE)="", "", VLOOKUP($A2, 'Client Data'!$A:$G,Spec!G$3,FALSE))) | I2: =IF(ISNA($M2), "", IF(VLOOKUP($A2,'Client Data'!$A:$G,Spec!H$3,FALSE)="", "", VLOOKUP($A2, 'Client Data'!$A:$G,Spec!H$3,FALSE))) | J2: =IF(NOT(ISNA($M2)), VLOOKUP($A2,'Client Data'!$A:$G,Spec!I$3,FALSE), "") -> A | K2: =IF(NOT(ISNA($N2)), VLOOKUP($A2,'Employee Database'!$A:$K,Spec!J$2,FALSE), "") -> A | M2: =MATCH(A2,'Client Data'!A:A,0) -> 2 | N2: =MATCH(A2,'Employee Database'!A:A,0) -> 6 | O2: =IF(AND(NOT(ISNA(M2)), ISNA(N2)),TRUE,"") | P2: =IF(AND(ISNA(M2), NOT(ISNA(N2))),TRUE,"") | R2: =IF(OR(ISNA($M2),ISNA($N2)),"",IF(C2=VLOOKUP($A2,'Client Data'!$A:$G,Spec!B$3,FALSE),"",VLOOKUP($A2,'Client Data'!$A:$G,Spec!B$3,FALSE))) | S2: =IF(OR(ISNA($M2),ISNA($N2)),"",IF(D2=VLOOKUP($A2,'Client Data'!$A:$G,Spec!C$3,FALSE),"",VLOOKUP($A2,'Client Data'!$A:$G,Spec!C$3,FALSE))) | T2: =IF(OR(ISNA($M2),ISNA($N2)),"",IF(H2=VLOOKUP($A2,'Employee Database'!$A:$K,Spec!G$2,FALSE),"",VLOOKUP($A2,'Employee Database'!$A:$K,Spec!G$2,FALSE))) | U2: =IF(OR(ISNA($M2),ISNA($N2)),"",IF(I2=VLOOKUP($A2,'Employee Database'!$A:$K,Spec!H$2,FALSE),"",VLOOKUP($A2,'Employee Database'!$A:$K,Spec!H$2,FALSE)))
A3: 144983 | B3: =IF(ISNA(MATCH(A3,'Employee Database'!$A$6:$A$58,0)),"Not Available",INDEX('Employee Database'!$B$6:$B$58,MATCH(A3,'Employee Database'!$A$6:$A$58,0))) -> Donovan, Adrienne | C3: =IF(NOT(ISNA($N3)),VLOOKUP($A3,'Employee Database'!$A:$K,Spec!B$2,FALSE), IF(NOT(ISNA($M3)), VLOOKUP($A3,'Client Data'!$A:$G,Spec!B$3,FALSE),"")) -> 27601 | D3: =IF(NOT(ISNA($N3)),VLOOKUP($A3,'Employee Database'!$A:$K,Spec!C$2,FALSE), IF(NOT(ISNA($M3)), VLOOKUP($A3,'Client Data'!$A:$G,Spec!C$3,FALSE),"")) -> 38001 | E3: =IF(NOT(ISNA($M3)), VLOOKUP($A3,'Client Data'!$A:$G,Spec!D$3,FALSE), "") -> 99000 | F3: =IF(NOT(ISNA($N3)), VLOOKUP($A3,'Employee Database'!$A:$K,Spec!E$2,FALSE), "") -> 99000 | G3: =IF(NOT(ISNA($N3)), VLOOKUP($A3,'Employee Database'!$A:$K,Spec!F$2,FALSE), "") -> 94300 | H3: =IF(ISNA($M3), "", IF(VLOOKUP($A3,'Client Data'!$A:$G,Spec!G$3,FALSE)="", "", VLOOKUP($A3, 'Client Data'!$A:$G,Spec!G$3,FALSE))) | I3: =IF(ISNA($M3), "", IF(VLOOKUP($A3,'Client Data'!$A:$G,Spec!H$3,FALSE)="", "", VLOOKUP($A3, 'Client Data'!$A:$G,Spec!H$3,FALSE))) | J3: =IF(NOT(ISNA($M3)), VLOOKUP($A3,'Client Data'!$A:$G,Spec!I$3,FALSE), "") -> A | K3: =IF(NOT(ISNA($N3)), VLOOKUP($A3,'Employee Database'!$A:$K,Spec!J$2,FALSE), "") -> A | M3: =MATCH(A3,'Client Data'!A:A,0) -> 3 | N3: =MATCH(A3,'Employee Database'!A:A,0) -> 7 | O3: =IF(AND(NOT(ISNA(M3)), ISNA(N3)),TRUE,"") | P3: =IF(AND(ISNA(M3), NOT(ISNA(N3))),TRUE,"") | R3: =IF(OR(ISNA($M3),ISNA($N3)),"",IF(C3=VLOOKUP($A3,'Client Data'!$A:$G,Spec!B$3,FALSE),"",VLOOKUP($A3,'Client Data'!$A:$G,Spec!B$3,FALSE))) | S3: =IF(OR(ISNA($M3),ISNA($N3)),"",IF(D3=VLOOKUP($A3,'Client Data'!$A:$G,Spec!C$3,FALSE),"",VLOOKUP($A3,'Client Data'!$A:$G,Spec!C$3,FALSE))) | T3: =IF(OR(ISNA($M3),ISNA($N3)),"",IF(H3=VLOOKUP($A3,'Employee Database'!$A:$K,Spec!G$2,FALSE),"",VLOOKUP($A3,'Employee Database'!$A:$K,Spec!G$2,FALSE))) | U3: =IF(OR(ISNA($M3),ISNA($N3)),"",IF(I3=VLOOKUP($A3,'Employee Database'!$A:$K,Spec!H$2,FALSE),"",VLOOKUP($A3,'Employee Database'!$A:$K,Spec!H$2,FALSE)))
A4: 187427 | B4: =IF(ISNA(MATCH(A4,'Employee Database'!$A$6:$A$58,0)),"Not Available",INDEX('Employee Database'!$B$6:$B$58,MATCH(A4,'Employee Database'!$A$6:$A$58,0))) -> Tiedens, Bret | C4: =IF(NOT(ISNA($N4)),VLOOKUP($A4,'Employee Database'!$A:$K,Spec!B$2,FALSE), IF(NOT(ISNA($M4)), VLOOKUP($A4,'Client Data'!$A:$G,Spec!B$3,FALSE),"")) -> 21170 | D4: =IF(NOT(ISNA($N4)),VLOOKUP($A4,'Employee Database'!$A:$K,Spec!C$2,FALSE), IF(NOT(ISNA($M4)), VLOOKUP($A4,'Client Data'!$A:$G,Spec!C$3,FALSE),"")) -> 37975 | E4: =IF(NOT(ISNA($M4)), VLOOKUP($A4,'Client Data'!$A:$G,Spec!D$3,FALSE), "") -> 98000 | F4: =IF(NOT(ISNA($N4)), VLOOKUP($A4,'Employee Database'!$A:$K,Spec!E$2,FALSE), "") -> 98000 | G4: =IF(NOT(ISNA($N4)), VLOOKUP($A4,'Employee Database'!$A:$K,Spec!F$2,FALSE), "") -> 93300 | H4: =IF(ISNA($M4), "", IF(VLOOKUP($A4,'Client Data'!$A:$G,Spec!G$3,FALSE)="", "", VLOOKUP($A4, 'Client Data'!$A:$G,Spec!G$3,FALSE))) | I4: =IF(ISNA($M4), "", IF(VLOOKUP($A4,'Client Data'!$A:$G,Spec!H$3,FALSE)="", "", VLOOKUP($A4, 'Client Data'!$A:$G,Spec!H$3,FALSE))) | J4: =IF(NOT(ISNA($M4)), VLOOKUP($A4,'Client Data'!$A:$G,Spec!I$3,FALSE), "") -> A | K4: =IF(NOT(ISNA($N4)), VLOOKUP($A4,'Employee Database'!$A:$K,Spec!J$2,FALSE), "") -> A | M4: =MATCH(A4,'Client Data'!A:A,0) -> 4 | N4: =MATCH(A4,'Employee Database'!A:A,0) -> 8 | O4: =IF(AND(NOT(ISNA(M4)), ISNA(N4)),TRUE,"") | P4: =IF(AND(ISNA(M4), NOT(ISNA(N4))),TRUE,"") | R4: =IF(OR(ISNA($M4),ISNA($N4)),"",IF(C4=VLOOKUP($A4,'Client Data'!$A:$G,Spec!B$3,FALSE),"",VLOOKUP($A4,'Client Data'!$A:$G,Spec!B$3,FALSE))) | S4: =IF(OR(ISNA($M4),ISNA($N4)),"",IF(D4=VLOOKUP($A4,'Client Data'!$A:$G,Spec!C$3,FALSE),"",VLOOKUP($A4,'Client Data'!$A:$G,Spec!C$3,FALSE))) | T4: =IF(OR(ISNA($M4),ISNA($N4)),"",IF(H4=VLOOKUP($A4,'Employee Database'!$A:$K,Spec!G$2,FALSE),"",VLOOKUP($A4,'Employee Database'!$A:$K,Spec!G$2,FALSE))) | U4: =IF(OR(ISNA($M4),ISNA($N4)),"",IF(I4=VLOOKUP($A4,'Employee Database'!$A:$K,Spec!H$2,FALSE),"",VLOOKUP($A4,'Employee Database'!$A:$K,Spec!H$2,FALSE)))
A5: 189508 | B5: =IF(ISNA(MATCH(A5,'Employee Database'!$A$6:$A$58,0)),"Not Available",INDEX('Employee Database'!$B$6:$B$58,MATCH(A5,'Employee Database'!$A$6:$A$58,0))) -> Souers, Celina | C5: =IF(NOT(ISNA($N5)),VLOOKUP($A5,'Employee Database'!$A:$K,Spec!B$2,FALSE), IF(NOT(ISNA($M5)), VLOOKUP($A5,'Client Data'!$A:$G,Spec!B$3,FALSE),"")) -> 30229 | D5: =IF(NOT(ISNA($N5)),VLOOKUP($A5,'Employee Database'!$A:$K,Spec!C$2,FALSE), IF(NOT(ISNA($M5)), VLOOKUP($A5,'Client Data'!$A:$G,Spec!C$3,FALSE),"")) -> 35020 | E5: =IF(NOT(ISNA($M5)), VLOOKUP($A5,'Client Data'!$A:$G,Spec!D$3,FALSE), "") -> 97000 | F5: =IF(NOT(ISNA($N5)), VLOOKUP($A5,'Employee Database'!$A:$K,Spec!E$2,FALSE), "") -> 97000 | G5: =IF(NOT(ISNA($N5)), VLOOKUP($A5,'Employee Database'!$A:$K,Spec!F$2,FALSE), "") -> 92400 | H5: =IF(ISNA($M5), "", IF(VLOOKUP($A5,'Client Data'!$A:$G,Spec!G$3,FALSE)="", "", VLOOKUP($A5, 'Client Data'!$A:$G,Spec!G$3,FALSE))) | I5: =IF(ISNA($M5), "", IF(VLOOKUP($A5,'Client Data'!$A:$G,Spec!H$3,FALSE)="", "", VLOOKUP($A5, 'Client Data'!$A:$G,Spec!H$3,FALSE))) | J5: =IF(NOT(ISNA($M5)), VLOOKUP($A5,'Client Data'!$A:$G,Spec!I$3,FALSE), "") -> A | K5: =IF(NOT(ISNA($N5)), VLOOKUP($A5,'Employee Database'!$A:$K,Spec!J$2,FALSE), "") -> A | M5: =MATCH(A5,'Client Data'!A:A,0) -> 5 | N5: =MATCH(A5,'Employee Database'!A:A,0) -> 9 | O5: =IF(AND(NOT(ISNA(M5)), ISNA(N5)),TRUE,"") | P5: =IF(AND(ISNA(M5), NOT(ISNA(N5))),TRUE,"") | R5: =IF(OR(ISNA($M5),ISNA($N5)),"",IF(C5=VLOOKUP($A5,'Client Data'!$A:$G,Spec!B$3,FALSE),"",VLOOKUP($A5,'Client Data'!$A:$G,Spec!B$3,FALSE))) | S5: =IF(OR(ISNA($M5),ISNA($N5)),"",IF(D5=VLOOKUP($A5,'Client Data'!$A:$G,Spec!C$3,FALSE),"",VLOOKUP($A5,'Client Data'!$A:$G,Spec!C$3,FALSE))) | T5: =IF(OR(ISNA($M5),ISNA($N5)),"",IF(H5=VLOOKUP($A5,'Employee Database'!$A:$K,Spec!G$2,FALSE),"",VLOOKUP($A5,'Employee Database'!$A:$K,Spec!G$2,FALSE))) | U5: =IF(OR(ISNA($M5),ISNA($N5)),"",IF(I5=VLOOKUP($A5,'Employee Database'!$A:$K,Spec!H$2,FALSE),"",VLOOKUP($A5,'Employee Database'!$A:$K,Spec!H$2,FALSE)))
A6: 199741 | B6: =IF(ISNA(MATCH(A6,'Employee Database'!$A$6:$A$58,0)),"Not Available",INDEX('Employee Database'!$B$6:$B$58,MATCH(A6,'Employee Database'!$A$6:$A$58,0))) -> Al Jaloud, Steve | C6: =IF(NOT(ISNA($N6)),VLOOKUP($A6,'Employee Database'!$A:$K,Spec!B$2,FALSE), IF(NOT(ISNA($M6)), VLOOKUP($A6,'Client Data'!$A:$G,Spec!B$3,FALSE),"")) -> 16439 | D6: =IF(NOT(ISNA($N6)),VLOOKUP($A6,'Employee Database'!$A:$K,Spec!C$2,FALSE), IF(NOT(ISNA($M6)), VLOOKUP($A6,'Client Data'!$A:$G,Spec!C$3,FALSE),"")) -> 35929 | E6: =IF(NOT(ISNA($M6)), VLOOKUP($A6,'Client Data'!$A:$G,Spec!D$3,FALSE), "") -> 96000 | F6: =IF(NOT(ISNA($N6)), VLOOKUP($A6,'Employee Database'!$A:$K,Spec!E$2,FALSE), "") -> 96000 | G6: =IF(NOT(ISNA($N6)), VLOOKUP($A6,'Employee Database'!$A:$K,Spec!F$2,FALSE), "") -> 91400 | H6: =IF(ISNA($M6), "", IF(VLOOKUP($A6,'Client Data'!$A:$G,Spec!G$3,FALSE)="", "", VLOOKUP($A6, 'Client Data'!$A:$G,Spec!G$3,FALSE))) | I6: =IF(ISNA($M6), "", IF(VLOOKUP($A6,'Client Data'!$A:$G,Spec!H$3,FALSE)="", "", VLOOKUP($A6, 'Client Data'!$A:$G,Spec!H$3,FALSE))) | J6: =IF(NOT(ISNA($M6)), VLOOKUP($A6,'Client Data'!$A:$G,Spec!I$3,FALSE), "") -> A | K6: =IF(NOT(ISNA($N6)), VLOOKUP($A6,'Employee Database'!$A:$K,Spec!J$2,FALSE), "") -> A | M6: =MATCH(A6,'Client Data'!A:A,0) -> 6 | N6: =MATCH(A6,'Employee Database'!A:A,0) -> 10 | O6: =IF(AND(NOT(ISNA(M6)), ISNA(N6)),TRUE,"") | P6: =IF(AND(ISNA(M6), NOT(ISNA(N6))),TRUE,"") | R6: =IF(OR(ISNA($M6),ISNA($N6)),"",IF(C6=VLOOKUP($A6,'Client Data'!$A:$G,Spec!B$3,FALSE),"",VLOOKUP($A6,'Client Data'!$A:$G,Spec!B$3,FALSE))) | S6: =IF(OR(ISNA($M6),ISNA($N6)),"",IF(D6=VLOOKUP($A6,'Client Data'!$A:$G,Spec!C$3,FALSE),"",VLOOKUP($A6,'Client Data'!$A:$G,Spec!C$3,FALSE))) | T6: =IF(OR(ISNA($M6),ISNA($N6)),"",IF(H6=VLOOKUP($A6,'Employee Database'!$A:$K,Spec!G$2,FALSE),"",VLOOKUP($A6,'Employee Database'!$A:$K,Spec!G$2,FALSE))) | U6: =IF(OR(ISNA($M6),ISNA($N6)),"",IF(I6=VLOOKUP($A6,'Employee Database'!$A:$K,Spec!H$2,FALSE),"",VLOOKUP($A6,'Employee Database'!$A:$K,Spec!H$2,FALSE)))
A7: 205217 | B7: =IF(ISNA(MATCH(A7,'Employee Database'!$A$6:$A$58,0)),"Not Available",INDEX('Employee Database'!$B$6:$B$58,MATCH(A7,'Employee Database'!$A$6:$A$58,0))) -> Butina, Natalie | C7: =IF(NOT(ISNA($N7)),VLOOKUP($A7,'Employee Database'!$A:$K,Spec!B$2,FALSE), IF(NOT(ISNA($M7)), VLOOKUP($A7,'Client Data'!$A:$G,Spec!B$3,FALSE),"")) -> 17620 | D7: =IF(NOT(ISNA($N7)),VLOOKUP($A7,'Employee Database'!$A:$K,Spec!C$2,FALSE), IF(NOT(ISNA($M7)), VLOOKUP($A7,'Client Data'!$A:$G,Spec!C$3,FALSE),"")) -> 34867 | E7: =IF(NOT(ISNA($M7)), VLOOKUP($A7,'Client Data'!$A:$G,Spec!D$3,FALSE), "") -> 95000 | F7: =IF(NOT(ISNA($N7)), VLOOKUP($A7,'Employee Database'!$A:$K,Spec!E$2,FALSE), "") -> 95000 | G7: =IF(NOT(ISNA($N7)), VLOOKUP($A7,'Employee Database'!$A:$K,Spec!F$2,FALSE), "") -> 90500 | H7: =IF(ISNA($M7), "", IF(VLOOKUP($A7,'Client Data'!$A:$G,Spec!G$3,FALSE)="", "", VLOOKUP($A7, 'Client Data'!$A:$G,Spec!G$3,FALSE))) | I7: =IF(ISNA($M7), "", IF(VLOOKUP($A7,'Client Data'!$A:$G,Spec!H$3,FALSE)="", "", VLOOKUP($A7, 'Client Data'!$A:$G,Spec!H$3,FALSE))) | J7: =IF(NOT(ISNA($M7)), VLOOKUP($A7,'Client Data'!$A:$G,Spec!I$3,FALSE), "") -> A | K7: =IF(NOT(ISNA($N7)), VLOOKUP($A7,'Employee Database'!$A:$K,Spec!J$2,FALSE), "") -> A | M7: =MATCH(A7,'Client Data'!A:A,0) -> 7 | N7: =MATCH(A7,'Employee Database'!A:A,0) -> 11 | O7: =IF(AND(NOT(ISNA(M7)), ISNA(N7)),TRUE,"") | P7: =IF(AND(ISNA(M7), NOT(ISNA(N7))),TRUE,"") | R7: =IF(OR(ISNA($M7),ISNA($N7)),"",IF(C7=VLOOKUP($A7,'Client Data'!$A:$G,Spec!B$3,FALSE),"",VLOOKUP($A7,'Client Data'!$A:$G,Spec!B$3,FALSE))) | S7: =IF(OR(ISNA($M7),ISNA($N7)),"",IF(D7=VLOOKUP($A7,'Client Data'!$A:$G,Spec!C$3,FALSE),"",VLOOKUP($A7,'Client Data'!$A:$G,Spec!C$3,FALSE))) | T7: =IF(OR(ISNA($M7),ISNA($N7)),"",IF(H7=VLOOKUP($A7,'Employee Database'!$A:$K,Spec!G$2,FALSE),"",VLOOKUP($A7,'Employee Database'!$A:$K,Spec!G$2,FALSE))) | U7: =IF(OR(ISNA($M7),ISNA($N7)),"",IF(I7=VLOOKUP($A7,'Employee Database'!$A:$K,Spec!H$2,FALSE),"",VLOOKUP($A7,'Employee Database'!$A:$K,Spec!H$2,FALSE)))
A8: 206418 | B8: =IF(ISNA(MATCH(A8,'Employee Database'!$A$6:$A$58,0)),"Not Available",INDEX('Employee Database'!$B$6:$B$58,MATCH(A8,'Employee Database'!$A$6:$A$58,0))) -> Olson, Nicholas | C8: =IF(NOT(ISNA($N8)),VLOOKUP($A8,'Employee Database'!$A:$K,Spec!B$2,FALSE), IF(NOT(ISNA($M8)), VLOOKUP($A8,'Client Data'!$A:$G,Spec!B$3,FALSE),"")) -> 20874 | D8: =IF(NOT(ISNA($N8)),VLOOKUP($A8,'Employee Database'!$A:$K,Spec!C$2,FALSE), IF(NOT(ISNA($M8)), VLOOKUP($A8,'Client Data'!$A:$G,Spec!C$3,FALSE),"")) -> 40497 | E8: =IF(NOT(ISNA($M8)), VLOOKUP($A8,'Client Data'!$A:$G,Spec!D$3,FALSE), "") -> 320000 | F8: =IF(NOT(ISNA($N8)), VLOOKUP($A8,'Employee Database'!$A:$K,Spec!E$2,FALSE), "") -> 320000 | G8: =IF(NOT(ISNA($N8)), VLOOKUP($A8,'Employee Database'!$A:$K,Spec!F$2,FALSE), "") -> 32000 | H8: =IF(ISNA($M8), "", IF(VLOOKUP($A8,'Client Data'!$A:$G,Spec!G$3,FALSE)="", "", VLOOKUP($A8, 'Client Data'!$A:$G,Spec!G$3,FALSE))) | I8: =IF(ISNA($M8), "", IF(VLOOKUP($A8,'Client Data'!$A:$G,Spec!H$3,FALSE)="", "", VLOOKUP($A8, 'Client Data'!$A:$G,Spec!H$3,FALSE))) | J8: =IF(NOT(ISNA($M8)), VLOOKUP($A8,'Client Data'!$A:$G,Spec!I$3,FALSE), "") -> A | K8: =IF(NOT(ISNA($N8)), VLOOKUP($A8,'Employee Database'!$A:$K,Spec!J$2,FALSE), "") -> A | M8: =MATCH(A8,'Client Data'!A:A,0) -> 8 | N8: =MATCH(A8,'Employee Database'!A:A,0) -> 12 | O8: =IF(AND(NOT(ISNA(M8)), ISNA(N8)),TRUE,"") | P8: =IF(AND(ISNA(M8), NOT(ISNA(N8))),TRUE,"") | R8: =IF(OR(ISNA($M8),ISNA($N8)),"",IF(C8=VLOOKUP($A8,'Client Data'!$A:$G,Spec!B$3,FALSE),"",VLOOKUP($A8,'Client Data'!$A:$G,Spec!B$3,FALSE))) | S8: =IF(OR(ISNA($M8),ISNA($N8)),"",IF(D8=VLOOKUP($A8,'Client Data'!$A:$G,Spec!C$3,FALSE),"",VLOOKUP($A8,'Client Data'!$A:$G,Spec!C$3,FALSE))) | T8: =IF(OR(ISNA($M8),ISNA($N8)),"",IF(H8=VLOOKUP($A8,'Employee Database'!$A:$K,Spec!G$2,FALSE),"",VLOOKUP($A8,'Employee Database'!$A:$K,Spec!G$2,FALSE))) | U8: =IF(OR(ISNA($M8),ISNA($N8)),"",IF(I8=VLOOKUP($A8,'Employee Database'!$A:$K,Spec!H$2,FALSE),"",VLOOKUP($A8,'Employee Database'!$A:$K,Spec!H$2,FALSE)))
A9: 218201 | B9: =IF(ISNA(MATCH(A9,'Employee Database'!$A$6:$A$58,0)),"Not Available",INDEX('Employee Database'!$B$6:$B$58,MATCH(A9,'Employee Database'!$A$6:$A$58,0))) -> Richman, Michelle | C9: =IF(NOT(ISNA($N9)),VLOOKUP($A9,'Employee Database'!$A:$K,Spec!B$2,FALSE), IF(NOT(ISNA($M9)), VLOOKUP($A9,'Client Data'!$A:$G,Spec!B$3,FALSE),"")) -> 15818 | D9: =IF(NOT(ISNA($N9)),VLOOKUP($A9,'Employee Database'!$A:$K,Spec!C$2,FALSE), IF(NOT(ISNA($M9)), VLOOKUP($A9,'Client Data'!$A:$G,Spec!C$3,FALSE),"")) -> 35362 | E9: =IF(NOT(ISNA($M9)), VLOOKUP($A9,'Client Data'!$A:$G,Spec!D$3,FALSE), "") -> 93000 | F9: =IF(NOT(ISNA($N9)), VLOOKUP($A9,'Employee Database'!$A:$K,Spec!E$2,FALSE), "") -> 93000 | G9: =IF(NOT(ISNA($N9)), VLOOKUP($A9,'Employee Database'!$A:$K,Spec!F$2,FALSE), "") -> 88600 | H9: =IF(ISNA($M9), "", IF(VLOOKUP($A9,'Client Data'!$A:$G,Spec!G$3,FALSE)="", "", VLOOKUP($A9, 'Client Data'!$A:$G,Spec!G$3,FALSE))) | I9: =IF(ISNA($M9), "", IF(VLOOKUP($A9,'Client Data'!$A:$G,Spec!H$3,FALSE)="", "", VLOOKUP($A9, 'Client Data'!$A:$G,Spec!H$3,FALSE))) | J9: =IF(NOT(ISNA($M9)), VLOOKUP($A9,'Client Data'!$A:$G,Spec!I$3,FALSE), "") -> A | K9: =IF(NOT(ISNA($N9)), VLOOKUP($A9,'Employee Database'!$A:$K,Spec!J$2,FALSE), "") -> A | M9: =MATCH(A9,'Client Data'!A:A,0) -> 9 | N9: =MATCH(A9,'Employee Database'!A:A,0) -> 13 | O9: =IF(AND(NOT(ISNA(M9)), ISNA(N9)),TRUE,"") | P9: =IF(AND(ISNA(M9), NOT(ISNA(N9))),TRUE,"") | R9: =IF(OR(ISNA($M9),ISNA($N9)),"",IF(C9=VLOOKUP($A9,'Client Data'!$A:$G,Spec!B$3,FALSE),"",VLOOKUP($A9,'Client Data'!$A:$G,Spec!B$3,FALSE))) | S9: =IF(OR(ISNA($M9),ISNA($N9)),"",IF(D9=VLOOKUP($A9,'Client Data'!$A:$G,Spec!C$3,FALSE),"",VLOOKUP($A9,'Client Data'!$A:$G,Spec!C$3,FALSE))) | T9: =IF(OR(ISNA($M9),ISNA($N9)),"",IF(H9=VLOOKUP($A9,'Employee Database'!$A:$K,Spec!G$2,FALSE),"",VLOOKUP($A9,'Employee Database'!$A:$K,Spec!G$2,FALSE))) | U9: =IF(OR(ISNA($M9),ISNA($N9)),"",IF(I9=VLOOKUP($A9,'Employee Database'!$A:$K,Spec!H$2,FALSE),"",VLOOKUP($A9,'Employee Database'!$A:$K,Spec!H$2,FALSE)))
A10: 225139 | B10: =IF(ISNA(MATCH(A10,'Employee Database'!$A$6:$A$58,0)),"Not Available",INDEX('Employee Database'!$B$6:$B$58,MATCH(A10,'Employee Database'!$A$6:$A$58,0))) -> Johnson, Aaron | C10: =IF(NOT(ISNA($N10)),VLOOKUP($A10,'Employee Database'!$A:$K,Spec!B$2,FALSE), IF(NOT(ISNA($M10)), VLOOKUP($A10,'Client Data'!$A:$G,Spec!B$3,FALSE),"")) -> 33987 | D10: =IF(NOT(ISNA($N10)),VLOOKUP($A10,'Employee Database'!$A:$K,Spec!C$2,FALSE), IF(NOT(ISNA($M10)), VLOOKUP($A10,'Client Data'!$A:$G,Spec!C$3,FALSE),"")) -> 41074 | E10: =IF(NOT(ISNA($M10)), VLOOKUP($A10,'Client Data'!$A:$G,Spec!D$3,FALSE), "") -> 92000 | F10: =IF(NOT(ISNA($N10)), VLOOKUP($A10,'Employee Database'!$A:$K,Spec!E$2,FALSE), "") -> 92000 | G10: =IF(NOT(ISNA($N10)), VLOOKUP($A10,'Employee Database'!$A:$K,Spec!F$2,FALSE), "") -> 40000 | H10: =IF(ISNA($M10), "", IF(VLOOKUP($A10,'Client Data'!$A:$G,Spec!G$3,FALSE)="", "", VLOOKUP($A10, 'Client Data'!$A:$G,Spec!G$3,FALSE))) | I10: =IF(ISNA($M10), "", IF(VLOOKUP($A10,'Client Data'!$A:$G,Spec!H$3,FALSE)="", "", VLOOKUP($A10, 'Client Data'!$A:$G,Spec!H$3,FALSE))) | J10: =IF(NOT(ISNA($M10)), VLOOKUP($A10,'Client Data'!$A:$G,Spec!I$3,FALSE), "") -> A | K10: =IF(NOT(ISNA($N10)), VLOOKUP($A10,'Employee Database'!$A:$K,Spec!J$2,FALSE), "") -> A | M10: =MATCH(A10,'Client Data'!A:A,0) -> 10 | N10: =MATCH(A10,'Employee Database'!A:A,0) -> 14 | O10: =IF(AND(NOT(ISNA(M10)), ISNA(N10)),TRUE,"") | P10: =IF(AND(ISNA(M10), NOT(ISNA(N10))),TRUE,"") | R10: =IF(OR(ISNA($M10),ISNA($N10)),"",IF(C10=VLOOKUP($A10,'Client Data'!$A:$G,Spec!B$3,FALSE),"",VLOOKUP($A10,'Client Data'!$A:$G,Spec!B$3,FALSE))) | S10: =IF(OR(ISNA($M10),ISNA($N10)),"",IF(D10=VLOOKUP($A10,'Client Data'!$A:$G,Spec!C$3,FALSE),"",VLOOKUP($A10,'Client Data'!$A:$G,Spec!C$3,FALSE))) | T10: =IF(OR(ISNA($M10),ISNA($N10)),"",IF(H10=VLOOKUP($A10,'Employee Database'!$A:$K,Spec!G$2,FALSE),"",VLOOKUP($A10,'Employee Database'!$A:$K,Spec!G$2,FALSE))) | U10: =IF(OR(ISNA($M10),ISNA($N10)),"",IF(I10=VLOOKUP($A10,'Employee Database'!$A:$K,Spec!H$2,FALSE),"",VLOOKUP($A10,'Employee Database'!$A:$K,Spec!H$2,FALSE)))
A11: 232072 | B11: =IF(ISNA(MATCH(A11,'Employee Database'!$A$6:$A$58,0)),"Not Available",INDEX('Employee Database'!$B$6:$B$58,MATCH(A11,'Employee Database'!$A$6:$A$58,0))) -> Brinkley, Jeanne M | C11: =IF(NOT(ISNA($N11)),VLOOKUP($A11,'Employee Database'!$A:$K,Spec!B$2,FALSE), IF(NOT(ISNA($M11)), VLOOKUP($A11,'Client Data'!$A:$G,Spec!B$3,FALSE),"")) -> 24290 | D11: =IF(NOT(ISNA($N11)),VLOOKUP($A11,'Employee Database'!$A:$K,Spec!C$2,FALSE), IF(NOT(ISNA($M11)), VLOOKUP($A11,'Client Data'!$A:$G,Spec!C$3,FALSE),"")) -> 39634 | E11: =IF(NOT(ISNA($M11)), VLOOKUP($A11,'Client Data'!$A:$G,Spec!D$3,FALSE), "") -> 91000 | F11: =IF(NOT(ISNA($N11)), VLOOKUP($A11,'Employee Database'!$A:$K,Spec!E$2,FALSE), "") -> 91000 | G11: =IF(NOT(ISNA($N11)), VLOOKUP($A11,'Employee Database'!$A:$K,Spec!F$2,FALSE), "") -> 86700 | H11: =IF(ISNA($M11), "", IF(VLOOKUP($A11,'Client Data'!$A:$G,Spec!G$3,FALSE)="", "", VLOOKUP($A11, 'Client Data'!$A:$G,Spec!G$3,FALSE))) | I11: =IF(ISNA($M11), "", IF(VLOOKUP($A11,'Client Data'!$A:$G,Spec!H$3,FALSE)="", "", VLOOKUP($A11, 'Client Data'!$A:$G,Spec!H$3,FALSE))) | J11: =IF(NOT(ISNA($M11)), VLOOKUP($A11,'Client Data'!$A:$G,Spec!I$3,FALSE), "") -> A | K11: =IF(NOT(ISNA($N11)), VLOOKUP($A11,'Employee Database'!$A:$K,Spec!J$2,FALSE), "") -> A | M11: =MATCH(A11,'Client Data'!A:A,0) -> 11 | N11: =MATCH(A11,'Employee Database'!A:A,0) -> 15 | O11: =IF(AND(NOT(ISNA(M11)), ISNA(N11)),TRUE,"") | P11: =IF(AND(ISNA(M11), NOT(ISNA(N11))),TRUE,"") | R11: =IF(OR(ISNA($M11),ISNA($N11)),"",IF(C11=VLOOKUP($A11,'Client Data'!$A:$G,Spec!B$3,FALSE),"",VLOOKUP($A11,'Client Data'!$A:$G,Spec!B$3,FALSE))) | S11: =IF(OR(ISNA($M11),ISNA($N11)),"",IF(D11=VLOOKUP($A11,'Client Data'!$A:$G,Spec!C$3,FALSE),"",VLOOKUP($A11,'Client Data'!$A:$G,Spec!C$3,FALSE))) | T11: =IF(OR(ISNA($M11),ISNA($N11)),"",IF(H11=VLOOKUP($A11,'Employee Database'!$A:$K,Spec!G$2,FALSE),"",VLOOKUP($A11,'Employee Database'!$A:$K,Spec!G$2,FALSE))) | U11: =IF(OR(ISNA($M11),ISNA($N11)),"",IF(I11=VLOOKUP($A11,'Employee Database'!$A:$K,Spec!H$2,FALSE),"",VLOOKUP($A11,'Employee Database'!$A:$K,Spec!H$2,FALSE)))
A12: 250067 | B12: =IF(ISNA(MATCH(A12,'Employee Database'!$A$6:$A$58,0)),"Not Available",INDEX('Employee Database'!$B$6:$B$58,MATCH(A12,'Employee Database'!$A$6:$A$58,0))) -> Brinkley, Roxanne L | C12: =IF(NOT(ISNA($N12)),VLOOKUP($A12,'Employee Database'!$A:$K,Spec!B$2,FALSE), IF(NOT(ISNA($M12)), VLOOKUP($A12,'Client Data'!$A:$G,Spec!B$3,FALSE),"")) -> 2/30/1960 | D12: =IF(NOT(ISNA($N12)),VLOOKUP($A12,'Employee Database'!$A:$K,Spec!C$2,FALSE), IF(NOT(ISNA($M12)), VLOOKUP($A12,'Client Data'!$A:$G,Spec!C$3,FALSE),"")) -> 40073 | E12: =IF(NOT(ISNA($M12)), VLOOKUP($A12,'Client Data'!$A:$G,Spec!D$3,FALSE), "") -> 90000 | F12: =IF(NOT(ISNA($N12)), VLOOKUP($A12,'Employee Database'!$A:$K,Spec!E$2,FALSE), "") -> 90000 | G12: =IF(NOT(ISNA($N12)), VLOOKUP($A12,'Employee Database'!$A:$K,Spec!F$2,FALSE), "") -> 85700 | H12: =IF(ISNA($M12), "", IF(VLOOKUP($A12,'Client Data'!$A:$G,Spec!G$3,FALSE)="", "", VLOOKUP($A12, 'Client Data'!$A:$G,Spec!G$3,FALSE))) | I12: =IF(ISNA($M12), "", IF(VLOOKUP($A12,'Client Data'!$A:$G,Spec!H$3,FALSE)="", "", VLOOKUP($A12, 'Client Data'!$A:$G,Spec!H$3,FALSE))) | J12: =IF(NOT(ISNA($M12)), VLOOKUP($A12,'Client Data'!$A:$G,Spec!I$3,FALSE), "") -> A | K12: =IF(NOT(ISNA($N12)), VLOOKUP($A12,'Employee Database'!$A:$K,Spec!J$2,FALSE), "") -> A | M12: =MATCH(A12,'Client Data'!A:A,0) -> 12 | N12: =MATCH(A12,'Employee Database'!A:A,0) -> 16 | O12: =IF(AND(NOT(ISNA(M12)), ISNA(N12)),TRUE,"") | P12: =IF(AND(ISNA(M12), NOT(ISNA(N12))),TRUE,"") | R12: =IF(OR(ISNA($M12),ISNA($N12)),"",IF(C12=VLOOKUP($A12,'Client Data'!$A:$G,Spec!B$3,FALSE),"",VLOOKUP($A12,'Client Data'!$A:$G,Spec!B$3,FALSE))) | S12: =IF(OR(ISNA($M12),ISNA($N12)),"",IF(D12=VLOOKUP($A12,'Client Data'!$A:$G,Spec!C$3,FALSE),"",VLOOKUP($A12,'Client Data'!$A:$G,Spec!C$3,FALSE))) | T12: =IF(OR(ISNA($M12),ISNA($N12)),"",IF(H12=VLOOKUP($A12,'Employee Database'!$A:$K,Spec!G$2,FALSE),"",VLOOKUP($A12,'Employee Database'!$A:$K,Spec!G$2,FALSE))) | U12: =IF(OR(ISNA($M12),ISNA($N12)),"",IF(I12=VLOOKUP($A12,'Employee Database'!$A:$K,Spec!H$2,FALSE),"",VLOOKUP($A12,'Employee Database'!$A:$K,Spec!H$2,FALSE)))
A13: 253862 | B13: =IF(ISNA(MATCH(A13,'Employee Database'!$A$6:$A$58,0)),"Not Available",INDEX('Employee Database'!$B$6:$B$58,MATCH(A13,'Employee Database'!$A$6:$A$58,0))) -> Nelson, Yuyang | C13: =IF(NOT(ISNA($N13)),VLOOKUP($A13,'Employee Database'!$A:$K,Spec!B$2,FALSE), IF(NOT(ISNA($M13)), VLOOKUP($A13,'Client Data'!$A:$G,Spec!B$3,FALSE),"")) -> 23332 | D13: =IF(NOT(ISNA($N13)),VLOOKUP($A13,'Employee Database'!$A:$K,Spec!C$2,FALSE), IF(NOT(ISNA($M13)), VLOOKUP($A13,'Client Data'!$A:$G,Spec!C$3,FALSE),"")) -> 40339 | E13: =IF(NOT(ISNA($M13)), VLOOKUP($A13,'Client Data'!$A:$G,Spec!D$3,FALSE), "") -> 89000 | F13: =IF(NOT(ISNA($N13)), VLOOKUP($A13,'Employee Database'!$A:$K,Spec!E$2,FALSE), "") -> 89000 | G13: =IF(NOT(ISNA($N13)), VLOOKUP($A13,'Employee Database'!$A:$K,Spec!F$2,FALSE), "") -> 84800 | H13: =IF(ISNA($M13), "", IF(VLOOKUP($A13,'Client Data'!$A:$G,Spec!G$3,FALSE)="", "", VLOOKUP($A13, 'Client Data'!$A:$G,Spec!G$3,FALSE))) | I13: =IF(ISNA($M13), "", IF(VLOOKUP($A13,'Client Data'!$A:$G,Spec!H$3,FALSE)="", "", VLOOKUP($A13, 'Client Data'!$A:$G,Spec!H$3,FALSE))) | J13: =IF(NOT(ISNA($M13)), VLOOKUP($A13,'Client Data'!$A:$G,Spec!I$3,FALSE), "") -> A | K13: =IF(NOT(ISNA($N13)), VLOOKUP($A13,'Employee Database'!$A:$K,Spec!J$2,FALSE), "") -> A | M13: =MATCH(A13,'Client Data'!A:A,0) -> 13 | N13: =MATCH(A13,'Employee Database'!A:A,0) -> 17 | O13: =IF(AND(NOT(ISNA(M13)), ISNA(N13)),TRUE,"") | P13: =IF(AND(ISNA(M13), NOT(ISNA(N13))),TRUE,"") | R13: =IF(OR(ISNA($M13),ISNA($N13)),"",IF(C13=VLOOKUP($A13,'Client Data'!$A:$G,Spec!B$3,FALSE),"",VLOOKUP($A13,'Client Data'!$A:$G,Spec!B$3,FALSE))) | S13: =IF(OR(ISNA($M13),ISNA($N13)),"",IF(D13=VLOOKUP($A13,'Client Data'!$A:$G,Spec!C$3,FALSE),"",VLOOKUP($A13,'Client Data'!$A:$G,Spec!C$3,FALSE))) | T13: =IF(OR(ISNA($M13),ISNA($N13)),"",IF(H13=VLOOKUP($A13,'Employee Database'!$A:$K,Spec!G$2,FALSE),"",VLOOKUP($A13,'Employee Database'!$A:$K,Spec!G$2,FALSE))) | U13: =IF(OR(ISNA($M13),ISNA($N13)),"",IF(I13=VLOOKUP($A13,'Employee Database'!$A:$K,Spec!H$2,FALSE),"",VLOOKUP($A13,'Employee Database'!$A:$K,Spec!H$2,FALSE)))
... A58: 579414 | B58: =IF(ISNA(MATCH(A58,'Employee Database'!$A$6:$A$58,0)),"Not Available",INDEX('Employee Database'!$B$6:$B$58,MATCH(A58,'Employee Database'!$A$6:$A$58,0))) -> Not Available | C58: =IF(NOT(ISNA($N58)),VLOOKUP($A58,'Employee Database'!$A:$K,Spec!B$2,FALSE), IF(NOT(ISNA($M58)), VLOOKUP($A58,'Client Data'!$A:$G,Spec!B$3,FALSE),"")) -> 32874 | D58: =IF(NOT(ISNA($N58)),VLOOKUP($A58,'Employee Database'!$A:$K,Spec!C$2,FALSE), IF(NOT(ISNA($M58)), VLOOKUP($A58,'Client Data'!$A:$G,Spec!C$3,FALSE),"")) -> 41974 | E58: =IF(NOT(ISNA($M58)), VLOOKUP($A58,'Client Data'!$A:$G,Spec!D$3,FALSE), "") -> 110000 | F58: =IF(NOT(ISNA($N58)), VLOOKUP($A58,'Employee Database'!$A:$K,Spec!E$2,FALSE), "") | G58: =IF(NOT(ISNA($N58)), VLOOKUP($A58,'Employee Database'!$A:$K,Spec!F$2,FALSE), "") | H58: =IF(ISNA($M58), "", IF(VLOOKUP($A58,'Client Data'!$A:$G,Spec!G$3,FALSE)="", "", VLOOKUP($A58, 'Client Data'!$A:$G,Spec!G$3,FALSE))) | I58: =IF(ISNA($M58), "", IF(VLOOKUP($A58,'Client Data'!$A:$G,Spec!H$3,FALSE)="", "", VLOOKUP($A58, 'Client Data'!$A:$G,Spec!H$3,FALSE))) | J58: =IF(NOT(ISNA($M58)), VLOOKUP($A58,'Client Data'!$A:$G,Spec!I$3,FALSE), "") -> A | K58: =IF(NOT(ISNA($N58)), VLOOKUP($A58,'Employee Database'!$A:$K,Spec!J$2,FALSE), "") | M58: =MATCH(A58,'Client Data'!A:A,0) -> 57 | N58: =MATCH(A58,'Employee Database'!A:A,0) -> #N/A | O58: =IF(AND(NOT(ISNA(M58)), ISNA(N58)),TRUE,"") -> TRUE | P58: =IF(AND(ISNA(M58), NOT(ISNA(N58))),TRUE,"") | R58: =IF(OR(ISNA($M58),ISNA($N58)),"",IF(C58=VLOOKUP($A58,'Client Data'!$A:$G,Spec!B$3,FALSE),"",VLOOKUP($A58,'Client Data'!$A:$G,Spec!B$3,FALSE))) | S58: =IF(OR(ISNA($M58),ISNA($N58)),"",IF(D58=VLOOKUP($A58,'Client Data'!$A:$G,Spec!C$3,FALSE),"",VLOOKUP($A58,'Client Data'!$A:$G,Spec!C$3,FALSE))) | T58: =IF(OR(ISNA($M58),ISNA($N58)),"",IF(H58=VLOOKUP($A58,'Employee Database'!$A:$K,Spec!G$2,FALSE),"",VLOOKUP($A58,'Employee Database'!$A:$K,Spec!G$2,FALSE))) | U58: =IF(OR(ISNA($M58),ISNA($N58)),"",IF(I58=VLOOKUP($A58,'Employee Database'!$A:$K,Spec!H$2,FALSE),"",VLOOKUP($A58,'Employee Database'!$A:$K,Spec!H$2,FALSE)))

Sheet Final Sheet
A1: ID | B1: Name | C1: Date of Birth | D1: Date of Hire | E1: 2015 Salary | F1: 2014 Salary | G1: 2013 Salary | H1: Retirement Date | I1: Retirement Benefit | J1: Status Code | K1: Prior Status
A2: 123491 | B2: Shapiro, Amanda | C2: 24017 | D2: 34809 | E2: 250000 | F2: 250000 | G2: 230000 | J2: A | K2: A
A3: 144983 | B3: Donovan, Adrienne | C3: 27601 | D3: 38001 | E3: 99000 | F3: 99000 | G3: 94300 | J3: A | K3: A
A4: 187427 | B4: Tiedens, Bret | C4: 21170 | D4: 37975 | E4: 98000 | F4: 98000 | G4: 93300 | J4: A | K4: A
A5: 189508 | B5: Souers, Celina | C5: 30229 | D5: 35020 | E5: 97000 | F5: 97000 | G5: 92400 | J5: A | K5: A
A6: 199741 | B6: Al Jaloud, Steve | C6: 16439 | D6: 35929 | E6: 96000 | F6: 96000 | G6: 91400 | J6: A | K6: A
A7: 205217 | B7: Butina, Natalie | C7: 17620 | D7: 34867 | E7: 95000 | F7: 95000 | G7: 90500 | J7: A | K7: A
A8: 206418 | B8: Olson, Nicholas | C8: 20874 | D8: 40497 | E8: 320000 | F8: 320000 | G8: 32000 | J8: A | K8: A
A9: 218201 | B9: Richman, Michelle | C9: 15818 | D9: 35362 | E9: 93000 | F9: 93000 | G9: 88600 | J9: A | K9: A
A10: 225139 | B10: Johnson, Aaron | C10: 33987 | D10: 41074 | E10: 92000 | F10: 92000 | G10: 40000 | J10: A | K10: A
A11: 232072 | B11: Brinkley, Jeanne M | C11: 24290 | D11: 39634 | E11: 91000 | F11: 91000 | G11: 86700 | J11: A | K11: A
A12: 250067 | B12: Brinkley, Roxanne L | C12: 2/30/1960 | D12: 40073 | E12: 90000 | F12: 90000 | G12: 85700 | J12: A | K12: A
A13: 253862 | B13: Nelson, Yuyang | C13: 23332 | D13: 40339 | E13: 89000 | F13: 89000 | G13: 84800 | J13: A | K13: A
A14: 255179 | B14: Bossler, Bill | C14: 22281 | D14: 40774 | E14: 88000 | F14: 88000 | G14: 83800 | J14: A | K14: A
A15: 258130 | B15: Cress, Scott G | C15: 29124 | D15: 29006 | E15: 87000 | F15: 87000 | G15: 82900 | J15: A | K15: A
A16: 286491 | B16: Aljebreen, Patric | C16: 16018 | D16: 31071 | E16: 86000 | F16: 86000 | G16: 81900 | J16: A | K16: A
A17: 290999 | B17: Dehn, Diane M | C17: 25991 | D17: 41600 | E17: 85000 | F17: 85000 | G17: 2000 | J17: A | K17: A
A18: 300843 | B18: Baker, Eric | C18: 17659 | D18: 31876 | E18: 84000 | F18: 84000 | G18: 80000 | J18: A | K18: A
A19: 302798 | B19: Asche, Ryan | C19: 28924 | D19: 35009 | E19: 86000 | F19: 300000 | G19: 276000 | J19: A | K19: A
A20: 310267 | B20: Chen, Jerome F | C20: 23532 | D20: 38201 | E20: 86000 | F20: 118800 | G20: 113100 | J20: A | K20: A
A21: 313615 | B21: Gist, Tracy A | C21: 34187 | D21: 38175 | E21: 87000 | F21: 117600 | G21: 112000 | J21: A | K21: A
A22: 320387 | B22: Carlson, Jeremy | C22: 25791 | D22: 35220 | E22: 76000 | F22: 116400 | G22: 110900 | J22: A | K22: A
A23: 340436 | B23: Duvall, DeeAnn S | C23: 27791 | D23: 36129 | E23: 75000 | F23: 115200 | G23: 109700 | J23: A | K23: A
A24: 345767 | B24: Gall, Susann K | C24: 24217 | D24: 35067 | E24: 86000 | F24: 114000 | G24: 108600 | J24: A | K24: A
... A44: 565414 | B44: Aho, Blake | C44: 21758 | D44: 41474 | E44: 110000 | F44: 132500 | G44: 57600 | J44: A | K44: A
A45: 570202 | B45: Klendshoj, Saleh | C45: 16239 | D45: 40073 | E45: 0 | F45: 90000 | G45: 85700 | J45: 0 | K45: A
A46: 578408 | B46: Bartho, George | C46: 17459 | D46: 40339 | E46: 0 | F46: 89000 | G46: 84800 | J46: 0 | K46: A
A47: 579268 | B47: Benson, Jessika | C47: 22081 | D47: 40774 | E47: 83000 | F47: 88000 | G47: 83800 | J47: A | K47: A
A48: 123486 | B48: Wang, Eric | C48: 19725 | D48: 0 | E48: 0 | F48: 0 | G48: 0 | H48: 43466 | I48: 8990 | J48: V | K48: V
A49: 123485 | B49: Larson, Chris | C49: 16254 | D49: 0 | E49: 0 | F49: 0 | G49: 0 | H49: 39995 | I49: 18047 | J49: R | K49: R
A50: 123484 | B50: Larson, George | C50: 18203 | D50: 0 | E50: 0 | F50: 0 | G50: 0 | H50: 41944 | I50: 9625 | J50: R | K50: R
A51: 123472 | B51: Jobs, Benjamin | C51: 19725 | D51: 0 | E51: 0 | F51: 0 | G51: 0 | H51: 43466 | I51: 5840 | J51: V | K51: V
A52: 123466 | B52: Jordon, Hillary | C52: 22098 | D52: 0 | E52: 0 | F52: 0 | G52: 0 | H52: 45839 | I52: 15804 | J52: V | K52: V
A53: 123465 | B53: Clinton, Bills | C53: 16803 | D53: 0 | E53: 0 | F53: 0 | G53: 0 | H53: 40544 | I53: 10349 | J53: R | K53: R
A54: 123451 | B54: Lee, Gordon | C54: 13789 | D54: 0 | F54: 0 | G54: 0 | K54: R
A55: 579277 | B55: Not Available | C55: 22084 | D55: 0 | E55: 85000 | J55: A
A56: 579271 | B56: Not Available | C56: 22069 | D56: 0 | E56: 0 | J56: 0
A57: 579274 | B57: Not Available | C57: 20256 | D57: 0 | E57: 200000 | J57: A
A58: 579414 | B58: Not Available | C58: 32874 | D58: 41974 | E58: 110000 | J58: A
